Workbook

Sheet Старт
B2: ПЛАНЕР ПРИВЫЧЕК
B3: Один файл на весь год · 12 месяцев · чекбоксы в один клик · статистика, серии и инсайты считаются сами
B5: НАСТРОЙКИ | H5: КАК ПОЛЬЗОВАТЬСЯ
C6: Год | D6: 2026 | E6: все 12 месяцев подстроятся под этот год | H6: 1. Впиши год и свои привычки слева. Они появятся на всех 12 листах-месяцах.
C7: Имя | E7: необязательно | H7: 2. «Цель, дней в месяц» — для привычек не на каждый день (зал 3 раза в неделю ≈ 12). Пусто = ежедневно.
C8: Девиз года | D8: Не идеально, а регулярно. | H8: 3. Открой лист текущего месяца и каждый вечер ставь галочки. Один клик — готово.
B10: МОИ ПРИВЫЧКИ | H10: 4. Под сеткой отмечай сон, энергию и настроение — планер покажет, как они влияют на результат.
B11: № | C11: Сфера | D11: Привычка | E11: Цель, дней в месяц | F11: Зачем мне это | H11: 5. В дневнике внизу листа пиши одну строку в день: событие, урок, победа.
B12: 1 | C12: Здоровье | D12: Подъём до 7:00 | F12: Утро задаёт весь день | H12: 6. Раз в неделю смотри «Прогресс», серии 🔥, слабый день и «Подтянуть» — и корректируй план.
B13: 2 | C13: Спорт | D13: Тренировка | E13: 12 | F13: Сила, энергия, форма | H13: ЧТО СЧИТАЕТСЯ САМО
B14: 3 | C14: Здоровье | D14: 10 000 шагов | F14: Голова яснее, сон крепче | H14: • Прогресс каждой привычки, каждого дня, недели и месяца — относительно уже прошедших дней.
B15: 4 | C15: Учёба | D15: Чтение 20 минут | F15: 24 книги за год | H15: • Серии подряд 🔥 и личный рекорд по каждой привычке.
B16: 5 | C16: Личное | D16: Медитация 10 минут | F16: Спокойствие и фокус | H16: • Лучший и слабый день, топ-привычка и что подтянуть, идеальные дни (100%).
B17: 6 | C17: Здоровье | D17: Без сахара | F17: Ровная энергия весь день | H17: • Инсайты: средний сон и энергия, прогресс при хорошем и плохом сне.
B18: 7 | C18: Работа | D18: План на завтра | F18: Утро без хаоса | H18: • Лист «Год»: итоги по месяцам, график и тепловая карта «привычки × месяцы».
B19: 8 | C19: Учёба | D19: Английский 15 минут | E19: 20 | F19: Свободно говорить к лету | H19: СОВМЕСТИМОСТЬ
B20: 9 | H20: • Excel 365 (Windows, Mac, Web, iPhone/iPad, Android) — чекбоксы работают сразу.
B21: 10 | H21: • Google Таблицы: после импорта выдели область галочек → Вставка → Флажок. Формулы работают.
B22: 11 | H22: • Старые версии Excel: вместо галочки ставь 1 — всё считается так же.
B23: 12 | H23: • Формулы в серых ячейках лучше не трогать. Скрытые колонки справа от статистики — служебные.
B24: 13
B25: 14
B26: 15
B28: Ячейки с золотистым фоном — для заполнения. Всё остальное считается автоматически.
B29: Впиши 5–10 привычек: больше — перегруз, меньше — мало данных для статистики.
B30: Пример уже заполнен — просто замени его своими привычками.
B31: Название на конкретном месяце можно перезаписать прямо на листе месяца.

Sheet Год
B2: ="ГОД "&'Старт'!$D$6&" — ИТОГИ" -> ГОД 2026 — ИТОГИ
B3: Месяцы без отметок остаются пустыми. Всё обновляется само.
B5: ПРОГРЕСС ГОДА | D5: ОТМЕТОК ЗА ГОД | G5: ИДЕАЛЬНЫХ ДНЕЙ | J5: ЛУЧШИЙ МЕСЯЦ | M5: РЕКОРД СЕРИИ
B6: =$C$22 -> 0.78548387 | D6: =$D$22 -> 447 | G6: =$E$22 -> 7 | J6: =IFERROR(INDEX($B$10:$B$21,MATCH(MAX($C$10:$C$21),$C$10:$C$21,0)),"—") -> Сентябрь | M6: =$F$22 -> 17
B7: средний прогресс начатых месяцев | D7: выполненных привычек | G7: дней, когда сделано всё | J7: по прогрессу | M7: самая длинная серия года
B9: Месяц | C9: Прогресс | D9: Отметок | E9: Идеальных дней | F9: Лучшая серия | G9: Сон, ч | H9: Энергия
B10: Январь | C10: =IF(OR('Январь'!$AP$3=0,'Январь'!$AP$6=0),"",'Январь'!$AP$7) | D10: =IF(OR('Январь'!$AP$3=0,'Январь'!$AP$6=0),"",'Январь'!$AP$6) | E10: =IF(OR('Январь'!$AP$3=0,'Январь'!$AP$6=0),"",'Январь'!$AP$9) | F10: =IF(OR('Январь'!$AP$3=0,'Январь'!$AP$6=0),"",MAX('Январь'!$AN$12:$AN$26)) | G10: =IF(OR('Январь'!$AP$3=0,'Январь'!$AP$6=0),"",IFERROR(ROUND(AVERAGE('Январь'!$E$30:$AI$30),1),"—")) | H10: =IF(OR('Январь'!$AP$3=0,'Январь'!$AP$6=0),"",IFERROR(ROUND(AVERAGE('Январь'!$E$31:$AI$31),1),"—"))
B11: Февраль | C11: =IF(OR('Февраль'!$AP$3=0,'Февраль'!$AP$6=0),"",'Февраль'!$AP$7) | D11: =IF(OR('Февраль'!$AP$3=0,'Февраль'!$AP$6=0),"",'Февраль'!$AP$6) | E11: =IF(OR('Февраль'!$AP$3=0,'Февраль'!$AP$6=0),"",'Февраль'!$AP$9) | F11: =IF(OR('Февраль'!$AP$3=0,'Февраль'!$AP$6=0),"",MAX('Февраль'!$AN$12:$AN$26)) | G11: =IF(OR('Февраль'!$AP$3=0,'Февраль'!$AP$6=0),"",IFERROR(ROUND(AVERAGE('Февраль'!$E$30:$AI$30),1),"—")) | H11: =IF(OR('Февраль'!$AP$3=0,'Февраль'!$AP$6=0),"",IFERROR(ROUND(AVERAGE('Февраль'!$E$31:$AI$31),1),"—"))
B12: Март | C12: =IF(OR('Март'!$AP$3=0,'Март'!$AP$6=0),"",'Март'!$AP$7) | D12: =IF(OR('Март'!$AP$3=0,'Март'!$AP$6=0),"",'Март'!$AP$6) | E12: =IF(OR('Март'!$AP$3=0,'Март'!$AP$6=0),"",'Март'!$AP$9) | F12: =IF(OR('Март'!$AP$3=0,'Март'!$AP$6=0),"",MAX('Март'!$AN$12:$AN$26)) | G12: =IF(OR('Март'!$AP$3=0,'Март'!$AP$6=0),"",IFERROR(ROUND(AVERAGE('Март'!$E$30:$AI$30),1),"—")) | H12: =IF(OR('Март'!$AP$3=0,'Март'!$AP$6=0),"",IFERROR(ROUND(AVERAGE('Март'!$E$31:$AI$31),1),"—"))
B13: Апрель | C13: =IF(OR('Апрель'!$AP$3=0,'Апрель'!$AP$6=0),"",'Апрель'!$AP$7) | D13: =IF(OR('Апрель'!$AP$3=0,'Апрель'!$AP$6=0),"",'Апрель'!$AP$6) | E13: =IF(OR('Апрель'!$AP$3=0,'Апрель'!$AP$6=0),"",'Апрель'!$AP$9) | F13: =IF(OR('Апрель'!$AP$3=0,'Апрель'!$AP$6=0),"",MAX('Апрель'!$AN$12:$AN$26)) | G13: =IF(OR('Апрель'!$AP$3=0,'Апрель'!$AP$6=0),"",IFERROR(ROUND(AVERAGE('Апрель'!$E$30:$AI$30),1),"—")) | H13: =IF(OR('Апрель'!$AP$3=0,'Апрель'!$AP$6=0),"",IFERROR(ROUND(AVERAGE('Апрель'!$E$31:$AI$31),1),"—"))
B14: Май | C14: =IF(OR('Май'!$AP$3=0,'Май'!$AP$6=0),"",'Май'!$AP$7) | D14: =IF(OR('Май'!$AP$3=0,'Май'!$AP$6=0),"",'Май'!$AP$6) | E14: =IF(OR('Май'!$AP$3=0,'Май'!$AP$6=0),"",'Май'!$AP$9) | F14: =IF(OR('Май'!$AP$3=0,'Май'!$AP$6=0),"",MAX('Май'!$AN$12:$AN$26)) | G14: =IF(OR('Май'!$AP$3=0,'Май'!$AP$6=0),"",IFERROR(ROUND(AVERAGE('Май'!$E$30:$AI$30),1),"—")) | H14: =IF(OR('Май'!$AP$3=0,'Май'!$AP$6=0),"",IFERROR(ROUND(AVERAGE('Май'!$E$31:$AI$31),1),"—"))
B15: Июнь | C15: =IF(OR('Июнь'!$AP$3=0,'Июнь'!$AP$6=0),"",'Июнь'!$AP$7) | D15: =IF(OR('Июнь'!$AP$3=0,'Июнь'!$AP$6=0),"",'Июнь'!$AP$6) | E15: =IF(OR('Июнь'!$AP$3=0,'Июнь'!$AP$6=0),"",'Июнь'!$AP$9) | F15: =IF(OR('Июнь'!$AP$3=0,'Июнь'!$AP$6=0),"",MAX('Июнь'!$AN$12:$AN$26)) | G15: =IF(OR('Июнь'!$AP$3=0,'Июнь'!$AP$6=0),"",IFERROR(ROUND(AVERAGE('Июнь'!$E$30:$AI$30),1),"—")) | H15: =IF(OR('Июнь'!$AP$3=0,'Июнь'!$AP$6=0),"",IFERROR(ROUND(AVERAGE('Июнь'!$E$31:$AI$31),1),"—"))
B16: Июль | C16: =IF(OR('Июль'!$AP$3=0,'Июль'!$AP$6=0),"",'Июль'!$AP$7) -> 0.78185484 | D16: =IF(OR('Июль'!$AP$3=0,'Июль'!$AP$6=0),"",'Июль'!$AP$6) -> 169 | E16: =IF(OR('Июль'!$AP$3=0,'Июль'!$AP$6=0),"",'Июль'!$AP$9) -> 2 | F16: =IF(OR('Июль'!$AP$3=0,'Июль'!$AP$6=0),"",MAX('Июль'!$AN$12:$AN$26)) -> 13 | G16: =IF(OR('Июль'!$AP$3=0,'Июль'!$AP$6=0),"",IFERROR(ROUND(AVERAGE('Июль'!$E$30:$AI$30),1),"—")) -> 7.3 | H16: =IF(OR('Июль'!$AP$3=0,'Июль'!$AP$6=0),"",IFERROR(ROUND(AVERAGE('Июль'!$E$31:$AI$31),1),"—")) -> 3.7
B17: Август | C17: =IF(OR('Август'!$AP$3=0,'Август'!$AP$6=0),"",'Август'!$AP$7) -> 0.74959677 | D17: =IF(OR('Август'!$AP$3=0,'Август'!$AP$6=0),"",'Август'!$AP$6) -> 160 | E17: =IF(OR('Август'!$AP$3=0,'Август'!$AP$6=0),"",'Август'!$AP$9) -> 3 | F17: =IF(OR('Август'!$AP$3=0,'Август'!$AP$6=0),"",MAX('Август'!$AN$12:$AN$26)) -> 15 | G17: =IF(OR('Август'!$AP$3=0,'Август'!$AP$6=0),"",IFERROR(ROUND(AVERAGE('Август'!$E$30:$AI$30),1),"—")) -> 6.6 | H17: =IF(OR('Август'!$AP$3=0,'Август'!$AP$6=0),"",IFERROR(ROUND(AVERAGE('Август'!$E$31:$AI$31),1),"—")) -> 3.6
B18: Сентябрь | C18: =IF(OR('Сентябрь'!$AP$3=0,'Сентябрь'!$AP$6=0),"",'Сентябрь'!$AP$7) -> 0.825 | D18: =IF(OR('Сентябрь'!$AP$3=0,'Сентябрь'!$AP$6=0),"",'Сентябрь'!$AP$6) -> 118 | E18: =IF(OR('Сентябрь'!$AP$3=0,'Сентябрь'!$AP$6=0),"",'Сентябрь'!$AP$9) -> 2 | F18: =IF(OR('Сентябрь'!$AP$3=0,'Сентябрь'!$AP$6=0),"",MAX('Сентябрь'!$AN$12:$AN$26)) -> 17 | G18: =IF(OR('Сентябрь'!$AP$3=0,'Сентябрь'!$AP$6=0),"",IFERROR(ROUND(AVERAGE('Сентябрь'!$E$30:$AI$30),1),"—")) -> 7 | H18: =IF(OR('Сентябрь'!$AP$3=0,'Сентябрь'!$AP$6=0),"",IFERROR(ROUND(AVERAGE('Сентябрь'!$E$31:$AI$31),1),"—")) -> 4.1
B19: Октябрь | C19: =IF(OR('Октябрь'!$AP$3=0,'Октябрь'!$AP$6=0),"",'Октябрь'!$AP$7) | D19: =IF(OR('Октябрь'!$AP$3=0,'Октябрь'!$AP$6=0),"",'Октябрь'!$AP$6) | E19: =IF(OR('Октябрь'!$AP$3=0,'Октябрь'!$AP$6=0),"",'Октябрь'!$AP$9) | F19: =IF(OR('Октябрь'!$AP$3=0,'Октябрь'!$AP$6=0),"",MAX('Октябрь'!$AN$12:$AN$26)) | G19: =IF(OR('Октябрь'!$AP$3=0,'Октябрь'!$AP$6=0),"",IFERROR(ROUND(AVERAGE('Октябрь'!$E$30:$AI$30),1),"—")) | H19: =IF(OR('Октябрь'!$AP$3=0,'Октябрь'!$AP$6=0),"",IFERROR(ROUND(AVERAGE('Октябрь'!$E$31:$AI$31),1),"—"))
B20: Ноябрь | C20: =IF(OR('Ноябрь'!$AP$3=0,'Ноябрь'!$AP$6=0),"",'Ноябрь'!$AP$7) | D20: =IF(OR('Ноябрь'!$AP$3=0,'Ноябрь'!$AP$6=0),"",'Ноябрь'!$AP$6) | E20: =IF(OR('Ноябрь'!$AP$3=0,'Ноябрь'!$AP$6=0),"",'Ноябрь'!$AP$9) | F20: =IF(OR('Ноябрь'!$AP$3=0,'Ноябрь'!$AP$6=0),"",MAX('Ноябрь'!$AN$12:$AN$26)) | G20: =IF(OR('Ноябрь'!$AP$3=0,'Ноябрь'!$AP$6=0),"",IFERROR(ROUND(AVERAGE('Ноябрь'!$E$30:$AI$30),1),"—")) | H20: =IF(OR('Ноябрь'!$AP$3=0,'Ноябрь'!$AP$6=0),"",IFERROR(ROUND(AVERAGE('Ноябрь'!$E$31:$AI$31),1),"—"))
B21: Декабрь | C21: =IF(OR('Декабрь'!$AP$3=0,'Декабрь'!$AP$6=0),"",'Декабрь'!$AP$7) | D21: =IF(OR('Декабрь'!$AP$3=0,'Декабрь'!$AP$6=0),"",'Декабрь'!$AP$6) | E21: =IF(OR('Декабрь'!$AP$3=0,'Декабрь'!$AP$6=0),"",'Декабрь'!$AP$9) | F21: =IF(OR('Декабрь'!$AP$3=0,'Декабрь'!$AP$6=0),"",MAX('Декабрь'!$AN$12:$AN$26)) | G21: =IF(OR('Декабрь'!$AP$3=0,'Декабрь'!$AP$6=0),"",IFERROR(ROUND(AVERAGE('Декабрь'!$E$30:$AI$30),1),"—")) | H21: =IF(OR('Декабрь'!$AP$3=0,'Декабрь'!$AP$6=0),"",IFERROR(ROUND(AVERAGE('Декабрь'!$E$31:$AI$31),1),"—"))
B22: Итого / среднее | C22: =IFERROR(AVERAGE($C$10:$C$21),0) -> 0.78548387 | D22: =SUM($D$10:$D$21) -> 447 | E22: =SUM($E$10:$E$21) -> 7 | F22: =MAX(0,MAX($F$10:$F$21)) -> 17 | G22: =IFERROR(ROUND(AVERAGE($G$10:$G$21),1),"—") -> 7 | H22: =IFERROR(ROUND(AVERAGE($H$10:$H$21),1),"—") -> 3.8
B24: ПРОГРЕСС ПО МЕСЯЦАМ
B40: КАРТА ПРИВЫЧЕК: ПРОГРЕСС ПО МЕСЯЦАМ
B41: Привычка | C41: янв | D41: фев | E41: мар | F41: апр | G41: мая | H41: июн | I41: июл | J41: авг | K41: сен | L41: окт | M41: ноя | N41: дек | O41: Год
B42: =IF('Старт'!$D$12="","",'Старт'!$D$12) -> Подъём до 7:00 | C42: =IF(OR('Январь'!$AP$3=0,'Январь'!$AP$6=0,'Январь'!$AL$12=""),"",'Январь'!$AL$12) | D42: =IF(OR('Февраль'!$AP$3=0,'Февраль'!$AP$6=0,'Февраль'!$AL$12=""),"",'Февраль'!$AL$12) | E42: =IF(OR('Март'!$AP$3=0,'Март'!$AP$6=0,'Март'!$AL$12=""),"",'Март'!$AL$12) | F42: =IF(OR('Апрель'!$AP$3=0,'Апрель'!$AP$6=0,'Апрель'!$AL$12=""),"",'Апрель'!$AL$12) | G42: =IF(OR('Май'!$AP$3=0,'Май'!$AP$6=0,'Май'!$AL$12=""),"",'Май'!$AL$12) | H42: =IF(OR('Июнь'!$AP$3=0,'Июнь'!$AP$6=0,'Июнь'!$AL$12=""),"",'Июнь'!$AL$12) | I42: =IF(OR('Июль'!$AP$3=0,'Июль'!$AP$6=0,'Июль'!$AL$12=""),"",'Июль'!$AL$12) -> 0.90322581 | J42: =IF(OR('Август'!$AP$3=0,'Август'!$AP$6=0,'Август'!$AL$12=""),"",'Август'!$AL$12) -> 0.70967742 | K42: =IF(OR('Сентябрь'!$AP$3=0,'Сентябрь'!$AP$6=0,'Сентябрь'!$AL$12=""),"",'Сентябрь'!$AL$12) -> 0.95 | L42: =IF(OR('Октябрь'!$AP$3=0,'Октябрь'!$AP$6=0,'Октябрь'!$AL$12=""),"",'Октябрь'!$AL$12) | M42: =IF(OR('Ноябрь'!$AP$3=0,'Ноябрь'!$AP$6=0,'Ноябрь'!$AL$12=""),"",'Ноябрь'!$AL$12) | N42: =IF(OR('Декабрь'!$AP$3=0,'Декабрь'!$AP$6=0,'Декабрь'!$AL$12=""),"",'Декабрь'!$AL$12) | O42: =IFERROR(AVERAGE($C$42:$N$42),"") -> 0.85430108
B43: =IF('Старт'!$D$13="","",'Старт'!$D$13) -> Тренировка | C43: =IF(OR('Январь'!$AP$3=0,'Январь'!$AP$6=0,'Январь'!$AL$13=""),"",'Январь'!$AL$13) | D43: =IF(OR('Февраль'!$AP$3=0,'Февраль'!$AP$6=0,'Февраль'!$AL$13=""),"",'Февраль'!$AL$13) | E43: =IF(OR('Март'!$AP$3=0,'Март'!$AP$6=0,'Март'!$AL$13=""),"",'Март'!$AL$13) | F43: =IF(OR('Апрель'!$AP$3=0,'Апрель'!$AP$6=0,'Апрель'!$AL$13=""),"",'Апрель'!$AL$13) | G43: =IF(OR('Май'!$AP$3=0,'Май'!$AP$6=0,'Май'!$AL$13=""),"",'Май'!$AL$13) | H43: =IF(OR('Июнь'!$AP$3=0,'Июнь'!$AP$6=0,'Июнь'!$AL$13=""),"",'Июнь'!$AL$13) | I43: =IF(OR('Июль'!$AP$3=0,'Июль'!$AP$6=0,'Июль'!$AL$13=""),"",'Июль'!$AL$13) -> 1 | J43: =IF(OR('Август'!$AP$3=0,'Август'!$AP$6=0,'Август'!$AL$13=""),"",'Август'!$AL$13) -> 1 | K43: =IF(OR('Сентябрь'!$AP$3=0,'Сентябрь'!$AP$6=0,'Сентябрь'!$AL$13=""),"",'Сентябрь'!$AL$13) -> 1 | L43: =IF(OR('Октябрь'!$AP$3=0,'Октябрь'!$AP$6=0,'Октябрь'!$AL$13=""),"",'Октябрь'!$AL$13) | M43: =IF(OR('Ноябрь'!$AP$3=0,'Ноябрь'!$AP$6=0,'Ноябрь'!$AL$13=""),"",'Ноябрь'!$AL$13) | N43: =IF(OR('Декабрь'!$AP$3=0,'Декабрь'!$AP$6=0,'Декабрь'!$AL$13=""),"",'Декабрь'!$AL$13) | O43: =IFERROR(AVERAGE($C$43:$N$43),"") -> 1
B44: =IF('Старт'!$D$14="","",'Старт'!$D$14) -> 10 000 шагов | C44: =IF(OR('Январь'!$AP$3=0,'Январь'!$AP$6=0,'Январь'!$AL$14=""),"",'Январь'!$AL$14) | D44: =IF(OR('Февраль'!$AP$3=0,'Февраль'!$AP$6=0,'Февраль'!$AL$14=""),"",'Февраль'!$AL$14) | E44: =IF(OR('Март'!$AP$3=0,'Март'!$AP$6=0,'Март'!$AL$14=""),"",'Март'!$AL$14) | F44: =IF(OR('Апрель'!$AP$3=0,'Апрель'!$AP$6=0,'Апрель'!$AL$14=""),"",'Апрель'!$AL$14) | G44: =IF(OR('Май'!$AP$3=0,'Май'!$AP$6=0,'Май'!$AL$14=""),"",'Май'!$AL$14) | H44: =IF(OR('Июнь'!$AP$3=0,'Июнь'!$AP$6=0,'Июнь'!$AL$14=""),"",'Июнь'!$AL$14) | I44: =IF(OR('Июль'!$AP$3=0,'Июль'!$AP$6=0,'Июль'!$AL$14=""),"",'Июль'!$AL$14) -> 0.74193548 | J44: =IF(OR('Август'!$AP$3=0,'Август'!$AP$6=0,'Август'!$AL$14=""),"",'Август'!$AL$14) -> 0.74193548 | K44: =IF(OR('Сентябрь'!$AP$3=0,'Сентябрь'!$AP$6=0,'Сентябрь'!$AL$14=""),"",'Сентябрь'!$AL$14) -> 0.65 | L44: =IF(OR('Октябрь'!$AP$3=0,'Октябрь'!$AP$6=0,'Октябрь'!$AL$14=""),"",'Октябрь'!$AL$14) | M44: =IF(OR('Ноябрь'!$AP$3=0,'Ноябрь'!$AP$6=0,'Ноябрь'!$AL$14=""),"",'Ноябрь'!$AL$14) | N44: =IF(OR('Декабрь'!$AP$3=0,'Декабрь'!$AP$6=0,'Декабрь'!$AL$14=""),"",'Декабрь'!$AL$14) | O44: =IFERROR(AVERAGE($C$44:$N$44),"") -> 0.71129032
B45: =IF('Старт'!$D$15="","",'Старт'!$D$15) -> Чтение 20 минут | C45: =IF(OR('Январь'!$AP$3=0,'Январь'!$AP$6=0,'Январь'!$AL$15=""),"",'Январь'!$AL$15) | D45: =IF(OR('Февраль'!$AP$3=0,'Февраль'!$AP$6=0,'Февраль'!$AL$15=""),"",'Февраль'!$AL$15) | E45: =IF(OR('Март'!$AP$3=0,'Март'!$AP$6=0,'Март'!$AL$15=""),"",'Март'!$AL$15) | F45: =IF(OR('Апрель'!$AP$3=0,'Апрель'!$AP$6=0,'Апрель'!$AL$15=""),"",'Апрель'!$AL$15) | G45: =IF(OR('Май'!$AP$3=0,'Май'!$AP$6=0,'Май'!$AL$15=""),"",'Май'!$AL$15) | H45: =IF(OR('Июнь'!$AP$3=0,'Июнь'!$AP$6=0,'Июнь'!$AL$15=""),"",'Июнь'!$AL$15) | I45: =IF(OR('Июль'!$AP$3=0,'Июль'!$AP$6=0,'Июль'!$AL$15=""),"",'Июль'!$AL$15) -> 0.80645161 | J45: =IF(OR('Август'!$AP$3=0,'Август'!$AP$6=0,'Август'!$AL$15=""),"",'Август'!$AL$15) -> 0.70967742 | K45: =IF(OR('Сентябрь'!$AP$3=0,'Сентябрь'!$AP$6=0,'Сентябрь'!$AL$15=""),"",'Сентябрь'!$AL$15) -> 0.95 | L45: =IF(OR('Октябрь'!$AP$3=0,'Октябрь'!$AP$6=0,'Октябрь'!$AL$15=""),"",'Октябрь'!$AL$15) | M45: =IF(OR('Ноябрь'!$AP$3=0,'Ноябрь'!$AP$6=0,'Ноябрь'!$AL$15=""),"",'Ноябрь'!$AL$15) | N45: =IF(OR('Декабрь'!$AP$3=0,'Декабрь'!$AP$6=0,'Декабрь'!$AL$15=""),"",'Декабрь'!$AL$15) | O45: =IFERROR(AVERAGE($C$45:$N$45),"") -> 0.82204301
B46: =IF('Старт'!$D$16="","",'Старт'!$D$16) -> Медитация 10 минут | C46: =IF(OR('Январь'!$AP$3=0,'Январь'!$AP$6=0,'Январь'!$AL$16=""),"",'Январь'!$AL$16) | D46: =IF(OR('Февраль'!$AP$3=0,'Февраль'!$AP$6=0,'Февраль'!$AL$16=""),"",'Февраль'!$AL$16) | E46: =IF(OR('Март'!$AP$3=0,'Март'!$AP$6=0,'Март'!$AL$16=""),"",'Март'!$AL$16) | F46: =IF(OR('Апрель'!$AP$3=0,'Апрель'!$AP$6=0,'Апрель'!$AL$16=""),"",'Апрель'!$AL$16) | G46: =IF(OR('Май'!$AP$3=0,'Май'!$AP$6=0,'Май'!$AL$16=""),"",'Май'!$AL$16) | H46: =IF(OR('Июнь'!$AP$3=0,'Июнь'!$AP$6=0,'Июнь'!$AL$16=""),"",'Июнь'!$AL$16) | I46: =IF(OR('Июль'!$AP$3=0,'Июль'!$AP$6=0,'Июль'!$AL$16=""),"",'Июль'!$AL$16) -> 0.61290323 | J46: =IF(OR('Август'!$AP$3=0,'Август'!$AP$6=0,'Август'!$AL$16=""),"",'Август'!$AL$16) -> 0.67741935 | K46: =IF(OR('Сентябрь'!$AP$3=0,'Сентябрь'!$AP$6=0,'Сентябрь'!$AL$16=""),"",'Сентябрь'!$AL$16) -> 0.55 | L46: =IF(OR('Октябрь'!$AP$3=0,'Октябрь'!$AP$6=0,'Октябрь'!$AL$16=""),"",'Октябрь'!$AL$16) | M46: =IF(OR('Ноябрь'!$AP$3=0,'Ноябрь'!$AP$6=0,'Ноябрь'!$AL$16=""),"",'Ноябрь'!$AL$16) | N46: =IF(OR('Декабрь'!$AP$3=0,'Декабрь'!$AP$6=0,'Декабрь'!$AL$16=""),"",'Декабрь'!$AL$16) | O46: =IFERROR(AVERAGE($C$46:$N$46),"") -> 0.61344086
B47: =IF('Старт'!$D$17="","",'Старт'!$D$17) -> Без сахара | C47: =IF(OR('Январь'!$AP$3=0,'Январь'!$AP$6=0,'Январь'!$AL$17=""),"",'Январь'!$AL$17) | D47: =IF(OR('Февраль'!$AP$3=0,'Февраль'!$AP$6=0,'Февраль'!$AL$17=""),"",'Февраль'!$AL$17) | E47: =IF(OR('Март'!$AP$3=0,'Март'!$AP$6=0,'Март'!$AL$17=""),"",'Март'!$AL$17) | F47: =IF(OR('Апрель'!$AP$3=0,'Апрель'!$AP$6=0,'Апрель'!$AL$17=""),"",'Апрель'!$AL$17) | G47: =IF(OR('Май'!$AP$3=0,'Май'!$AP$6=0,'Май'!$AL$17=""),"",'Май'!$AL$17) | H47: =IF(OR('Июнь'!$AP$3=0,'Июнь'!$AP$6=0,'Июнь'!$AL$17=""),"",'Июнь'!$AL$17) | I47: =IF(OR('Июль'!$AP$3=0,'Июль'!$AP$6=0,'Июль'!$AL$17=""),"",'Июль'!$AL$17) -> 0.4516129 | J47: =IF(OR('Август'!$AP$3=0,'Август'!$AP$6=0,'Август'!$AL$17=""),"",'Август'!$AL$17) -> 0.4516129 | K47: =IF(OR('Сентябрь'!$AP$3=0,'Сентябрь'!$AP$6=0,'Сентябрь'!$AL$17=""),"",'Сентябрь'!$AL$17) -> 0.55 | L47: =IF(OR('Октябрь'!$AP$3=0,'Октябрь'!$AP$6=0,'Октябрь'!$AL$17=""),"",'Октябрь'!$AL$17) | M47: =IF(OR('Ноябрь'!$AP$3=0,'Ноябрь'!$AP$6=0,'Ноябрь'!$AL$17=""),"",'Ноябрь'!$AL$17) | N47: =IF(OR('Декабрь'!$AP$3=0,'Декабрь'!$AP$6=0,'Декабрь'!$AL$17=""),"",'Декабрь'!$AL$17) | O47: =IFERROR(AVERAGE($C$47:$N$47),"") -> 0.4844086
B48: =IF('Старт'!$D$18="","",'Старт'!$D$18) -> План на завтра | C48: =IF(OR('Январь'!$AP$3=0,'Январь'!$AP$6=0,'Январь'!$AL$18=""),"",'Январь'!$AL$18) | D48: =IF(OR('Февраль'!$AP$3=0,'Февраль'!$AP$6=0,'Февраль'!$AL$18=""),"",'Февраль'!$AL$18) | E48: =IF(OR('Март'!$AP$3=0,'Март'!$AP$6=0,'Март'!$AL$18=""),"",'Март'!$AL$18) | F48: =IF(OR('Апрель'!$AP$3=0,'Апрель'!$AP$6=0,'Апрель'!$AL$18=""),"",'Апрель'!$AL$18) | G48: =IF(OR('Май'!$AP$3=0,'Май'!$AP$6=0,'Май'!$AL$18=""),"",'Май'!$AL$18) | H48: =IF(OR('Июнь'!$AP$3=0,'Июнь'!$AP$6=0,'Июнь'!$AL$18=""),"",'Июнь'!$AL$18) | I48: =IF(OR('Июль'!$AP$3=0,'Июль'!$AP$6=0,'Июль'!$AL$18=""),"",'Июль'!$AL$18) -> 0.83870968 | J48: =IF(OR('Август'!$AP$3=0,'Август'!$AP$6=0,'Август'!$AL$18=""),"",'Август'!$AL$18) -> 0.80645161 | K48: =IF(OR('Сентябрь'!$AP$3=0,'Сентябрь'!$AP$6=0,'Сентябрь'!$AL$18=""),"",'Сентябрь'!$AL$18) -> 0.95 | L48: =IF(OR('Октябрь'!$AP$3=0,'Октябрь'!$AP$6=0,'Октябрь'!$AL$18=""),"",'Октябрь'!$AL$18) | M48: =IF(OR('Ноябрь'!$AP$3=0,'Ноябрь'!$AP$6=0,'Ноябрь'!$AL$18=""),"",'Ноябрь'!$AL$18) | N48: =IF(OR('Декабрь'!$AP$3=0,'Декабрь'!$AP$6=0,'Декабрь'!$AL$18=""),"",'Декабрь'!$AL$18) | O48: =IFERROR(AVERAGE($C$48:$N$48),"") -> 0.86505376
B49: =IF('Старт'!$D$19="","",'Старт'!$D$19) -> Английский 15 минут | C49: =IF(OR('Январь'!$AP$3=0,'Январь'!$AP$6=0,'Январь'!$AL$19=""),"",'Январь'!$AL$19) | D49: =IF(OR('Февраль'!$AP$3=0,'Февраль'!$AP$6=0,'Февраль'!$AL$19=""),"",'Февраль'!$AL$19) | E49: =IF(OR('Март'!$AP$3=0,'Март'!$AP$6=0,'Март'!$AL$19=""),"",'Март'!$AL$19) | F49: =IF(OR('Апрель'!$AP$3=0,'Апрель'!$AP$6=0,'Апрель'!$AL$19=""),"",'Апрель'!$AL$19) | G49: =IF(OR('Май'!$AP$3=0,'Май'!$AP$6=0,'Май'!$AL$19=""),"",'Май'!$AL$19) | H49: =IF(OR('Июнь'!$AP$3=0,'Июнь'!$AP$6=0,'Июнь'!$AL$19=""),"",'Июнь'!$AL$19) | I49: =IF(OR('Июль'!$AP$3=0,'Июль'!$AP$6=0,'Июль'!$AL$19=""),"",'Июль'!$AL$19) -> 0.9 | J49: =IF(OR('Август'!$AP$3=0,'Август'!$AP$6=0,'Август'!$AL$19=""),"",'Август'!$AL$19) -> 0.9 | K49: =IF(OR('Сентябрь'!$AP$3=0,'Сентябрь'!$AP$6=0,'Сентябрь'!$AL$19=""),"",'Сентябрь'!$AL$19) -> 1 | L49: =IF(OR('Октябрь'!$AP$3=0,'Октябрь'!$AP$6=0,'Октябрь'!$AL$19=""),"",'Октябрь'!$AL$19) | M49: =IF(OR('Ноябрь'!$AP$3=0,'Ноябрь'!$AP$6=0,'Ноябрь'!$AL$19=""),"",'Ноябрь'!$AL$19) | N49: =IF(OR('Декабрь'!$AP$3=0,'Декабрь'!$AP$6=0,'Декабрь'!$AL$19=""),"",'Декабрь'!$AL$19) | O49: =IFERROR(AVERAGE($C$49:$N$49),"") -> 0.93333333
B50: =IF('Старт'!$D$20="","",'Старт'!$D$20) | C50: =IF(OR('Январь'!$AP$3=0,'Январь'!$AP$6=0,'Январь'!$AL$20=""),"",'Январь'!$AL$20) | D50: =IF(OR('Февраль'!$AP$3=0,'Февраль'!$AP$6=0,'Февраль'!$AL$20=""),"",'Февраль'!$AL$20) | E50: =IF(OR('Март'!$AP$3=0,'Март'!$AP$6=0,'Март'!$AL$20=""),"",'Март'!$AL$20) | F50: =IF(OR('Апрель'!$AP$3=0,'Апрель'!$AP$6=0,'Апрель'!$AL$20=""),"",'Апрель'!$AL$20) | G50: =IF(OR('Май'!$AP$3=0,'Май'!$AP$6=0,'Май'!$AL$20=""),"",'Май'!$AL$20) | H50: =IF(OR('Июнь'!$AP$3=0,'Июнь'!$AP$6=0,'Июнь'!$AL$20=""),"",'Июнь'!$AL$20) | I50: =IF(OR('Июль'!$AP$3=0,'Июль'!$AP$6=0,'Июль'!$AL$20=""),"",'Июль'!$AL$20) | J50: =IF(OR('Август'!$AP$3=0,'Август'!$AP$6=0,'Август'!$AL$20=""),"",'Август'!$AL$20) | K50: =IF(OR('Сентябрь'!$AP$3=0,'Сентябрь'!$AP$6=0,'Сентябрь'!$AL$20=""),"",'Сентябрь'!$AL$20) | L50: =IF(OR('Октябрь'!$AP$3=0,'Октябрь'!$AP$6=0,'Октябрь'!$AL$20=""),"",'Октябрь'!$AL$20) | M50: =IF(OR('Ноябрь'!$AP$3=0,'Ноябрь'!$AP$6=0,'Ноябрь'!$AL$20=""),"",'Ноябрь'!$AL$20) | N50: =IF(OR('Декабрь'!$AP$3=0,'Декабрь'!$AP$6=0,'Декабрь'!$AL$20=""),"",'Декабрь'!$AL$20) | O50: =IFERROR(AVERAGE($C$50:$N$50),"")
B51: =IF('Старт'!$D$21="","",'Старт'!$D$21) | C51: =IF(OR('Январь'!$AP$3=0,'Январь'!$AP$6=0,'Январь'!$AL$21=""),"",'Январь'!$AL$21) | D51: =IF(OR('Февраль'!$AP$3=0,'Февраль'!$AP$6=0,'Февраль'!$AL$21=""),"",'Февраль'!$AL$21) | E51: =IF(OR('Март'!$AP$3=0,'Март'!$AP$6=0,'Март'!$AL$21=""),"",'Март'!$AL$21) | F51: =IF(OR('Апрель'!$AP$3=0,'Апрель'!$AP$6=0,'Апрель'!$AL$21=""),"",'Апрель'!$AL$21) | G51: =IF(OR('Май'!$AP$3=0,'Май'!$AP$6=0,'Май'!$AL$21=""),"",'Май'!$AL$21) | H51: =IF(OR('Июнь'!$AP$3=0,'Июнь'!$AP$6=0,'Июнь'!$AL$21=""),"",'Июнь'!$AL$21) | I51: =IF(OR('Июль'!$AP$3=0,'Июль'!$AP$6=0,'Июль'!$AL$21=""),"",'Июль'!$AL$21) | J51: =IF(OR('Август'!$AP$3=0,'Август'!$AP$6=0,'Август'!$AL$21=""),"",'Август'!$AL$21) | K51: =IF(OR('Сентябрь'!$AP$3=0,'Сентябрь'!$AP$6=0,'Сентябрь'!$AL$21=""),"",'Сентябрь'!$AL$21) | L51: =IF(OR('Октябрь'!$AP$3=0,'Октябрь'!$AP$6=0,'Октябрь'!$AL$21=""),"",'Октябрь'!$AL$21) | M51: =IF(OR('Ноябрь'!$AP$3=0,'Ноябрь'!$AP$6=0,'Ноябрь'!$AL$21=""),"",'Ноябрь'!$AL$21) | N51: =IF(OR('Декабрь'!$AP$3=0,'Декабрь'!$AP$6=0,'Декабрь'!$AL$21=""),"",'Декабрь'!$AL$21) | O51: =IFERROR(AVERAGE($C$51:$N$51),"")
B52: =IF('Старт'!$D$22="","",'Старт'!$D$22) | C52: =IF(OR('Январь'!$AP$3=0,'Январь'!$AP$6=0,'Январь'!$AL$22=""),"",'Январь'!$AL$22) | D52: =IF(OR('Февраль'!$AP$3=0,'Февраль'!$AP$6=0,'Февраль'!$AL$22=""),"",'Февраль'!$AL$22) | E52: =IF(OR('Март'!$AP$3=0,'Март'!$AP$6=0,'Март'!$AL$22=""),"",'Март'!$AL$22) | F52: =IF(OR('Апрель'!$AP$3=0,'Апрель'!$AP$6=0,'Апрель'!$AL$22=""),"",'Апрель'!$AL$22) | G52: =IF(OR('Май'!$AP$3=0,'Май'!$AP$6=0,'Май'!$AL$22=""),"",'Май'!$AL$22) | H52: =IF(OR('Июнь'!$AP$3=0,'Июнь'!$AP$6=0,'Июнь'!$AL$22=""),"",'Июнь'!$AL$22) | I52: =IF(OR('Июль'!$AP$3=0,'Июль'!$AP$6=0,'Июль'!$AL$22=""),"",'Июль'!$AL$22) | J52: =IF(OR('Август'!$AP$3=0,'Август'!$AP$6=0,'Август'!$AL$22=""),"",'Август'!$AL$22) | K52: =IF(OR('Сентябрь'!$AP$3=0,'Сентябрь'!$AP$6=0,'Сентябрь'!$AL$22=""),"",'Сентябрь'!$AL$22) | L52: =IF(OR('Октябрь'!$AP$3=0,'Октябрь'!$AP$6=0,'Октябрь'!$AL$22=""),"",'Октябрь'!$AL$22) | M52: =IF(OR('Ноябрь'!$AP$3=0,'Ноябрь'!$AP$6=0,'Ноябрь'!$AL$22=""),"",'Ноябрь'!$AL$22) | N52: =IF(OR('Декабрь'!$AP$3=0,'Декабрь'!$AP$6=0,'Декабрь'!$AL$22=""),"",'Декабрь'!$AL$22) | O52: =IFERROR(AVERAGE($C$52:$N$52),"")
B53: =IF('Старт'!$D$23="","",'Старт'!$D$23) | C53: =IF(OR('Январь'!$AP$3=0,'Январь'!$AP$6=0,'Январь'!$AL$23=""),"",'Январь'!$AL$23) | D53: =IF(OR('Февраль'!$AP$3=0,'Февраль'!$AP$6=0,'Февраль'!$AL$23=""),"",'Февраль'!$AL$23) | E53: =IF(OR('Март'!$AP$3=0,'Март'!$AP$6=0,'Март'!$AL$23=""),"",'Март'!$AL$23) | F53: =IF(OR('Апрель'!$AP$3=0,'Апрель'!$AP$6=0,'Апрель'!$AL$23=""),"",'Апрель'!$AL$23) | G53: =IF(OR('Май'!$AP$3=0,'Май'!$AP$6=0,'Май'!$AL$23=""),"",'Май'!$AL$23) | H53: =IF(OR('Июнь'!$AP$3=0,'Июнь'!$AP$6=0,'Июнь'!$AL$23=""),"",'Июнь'!$AL$23) | I53: =IF(OR('Июль'!$AP$3=0,'Июль'!$AP$6=0,'Июль'!$AL$23=""),"",'Июль'!$AL$23) | J53: =IF(OR('Август'!$AP$3=0,'Август'!$AP$6=0,'Август'!$AL$23=""),"",'Август'!$AL$23) | K53: =IF(OR('Сентябрь'!$AP$3=0,'Сентябрь'!$AP$6=0,'Сентябрь'!$AL$23=""),"",'Сентябрь'!$AL$23) | L53: =IF(OR('Октябрь'!$AP$3=0,'Октябрь'!$AP$6=0,'Октябрь'!$AL$23=""),"",'Октябрь'!$AL$23) | M53: =IF(OR('Ноябрь'!$AP$3=0,'Ноябрь'!$AP$6=0,'Ноябрь'!$AL$23=""),"",'Ноябрь'!$AL$23) | N53: =IF(OR('Декабрь'!$AP$3=0,'Декабрь'!$AP$6=0,'Декабрь'!$AL$23=""),"",'Декабрь'!$AL$23) | O53: =IFERROR(AVERAGE($C$53:$N$53),"")
B54: =IF('Старт'!$D$24="","",'Старт'!$D$24) | C54: =IF(OR('Январь'!$AP$3=0,'Январь'!$AP$6=0,'Январь'!$AL$24=""),"",'Январь'!$AL$24) | D54: =IF(OR('Февраль'!$AP$3=0,'Февраль'!$AP$6=0,'Февраль'!$AL$24=""),"",'Февраль'!$AL$24) | E54: =IF(OR('Март'!$AP$3=0,'Март'!$AP$6=0,'Март'!$AL$24=""),"",'Март'!$AL$24) | F54: =IF(OR('Апрель'!$AP$3=0,'Апрель'!$AP$6=0,'Апрель'!$AL$24=""),"",'Апрель'!$AL$24) | G54: =IF(OR('Май'!$AP$3=0,'Май'!$AP$6=0,'Май'!$AL$24=""),"",'Май'!$AL$24) | H54: =IF(OR('Июнь'!$AP$3=0,'Июнь'!$AP$6=0,'Июнь'!$AL$24=""),"",'Июнь'!$AL$24) | I54: =IF(OR('Июль'!$AP$3=0,'Июль'!$AP$6=0,'Июль'!$AL$24=""),"",'Июль'!$AL$24) | J54: =IF(OR('Август'!$AP$3=0,'Август'!$AP$6=0,'Август'!$AL$24=""),"",'Август'!$AL$24) | K54: =IF(OR('Сентябрь'!$AP$3=0,'Сентябрь'!$AP$6=0,'Сентябрь'!$AL$24=""),"",'Сентябрь'!$AL$24) | L54: =IF(OR('Октябрь'!$AP$3=0,'Октябрь'!$AP$6=0,'Октябрь'!$AL$24=""),"",'Октябрь'!$AL$24) | M54: =IF(OR('Ноябрь'!$AP$3=0,'Ноябрь'!$AP$6=0,'Ноябрь'!$AL$24=""),"",'Ноябрь'!$AL$24) | N54: =IF(OR('Декабрь'!$AP$3=0,'Декабрь'!$AP$6=0,'Декабрь'!$AL$24=""),"",'Декабрь'!$AL$24) | O54: =IFERROR(AVERAGE($C$54:$N$54),"")
B55: =IF('Старт'!$D$25="","",'Старт'!$D$25) | C55: =IF(OR('Январь'!$AP$3=0,'Январь'!$AP$6=0,'Январь'!$AL$25=""),"",'Январь'!$AL$25) | D55: =IF(OR('Февраль'!$AP$3=0,'Февраль'!$AP$6=0,'Февраль'!$AL$25=""),"",'Февраль'!$AL$25) | E55: =IF(OR('Март'!$AP$3=0,'Март'!$AP$6=0,'Март'!$AL$25=""),"",'Март'!$AL$25) | F55: =IF(OR('Апрель'!$AP$3=0,'Апрель'!$AP$6=0,'Апрель'!$AL$25=""),"",'Апрель'!$AL$25) | G55: =IF(OR('Май'!$AP$3=0,'Май'!$AP$6=0,'Май'!$AL$25=""),"",'Май'!$AL$25) | H55: =IF(OR('Июнь'!$AP$3=0,'Июнь'!$AP$6=0,'Июнь'!$AL$25=""),"",'Июнь'!$AL$25) | I55: =IF(OR('Июль'!$AP$3=0,'Июль'!$AP$6=0,'Июль'!$AL$25=""),"",'Июль'!$AL$25) | J55: =IF(OR('Август'!$AP$3=0,'Август'!$AP$6=0,'Август'!$AL$25=""),"",'Август'!$AL$25) | K55: =IF(OR('Сентябрь'!$AP$3=0,'Сентябрь'!$AP$6=0,'Сентябрь'!$AL$25=""),"",'Сентябрь'!$AL$25) | L55: =IF(OR('Октябрь'!$AP$3=0,'Октябрь'!$AP$6=0,'Октябрь'!$AL$25=""),"",'Октябрь'!$AL$25) | M55: =IF(OR('Ноябрь'!$AP$3=0,'Ноябрь'!$AP$6=0,'Ноябрь'!$AL$25=""),"",'Ноябрь'!$AL$25) | N55: =IF(OR('Декабрь'!$AP$3=0,'Декабрь'!$AP$6=0,'Декабрь'!$AL$25=""),"",'Декабрь'!$AL$25) | O55: =IFERROR(AVERAGE($C$55:$N$55),"")
B56: =IF('Старт'!$D$26="","",'Старт'!$D$26) | C56: =IF(OR('Январь'!$AP$3=0,'Январь'!$AP$6=0,'Январь'!$AL$26=""),"",'Январь'!$AL$26) | D56: =IF(OR('Февраль'!$AP$3=0,'Февраль'!$AP$6=0,'Февраль'!$AL$26=""),"",'Февраль'!$AL$26) | E56: =IF(OR('Март'!$AP$3=0,'Март'!$AP$6=0,'Март'!$AL$26=""),"",'Март'!$AL$26) | F56: =IF(OR('Апрель'!$AP$3=0,'Апрель'!$AP$6=0,'Апрель'!$AL$26=""),"",'Апрель'!$AL$26) | G56: =IF(OR('Май'!$AP$3=0,'Май'!$AP$6=0,'Май'!$AL$26=""),"",'Май'!$AL$26) | H56: =IF(OR('Июнь'!$AP$3=0,'Июнь'!$AP$6=0,'Июнь'!$AL$26=""),"",'Июнь'!$AL$26) | I56: =IF(OR('Июль'!$AP$3=0,'Июль'!$AP$6=0,'Июль'!$AL$26=""),"",'Июль'!$AL$26) | J56: =IF(OR('Август'!$AP$3=0,'Август'!$AP$6=0,'Август'!$AL$26=""),"",'Август'!$AL$26) | K56: =IF(OR('Сентябрь'!$AP$3=0,'Сентябрь'!$AP$6=0,'Сентябрь'!$AL$26=""),"",'Сентябрь'!$AL$26) | L56: =IF(OR('Октябрь'!$AP$3=0,'Октябрь'!$AP$6=0,'Октябрь'!$AL$26=""),"",'Октябрь'!$AL$26) | M56: =IF(OR('Ноябрь'!$AP$3=0,'Ноябрь'!$AP$6=0,'Ноябрь'!$AL$26=""),"",'Ноябрь'!$AL$26) | N56: =IF(OR('Декабрь'!$AP$3=0,'Декабрь'!$AP$6=0,'Декабрь'!$AL$26=""),"",'Декабрь'!$AL$26) | O56: =IFERROR(AVERAGE($C$56:$N$56),"")

Sheet Январь
AP1: =DATE('Старт'!$D$6,1,1) -> 46023
B2: ="ЯНВАРЬ "&'Старт'!$D$6 -> ЯНВАРЬ 2026 | R2: ПЛАНЕР ПРИВЫЧЕК | AP2: =DAY(EOMONTH($AP$1,0)) -> 31
B3: Ставь галочку каждый день · сон, энергия и настроение — под сеткой · список привычек и цели — на листе «Старт» | R3: Ты — это то, что ты делаешь каждый день. | AP3: =IF(TODAY()<$AP$1,0,IF(TODAY()>EOMONTH($AP$1,0),$AP$2,DAY(TODAY()))) -> 31
AP4: =SUMPRODUCT(--($C$12:$C$26<>"")) -> 8
B5: ПРОГРЕСС МЕСЯЦА | E5: ИДЕАЛЬНЫХ ДНЕЙ | L5: ЛУЧШАЯ СЕРИЯ 🔥 | S5: ЛУЧШИЙ ДЕНЬ | Z5: СЛАБЫЙ ДЕНЬ | AG5: ТОП ПРИВЫЧКА | AP5: =ROUND(SUM($AP$12:$AP$26),0) -> 218
B6: =$AP$7 -> 0 | E6: =$AP$9 -> 0 | L6: =IFERROR(MAX($AN$12:$AN$26),0) -> 0 | S6: =IF($AP$3*$AP$4*$AP$6=0,"—",INDEX($E$11:$AI$11,MATCH(MAX($E$28:$AI$28),$E$28:$AI$28,0))&" янв") -> — | Z6: =IF($AP$3*$AP$4*$AP$6=0,"—",INDEX($E$11:$AI$11,MATCH(MIN($E$28:$AI$28),$E$28:$AI$28,0))&" янв") -> — | AG6: =IF($AP$3*$AP$4*$AP$6=0,"—",INDEX($C$12:$C$26,MATCH(MAX($AL$12:$AL$26),$AL$12:$AL$26,0))) -> — | AP6: =SUM($AK$12:$AK$26) -> 0
B7: =IF($AP$3=0,"месяц ещё не начался",$AP$6&" из "&$AP$5&" отметок · день "&$AP$3&" из "&$AP$2) -> 0 из 218 отметок · день 31 из 31 | E7: =IF($AP$3=0,"—","из "&$AP$3&" прошедших · все привычки ✓") -> из 31 прошедших · все привычки ✓ | L7: =IF(IFERROR(MAX($AN$12:$AN$26),0)=0,"серий пока нет",INDEX($C$12:$C$26,MATCH(MAX($AN$12:$AN$26),$AN$12:$AN$26,0))) -> серий пока нет | S7: =IF($AP$3*$AP$4*$AP$6=0,"",ROUND(MAX($E$28:$AI$28)*100,0)&"% привычек выполнено") | Z7: =IF($AP$3*$AP$4*$AP$6=0,"",ROUND(MIN($E$28:$AI$28)*100,0)&"% привычек выполнено") | AG7: =IF($AP$3*$AP$4*$AP$6=0,"","Подтянуть: "&INDEX($C$12:$C$26,MATCH(MIN($AL$12:$AL$26),$AL$12:$AL$26,0))) | AP7: =IFERROR(AVERAGE($AL$12:$AL$26),0) -> 0
AP8: =1-$AP$7 -> 1
B9: МОИ ПРИВЫЧКИ | E9: =IF(1>$AP$2,"",IF(($AP$4*MAX(0,MIN($AP$3,7)-1+1))=0,"НЕДЕЛЯ 1","НЕДЕЛЯ 1 · "&SUM($E$27:$K$27)&"/"&($AP$4*MAX(0,MIN($AP$3,7)-1+1))&" · "&ROUND(SUM($E$27:$K$27)/($AP$4*MAX(0,MIN($AP$3,7)-1+1))*100,0)&"%")) -> НЕДЕЛЯ 1 · 0/56 · 0% | L9: =IF(8>$AP$2,"",IF(($AP$4*MAX(0,MIN($AP$3,14)-8+1))=0,"НЕДЕЛЯ 2","НЕДЕЛЯ 2 · "&SUM($L$27:$R$27)&"/"&($AP$4*MAX(0,MIN($AP$3,14)-8+1))&" · "&ROUND(SUM($L$27:$R$27)/($AP$4*MAX(0,MIN($AP$3,14)-8+1))*100,0)&"%")) -> НЕДЕЛЯ 2 · 0/56 · 0% | S9: =IF(15>$AP$2,"",IF(($AP$4*MAX(0,MIN($AP$3,21)-15+1))=0,"НЕДЕЛЯ 3","НЕДЕЛЯ 3 · "&SUM($S$27:$Y$27)&"/"&($AP$4*MAX(0,MIN($AP$3,21)-15+1))&" · "&ROUND(SUM($S$27:$Y$27)/($AP$4*MAX(0,MIN($AP$3,21)-15+1))*100,0)&"%")) -> НЕДЕЛЯ 3 · 0/56 · 0% | Z9: =IF(22>$AP$2,"",IF(($AP$4*MAX(0,MIN($AP$3,28)-22+1))=0,"НЕДЕЛЯ 4","НЕДЕЛЯ 4 · "&SUM($Z$27:$AF$27)&"/"&($AP$4*MAX(0,MIN($AP$3,28)-22+1))&" · "&ROUND(SUM($Z$27:$AF$27)/($AP$4*MAX(0,MIN($AP$3,28)-22+1))*100,0)&"%")) -> НЕДЕЛЯ 4 · 0/56 · 0% | AG9: =IF(29>$AP$2,"",IF(($AP$4*MAX(0,MIN($AP$3,31)-29+1))=0,"НЕДЕЛЯ 5","НЕДЕЛЯ 5 · "&SUM($AG$27:$AI$27)&"/"&($AP$4*MAX(0,MIN($AP$3,31)-29+1))&" · "&ROUND(SUM($AG$27:$AI$27)/($AP$4*MAX(0,MIN($AP$3,31)-29+1))*100,0)&"%")) -> НЕДЕЛЯ 5 · 0/24 · 0% | AK9: СТАТИСТИКА | AP9: =SUMPRODUCT(--($E$28:$AI$28=1)) -> 0
B10: Сфера | C10: Привычка | D10: Цель | E10: =IF(1<=$AP$2,CHOOSE(WEEKDAY($AP$1+0,2),"Пн","Вт","Ср","Чт","Пт","Сб","Вс"),"") -> Чт | F10: =IF(2<=$AP$2,CHOOSE(WEEKDAY($AP$1+1,2),"Пн","Вт","Ср","Чт","Пт","Сб","Вс"),"") -> Пт | G10: =IF(3<=$AP$2,CHOOSE(WEEKDAY($AP$1+2,2),"Пн","Вт","Ср","Чт","Пт","Сб","Вс"),"") -> Сб | H10: =IF(4<=$AP$2,CHOOSE(WEEKDAY($AP$1+3,2),"Пн","Вт","Ср","Чт","Пт","Сб","Вс"),"") -> Вс | I10: =IF(5<=$AP$2,CHOOSE(WEEKDAY($AP$1+4,2),"Пн","Вт","Ср","Чт","Пт","Сб","Вс"),"") -> Пн | J10: =IF(6<=$AP$2,CHOOSE(WEEKDAY($AP$1+5,2),"Пн","Вт","Ср","Чт","Пт","Сб","Вс"),"") -> Вт | K10: =IF(7<=$AP$2,CHOOSE(WEEKDAY($AP$1+6,2),"Пн","Вт","Ср","Чт","Пт","Сб","Вс"),"") -> Ср | L10: =IF(8<=$AP$2,CHOOSE(WEEKDAY($AP$1+7,2),"Пн","Вт","Ср","Чт","Пт","Сб","Вс"),"") -> Чт | M10: =IF(9<=$AP$2,CHOOSE(WEEKDAY($AP$1+8,2),"Пн","Вт","Ср","Чт","Пт","Сб","Вс"),"") -> Пт | N10: =IF(10<=$AP$2,CHOOSE(WEEKDAY($AP$1+9,2),"Пн","Вт","Ср","Чт","Пт","Сб","Вс"),"") -> Сб | O10: =IF(11<=$AP$2,CHOOSE(WEEKDAY($AP$1+10,2),"Пн","Вт","Ср","Чт","Пт","Сб","Вс"),"") -> Вс | P10: =IF(12<=$AP$2,CHOOSE(WEEKDAY($AP$1+11,2),"Пн","Вт","Ср","Чт","Пт","Сб","Вс"),"") -> Пн | Q10: =IF(13<=$AP$2,CHOOSE(WEEKDAY($AP$1+12,2),"Пн","Вт","Ср","Чт","Пт","Сб","Вс"),"") -> Вт | R10: =IF(14<=$AP$2,CHOOSE(WEEKDAY($AP$1+13,2),"Пн","Вт","Ср","Чт","Пт","Сб","Вс"),"") -> Ср | S10: =IF(15<=$AP$2,CHOOSE(WEEKDAY($AP$1+14,2),"Пн","Вт","Ср","Чт","Пт","Сб","Вс"),"") -> Чт | T10: =IF(16<=$AP$2,CHOOSE(WEEKDAY($AP$1+15,2),"Пн","Вт","Ср","Чт","Пт","Сб","Вс"),"") -> Пт | U10: =IF(17<=$AP$2,CHOOSE(WEEKDAY($AP$1+16,2),"Пн","Вт","Ср","Чт","Пт","Сб","Вс"),"") -> Сб | V10: =IF(18<=$AP$2,CHOOSE(WEEKDAY($AP$1+17,2),"Пн","Вт","Ср","Чт","Пт","Сб","Вс"),"") -> Вс | W10: =IF(19<=$AP$2,CHOOSE(WEEKDAY($AP$1+18,2),"Пн","Вт","Ср","Чт","Пт","Сб","Вс"),"") -> Пн | X10: =IF(20<=$AP$2,CHOOSE(WEEKDAY($AP$1+19,2),"Пн","Вт","Ср","Чт","Пт","Сб","Вс"),"") -> Вт | Y10: =IF(21<=$AP$2,CHOOSE(WEEKDAY($AP$1+20,2),"Пн","Вт","Ср","Чт","Пт","Сб","Вс"),"") -> Ср | Z10: =IF(22<=$AP$2,CHOOSE(WEEKDAY($AP$1+21,2),"Пн","Вт","Ср","Чт","Пт","Сб","Вс"),"") -> Чт | AA10: =IF(23<=$AP$2,CHOOSE(WEEKDAY($AP$1+22,2),"Пн","Вт","Ср","Чт","Пт","Сб","Вс"),"") -> Пт | AB10: =IF(24<=$AP$2,CHOOSE(WEEKDAY($AP$1+23,2),"Пн","Вт","Ср","Чт","Пт","Сб","Вс"),"") -> Сб | AC10: =IF(25<=$AP$2,CHOOSE(WEEKDAY($AP$1+24,2),"Пн","Вт","Ср","Чт","Пт","Сб","Вс"),"") -> Вс | AD10: =IF(26<=$AP$2,CHOOSE(WEEKDAY($AP$1+25,2),"Пн","Вт","Ср","Чт","Пт","Сб","Вс"),"") -> Пн | AE10: =IF(27<=$AP$2,CHOOSE(WEEKDAY($AP$1+26,2),"Пн","Вт","Ср","Чт","Пт","Сб","Вс"),"") -> Вт | AF10: =IF(28<=$AP$2,CHOOSE(WEEKDAY($AP$1+27,2),"Пн","Вт","Ср","Чт","Пт","Сб","Вс"),"") -> Ср | AG10: =IF(29<=$AP$2,CHOOSE(WEEKDAY($AP$1+28,2),"Пн","Вт","Ср","Чт","Пт","Сб","Вс"),"") -> Чт | AH10: =IF(30<=$AP$2,CHOOSE(WEEKDAY($AP$1+29,2),"Пн","Вт","Ср","Чт","Пт","Сб","Вс"),"") -> Пт | AI10: =IF(31<=$AP$2,CHOOSE(WEEKDAY($AP$1+30,2),"Пн","Вт","Ср","Чт","Пт","Сб","Вс"),"") -> Сб | AK10: Сделано | AL10: Прогресс | AM10: Серия 🔥 | AN10: Рекорд
E11: =IF(1<=$AP$2,1,"") -> 1 | F11: =IF(2<=$AP$2,2,"") -> 2 | G11: =IF(3<=$AP$2,3,"") -> 3 | H11: =IF(4<=$AP$2,4,"") -> 4 | I11: =IF(5<=$AP$2,5,"") -> 5 | J11: =IF(6<=$AP$2,6,"") -> 6 | K11: =IF(7<=$AP$2,7,"") -> 7 | L11: =IF(8<=$AP$2,8,"") -> 8 | M11: =IF(9<=$AP$2,9,"") -> 9 | N11: =IF(10<=$AP$2,10,"") -> 10 | O11: =IF(11<=$AP$2,11,"") -> 11 | P11: =IF(12<=$AP$2,12,"") -> 12 | Q11: =IF(13<=$AP$2,13,"") -> 13 | R11: =IF(14<=$AP$2,14,"") -> 14 | S11: =IF(15<=$AP$2,15,"") -> 15 | T11: =IF(16<=$AP$2,16,"") -> 16 | U11: =IF(17<=$AP$2,17,"") -> 17 | V11: =IF(18<=$AP$2,18,"") -> 18 | W11: =IF(19<=$AP$2,19,"") -> 19 | X11: =IF(20<=$AP$2,20,"") -> 20 | Y11: =IF(21<=$AP$2,21,"") -> 21 | Z11: =IF(22<=$AP$2,22,"") -> 22 | AA11: =IF(23<=$AP$2,23,"") -> 23 | AB11: =IF(24<=$AP$2,24,"") -> 24 | AC11: =IF(25<=$AP$2,25,"") -> 25 | AD11: =IF(26<=$AP$2,26,"") -> 26 | AE11: =IF(27<=$AP$2,27,"") -> 27 | AF11: =IF(28<=$AP$2,28,"") -> 28 | AG11: =IF(29<=$AP$2,29,"") -> 29 | AH11: =IF(30<=$AP$2,30,"") -> 30 | AI11: =IF(31<=$AP$2,31,"") -> 31
B12: =IF('Старт'!$C$12="","",'Старт'!$C$12) -> Здоровье | C12: =IF('Старт'!$D$12="","",'Старт'!$D$12) -> Подъём до 7:00 | D12: =IF('Старт'!$E$12="","",'Старт'!$E$12) | E12: FALSE | F12: FALSE | G12: FALSE | H12: FALSE | I12: FALSE | J12: FALSE | K12: FALSE | L12: FALSE | M12: FALSE | N12: FALSE | O12: FALSE | P12: FALSE | Q12: FALSE | R12: FALSE | S12: FALSE | T12: FALSE | U12: FALSE | V12: FALSE | W12: FALSE | X12: FALSE | Y12: FALSE | Z12: FALSE | AA12: FALSE | AB12: FALSE | AC12: FALSE | AD12: FALSE | AE12: FALSE | AF12: FALSE | AG12: FALSE | AH12: FALSE | AI12: FALSE | AK12: =IF($C12="","",SUMPRODUCT((((E12:AI12=TRUE)+(E12:AI12=1))>0)*($E$11:$AI$11<>""))) -> 0 | AL12: =IF($C12="","",IF($AP$3=0,0,IFERROR(MIN(1,AK12/$AP$12),0))) -> 0 | AM12: =IF($C12="","",IF($AP$3=0,0,MAX(INDEX($AQ$12:$BU$12,$AP$3),INDEX($AQ$12:$BU$12,MAX($AP$3-1,1))))) -> 0 | AN12: =IF($C12="","",MAX($AQ$12:$BU$12)) -> 0 | AP12: =IF($C12="",0,IFERROR(IF($D12="",$AP$2,$D12)*$AP$3/$AP$2,$AP$3)) -> 31 | AQ12: =IF(AND(1<=$AP$3,OR(E12=TRUE,E12=1)),0+1,0) -> 0 | AR12: =IF(AND(2<=$AP$3,OR(F12=TRUE,F12=1)),AQ12+1,0) -> 0 | AS12: =IF(AND(3<=$AP$3,OR(G12=TRUE,G12=1)),AR12+1,0) -> 0 | AT12: =IF(AND(4<=$AP$3,OR(H12=TRUE,H12=1)),AS12+1,0) -> 0 | AU12: =IF(AND(5<=$AP$3,OR(I12=TRUE,I12=1)),AT12+1,0) -> 0 | AV12: =IF(AND(6<=$AP$3,OR(J12=TRUE,J12=1)),AU12+1,0) -> 0 | AW12: =IF(AND(7<=$AP$3,OR(K12=TRUE,K12=1)),AV12+1,0) -> 0 | AX12: =IF(AND(8<=$AP$3,OR(L12=TRUE,L12=1)),AW12+1,0) -> 0 | AY12: =IF(AND(9<=$AP$3,OR(M12=TRUE,M12=1)),AX12+1,0) -> 0 | AZ12: =IF(AND(10<=$AP$3,OR(N12=TRUE,N12=1)),AY12+1,0) -> 0 | BA12: =IF(AND(11<=$AP$3,OR(O12=TRUE,O12=1)),AZ12+1,0) -> 0 | BB12: =IF(AND(12<=$AP$3,OR(P12=TRUE,P12=1)),BA12+1,0) -> 0 | BC12: =IF(AND(13<=$AP$3,OR(Q12=TRUE,Q12=1)),BB12+1,0) -> 0 | BD12: =IF(AND(14<=$AP$3,OR(R12=TRUE,R12=1)),BC12+1,0) -> 0 | BE12: =IF(AND(15<=$AP$3,OR(S12=TRUE,S12=1)),BD12+1,0) -> 0 | BF12: =IF(AND(16<=$AP$3,OR(T12=TRUE,T12=1)),BE12+1,0) -> 0 | BG12: =IF(AND(17<=$AP$3,OR(U12=TRUE,U12=1)),BF12+1,0) -> 0 | BH12: =IF(AND(18<=$AP$3,OR(V12=TRUE,V12=1)),BG12+1,0) -> 0 | BI12: =IF(AND(19<=$AP$3,OR(W12=TRUE,W12=1)),BH12+1,0) -> 0 | BJ12: =IF(AND(20<=$AP$3,OR(X12=TRUE,X12=1)),BI12+1,0) -> 0 | BK12: =IF(AND(21<=$AP$3,OR(Y12=TRUE,Y12=1)),BJ12+1,0) -> 0 | BL12: =IF(AND(22<=$AP$3,OR(Z12=TRUE,Z12=1)),BK12+1,0) -> 0 | BM12: =IF(AND(23<=$AP$3,OR(AA12=TRUE,AA12=1)),BL12+1,0) -> 0 | BN12: =IF(AND(24<=$AP$3,OR(AB12=TRUE,AB12=1)),BM12+1,0) -> 0 | BO12: =IF(AND(25<=$AP$3,OR(AC12=TRUE,AC12=1)),BN12+1,0) -> 0 | BP12: =IF(AND(26<=$AP$3,OR(AD12=TRUE,AD12=1)),BO12+1,0) -> 0 | BQ12: =IF(AND(27<=$AP$3,OR(AE12=TRUE,AE12=1)),BP12+1,0) -> 0 | BR12: =IF(AND(28<=$AP$3,OR(AF12=TRUE,AF12=1)),BQ12+1,0) -> 0 | BS12: =IF(AND(29<=$AP$3,OR(AG12=TRUE,AG12=1)),BR12+1,0) -> 0 | BT12: =IF(AND(30<=$AP$3,OR(AH12=TRUE,AH12=1)),BS12+1,0) -> 0 | BU12: =IF(AND(31<=$AP$3,OR(AI12=TRUE,AI12=1)),BT12+1,0) -> 0
B13: =IF('Старт'!$C$13="","",'Старт'!$C$13) -> Спорт | C13: =IF('Старт'!$D$13="","",'Старт'!$D$13) -> Тренировка | D13: =IF('Старт'!$E$13="","",'Старт'!$E$13) -> 12 | E13: FALSE | F13: FALSE | G13: FALSE | H13: FALSE | I13: FALSE | J13: FALSE | K13: FALSE | L13: FALSE | M13: FALSE | N13: FALSE | O13: FALSE | P13: FALSE | Q13: FALSE | R13: FALSE | S13: FALSE | T13: FALSE | U13: FALSE | V13: FALSE | W13: FALSE | X13: FALSE | Y13: FALSE | Z13: FALSE | AA13: FALSE | AB13: FALSE | AC13: FALSE | AD13: FALSE | AE13: FALSE | AF13: FALSE | AG13: FALSE | AH13: FALSE | AI13: FALSE | AK13: =IF($C13="","",SUMPRODUCT((((E13:AI13=TRUE)+(E13:AI13=1))>0)*($E$11:$AI$11<>""))) -> 0 | AL13: =IF($C13="","",IF($AP$3=0,0,IFERROR(MIN(1,AK13/$AP$13),0))) -> 0 | AM13: =IF($C13="","",IF($AP$3=0,0,MAX(INDEX($AQ$13:$BU$13,$AP$3),INDEX($AQ$13:$BU$13,MAX($AP$3-1,1))))) -> 0 | AN13: =IF($C13="","",MAX($AQ$13:$BU$13)) -> 0 | AP13: =IF($C13="",0,IFERROR(IF($D13="",$AP$2,$D13)*$AP$3/$AP$2,$AP$3)) -> 12 | AQ13: =IF(AND(1<=$AP$3,OR(E13=TRUE,E13=1)),0+1,0) -> 0 | AR13: =IF(AND(2<=$AP$3,OR(F13=TRUE,F13=1)),AQ13+1,0) -> 0 | AS13: =IF(AND(3<=$AP$3,OR(G13=TRUE,G13=1)),AR13+1,0) -> 0 | AT13: =IF(AND(4<=$AP$3,OR(H13=TRUE,H13=1)),AS13+1,0) -> 0 | AU13: =IF(AND(5<=$AP$3,OR(I13=TRUE,I13=1)),AT13+1,0) -> 0 | AV13: =IF(AND(6<=$AP$3,OR(J13=TRUE,J13=1)),AU13+1,0) -> 0 | AW13: =IF(AND(7<=$AP$3,OR(K13=TRUE,K13=1)),AV13+1,0) -> 0 | AX13: =IF(AND(8<=$AP$3,OR(L13=TRUE,L13=1)),AW13+1,0) -> 0 | AY13: =IF(AND(9<=$AP$3,OR(M13=TRUE,M13=1)),AX13+1,0) -> 0 | AZ13: =IF(AND(10<=$AP$3,OR(N13=TRUE,N13=1)),AY13+1,0) -> 0 | BA13: =IF(AND(11<=$AP$3,OR(O13=TRUE,O13=1)),AZ13+1,0) -> 0 | BB13: =IF(AND(12<=$AP$3,OR(P13=TRUE,P13=1)),BA13+1,0) -> 0 | BC13: =IF(AND(13<=$AP$3,OR(Q13=TRUE,Q13=1)),BB13+1,0) -> 0 | BD13: =IF(AND(14<=$AP$3,OR(R13=TRUE,R13=1)),BC13+1,0) -> 0 | BE13: =IF(AND(15<=$AP$3,OR(S13=TRUE,S13=1)),BD13+1,0) -> 0 | BF13: =IF(AND(16<=$AP$3,OR(T13=TRUE,T13=1)),BE13+1,0) -> 0 | BG13: =IF(AND(17<=$AP$3,OR(U13=TRUE,U13=1)),BF13+1,0) -> 0 | BH13: =IF(AND(18<=$AP$3,OR(V13=TRUE,V13=1)),BG13+1,0) -> 0 | BI13: =IF(AND(19<=$AP$3,OR(W13=TRUE,W13=1)),BH13+1,0) -> 0 | BJ13: =IF(AND(20<=$AP$3,OR(X13=TRUE,X13=1)),BI13+1,0) -> 0 | BK13: =IF(AND(21<=$AP$3,OR(Y13=TRUE,Y13=1)),BJ13+1,0) -> 0 | BL13: =IF(AND(22<=$AP$3,OR(Z13=TRUE,Z13=1)),BK13+1,0) -> 0 | BM13: =IF(AND(23<=$AP$3,OR(AA13=TRUE,AA13=1)),BL13+1,0) -> 0 | BN13: =IF(AND(24<=$AP$3,OR(AB13=TRUE,AB13=1)),BM13+1,0) -> 0 | BO13: =IF(AND(25<=$AP$3,OR(AC13=TRUE,AC13=1)),BN13+1,0) -> 0 | BP13: =IF(AND(26<=$AP$3,OR(AD13=TRUE,AD13=1)),BO13+1,0) -> 0 | BQ13: =IF(AND(27<=$AP$3,OR(AE13=TRUE,AE13=1)),BP13+1,0) -> 0 | BR13: =IF(AND(28<=$AP$3,OR(AF13=TRUE,AF13=1)),BQ13+1,0) -> 0 | BS13: =IF(AND(29<=$AP$3,OR(AG13=TRUE,AG13=1)),BR13+1,0) -> 0 | BT13: =IF(AND(30<=$AP$3,OR(AH13=TRUE,AH13=1)),BS13+1,0) -> 0 | BU13: =IF(AND(31<=$AP$3,OR(AI13=TRUE,AI13=1)),BT13+1,0) -> 0
B14: =IF('Старт'!$C$14="","",'Старт'!$C$14) -> Здоровье | C14: =IF('Старт'!$D$14="","",'Старт'!$D$14) -> 10 000 шагов | D14: =IF('Старт'!$E$14="","",'Старт'!$E$14) | E14: FALSE | F14: FALSE | G14: FALSE | H14: FALSE | I14: FALSE | J14: FALSE | K14: FALSE | L14: FALSE | M14: FALSE | N14: FALSE | O14: FALSE | P14: FALSE | Q14: FALSE | R14: FALSE | S14: FALSE | T14: FALSE | U14: FALSE | V14: FALSE | W14: FALSE | X14: FALSE | Y14: FALSE | Z14: FALSE | AA14: FALSE | AB14: FALSE | AC14: FALSE | AD14: FALSE | AE14: FALSE | AF14: FALSE | AG14: FALSE | AH14: FALSE | AI14: FALSE | AK14: =IF($C14="","",SUMPRODUCT((((E14:AI14=TRUE)+(E14:AI14=1))>0)*($E$11:$AI$11<>""))) -> 0 | AL14: =IF($C14="","",IF($AP$3=0,0,IFERROR(MIN(1,AK14/$AP$14),0))) -> 0 | AM14: =IF($C14="","",IF($AP$3=0,0,MAX(INDEX($AQ$14:$BU$14,$AP$3),INDEX($AQ$14:$BU$14,MAX($AP$3-1,1))))) -> 0 | AN14: =IF($C14="","",MAX($AQ$14:$BU$14)) -> 0 | AP14: =IF($C14="",0,IFERROR(IF($D14="",$AP$2,$D14)*$AP$3/$AP$2,$AP$3)) -> 31 | AQ14: =IF(AND(1<=$AP$3,OR(E14=TRUE,E14=1)),0+1,0) -> 0 | AR14: =IF(AND(2<=$AP$3,OR(F14=TRUE,F14=1)),AQ14+1,0) -> 0 | AS14: =IF(AND(3<=$AP$3,OR(G14=TRUE,G14=1)),AR14+1,0) -> 0 | AT14: =IF(AND(4<=$AP$3,OR(H14=TRUE,H14=1)),AS14+1,0) -> 0 | AU14: =IF(AND(5<=$AP$3,OR(I14=TRUE,I14=1)),AT14+1,0) -> 0 | AV14: =IF(AND(6<=$AP$3,OR(J14=TRUE,J14=1)),AU14+1,0) -> 0 | AW14: =IF(AND(7<=$AP$3,OR(K14=TRUE,K14=1)),AV14+1,0) -> 0 | AX14: =IF(AND(8<=$AP$3,OR(L14=TRUE,L14=1)),AW14+1,0) -> 0 | AY14: =IF(AND(9<=$AP$3,OR(M14=TRUE,M14=1)),AX14+1,0) -> 0 | AZ14: =IF(AND(10<=$AP$3,OR(N14=TRUE,N14=1)),AY14+1,0) -> 0 | BA14: =IF(AND(11<=$AP$3,OR(O14=TRUE,O14=1)),AZ14+1,0) -> 0 | BB14: =IF(AND(12<=$AP$3,OR(P14=TRUE,P14=1)),BA14+1,0) -> 0 | BC14: =IF(AND(13<=$AP$3,OR(Q14=TRUE,Q14=1)),BB14+1,0) -> 0 | BD14: =IF(AND(14<=$AP$3,OR(R14=TRUE,R14=1)),BC14+1,0) -> 0 | BE14: =IF(AND(15<=$AP$3,OR(S14=TRUE,S14=1)),BD14+1,0) -> 0 | BF14: =IF(AND(16<=$AP$3,OR(T14=TRUE,T14=1)),BE14+1,0) -> 0 | BG14: =IF(AND(17<=$AP$3,OR(U14=TRUE,U14=1)),BF14+1,0) -> 0 | BH14: =IF(AND(18<=$AP$3,OR(V14=TRUE,V14=1)),BG14+1,0) -> 0 | BI14: =IF(AND(19<=$AP$3,OR(W14=TRUE,W14=1)),BH14+1,0) -> 0 | BJ14: =IF(AND(20<=$AP$3,OR(X14=TRUE,X14=1)),BI14+1,0) -> 0 | BK14: =IF(AND(21<=$AP$3,OR(Y14=TRUE,Y14=1)),BJ14+1,0) -> 0 | BL14: =IF(AND(22<=$AP$3,OR(Z14=TRUE,Z14=1)),BK14+1,0) -> 0 | BM14: =IF(AND(23<=$AP$3,OR(AA14=TRUE,AA14=1)),BL14+1,0) -> 0 | BN14: =IF(AND(24<=$AP$3,OR(AB14=TRUE,AB14=1)),BM14+1,0) -> 0 | BO14: =IF(AND(25<=$AP$3,OR(AC14=TRUE,AC14=1)),BN14+1,0) -> 0 | BP14: =IF(AND(26<=$AP$3,OR(AD14=TRUE,AD14=1)),BO14+1,0) -> 0 | BQ14: =IF(AND(27<=$AP$3,OR(AE14=TRUE,AE14=1)),BP14+1,0) -> 0 | BR14: =IF(AND(28<=$AP$3,OR(AF14=TRUE,AF14=1)),BQ14+1,0) -> 0 | BS14: =IF(AND(29<=$AP$3,OR(AG14=TRUE,AG14=1)),BR14+1,0) -> 0 | BT14: =IF(AND(30<=$AP$3,OR(AH14=TRUE,AH14=1)),BS14+1,0) -> 0 | BU14: =IF(AND(31<=$AP$3,OR(AI14=TRUE,AI14=1)),BT14+1,0) -> 0
B15: =IF('Старт'!$C$15="","",'Старт'!$C$15) -> Учёба | C15: =IF('Старт'!$D$15="","",'Старт'!$D$15) -> Чтение 20 минут | D15: =IF('Старт'!$E$15="","",'Старт'!$E$15) | E15: FALSE | F15: FALSE | G15: FALSE | H15: FALSE | I15: FALSE | J15: FALSE | K15: FALSE | L15: FALSE | M15: FALSE | N15: FALSE | O15: FALSE | P15: FALSE | Q15: FALSE | R15: FALSE | S15: FALSE | T15: FALSE | U15: FALSE | V15: FALSE | W15: FALSE | X15: FALSE | Y15: FALSE | Z15: FALSE | AA15: FALSE | AB15: FALSE | AC15: FALSE | AD15: FALSE | AE15: FALSE | AF15: FALSE | AG15: FALSE | AH15: FALSE | AI15: FALSE | AK15: =IF($C15="","",SUMPRODUCT((((E15:AI15=TRUE)+(E15:AI15=1))>0)*($E$11:$AI$11<>""))) -> 0 | AL15: =IF($C15="","",IF($AP$3=0,0,IFERROR(MIN(1,AK15/$AP$15),0))) -> 0 | AM15: =IF($C15="","",IF($AP$3=0,0,MAX(INDEX($AQ$15:$BU$15,$AP$3),INDEX($AQ$15:$BU$15,MAX($AP$3-1,1))))) -> 0 | AN15: =IF($C15="","",MAX($AQ$15:$BU$15)) -> 0 | AP15: =IF($C15="",0,IFERROR(IF($D15="",$AP$2,$D15)*$AP$3/$AP$2,$AP$3)) -> 31 | AQ15: =IF(AND(1<=$AP$3,OR(E15=TRUE,E15=1)),0+1,0) -> 0 | AR15: =IF(AND(2<=$AP$3,OR(F15=TRUE,F15=1)),AQ15+1,0) -> 0 | AS15: =IF(AND(3<=$AP$3,OR(G15=TRUE,G15=1)),AR15+1,0) -> 0 | AT15: =IF(AND(4<=$AP$3,OR(H15=TRUE,H15=1)),AS15+1,0) -> 0 | AU15: =IF(AND(5<=$AP$3,OR(I15=TRUE,I15=1)),AT15+1,0) -> 0 | AV15: =IF(AND(6<=$AP$3,OR(J15=TRUE,J15=1)),AU15+1,0) -> 0 | AW15: =IF(AND(7<=$AP$3,OR(K15=TRUE,K15=1)),AV15+1,0) -> 0 | AX15: =IF(AND(8<=$AP$3,OR(L15=TRUE,L15=1)),AW15+1,0) -> 0 | AY15: =IF(AND(9<=$AP$3,OR(M15=TRUE,M15=1)),AX15+1,0) -> 0 | AZ15: =IF(AND(10<=$AP$3,OR(N15=TRUE,N15=1)),AY15+1,0) -> 0 | BA15: =IF(AND(11<=$AP$3,OR(O15=TRUE,O15=1)),AZ15+1,0) -> 0 | BB15: =IF(AND(12<=$AP$3,OR(P15=TRUE,P15=1)),BA15+1,0) -> 0 | BC15: =IF(AND(13<=$AP$3,OR(Q15=TRUE,Q15=1)),BB15+1,0) -> 0 | BD15: =IF(AND(14<=$AP$3,OR(R15=TRUE,R15=1)),BC15+1,0) -> 0 | BE15: =IF(AND(15<=$AP$3,OR(S15=TRUE,S15=1)),BD15+1,0) -> 0 | BF15: =IF(AND(16<=$AP$3,OR(T15=TRUE,T15=1)),BE15+1,0) -> 0 | BG15: =IF(AND(17<=$AP$3,OR(U15=TRUE,U15=1)),BF15+1,0) -> 0 | BH15: =IF(AND(18<=$AP$3,OR(V15=TRUE,V15=1)),BG15+1,0) -> 0 | BI15: =IF(AND(19<=$AP$3,OR(W15=TRUE,W15=1)),BH15+1,0) -> 0 | BJ15: =IF(AND(20<=$AP$3,OR(X15=TRUE,X15=1)),BI15+1,0) -> 0 | BK15: =IF(AND(21<=$AP$3,OR(Y15=TRUE,Y15=1)),BJ15+1,0) -> 0 | BL15: =IF(AND(22<=$AP$3,OR(Z15=TRUE,Z15=1)),BK15+1,0) -> 0 | BM15: =IF(AND(23<=$AP$3,OR(AA15=TRUE,AA15=1)),BL15+1,0) -> 0 | BN15: =IF(AND(24<=$AP$3,OR(AB15=TRUE,AB15=1)),BM15+1,0) -> 0 | BO15: =IF(AND(25<=$AP$3,OR(AC15=TRUE,AC15=1)),BN15+1,0) -> 0 | BP15: =IF(AND(26<=$AP$3,OR(AD15=TRUE,AD15=1)),BO15+1,0) -> 0 | BQ15: =IF(AND(27<=$AP$3,OR(AE15=TRUE,AE15=1)),BP15+1,0) -> 0 | BR15: =IF(AND(28<=$AP$3,OR(AF15=TRUE,AF15=1)),BQ15+1,0) -> 0 | BS15: =IF(AND(29<=$AP$3,OR(AG15=TRUE,AG15=1)),BR15+1,0) -> 0 | BT15: =IF(AND(30<=$AP$3,OR(AH15=TRUE,AH15=1)),BS15+1,0) -> 0 | BU15: =IF(AND(31<=$AP$3,OR(AI15=TRUE,AI15=1)),BT15+1,0) -> 0
B16: =IF('Старт'!$C$16="","",'Старт'!$C$16) -> Личное | C16: =IF('Старт'!$D$16="","",'Старт'!$D$16) -> Медитация 10 минут | D16: =IF('Старт'!$E$16="","",'Старт'!$E$16) | E16: FALSE | F16: FALSE | G16: FALSE | H16: FALSE | I16: FALSE | J16: FALSE | K16: FALSE | L16: FALSE | M16: FALSE | N16: FALSE | O16: FALSE | P16: FALSE | Q16: FALSE | R16: FALSE | S16: FALSE | T16: FALSE | U16: FALSE | V16: FALSE | W16: FALSE | X16: FALSE | Y16: FALSE | Z16: FALSE | AA16: FALSE | AB16: FALSE | AC16: FALSE | AD16: FALSE | AE16: FALSE | AF16: FALSE | AG16: FALSE | AH16: FALSE | AI16: FALSE | AK16: =IF($C16="","",SUMPRODUCT((((E16:AI16=TRUE)+(E16:AI16=1))>0)*($E$11:$AI$11<>""))) -> 0 | AL16: =IF($C16="","",IF($AP$3=0,0,IFERROR(MIN(1,AK16/$AP$16),0))) -> 0 | AM16: =IF($C16="","",IF($AP$3=0,0,MAX(INDEX($AQ$16:$BU$16,$AP$3),INDEX($AQ$16:$BU$16,MAX($AP$3-1,1))))) -> 0 | AN16: =IF($C16="","",MAX($AQ$16:$BU$16)) -> 0 | AP16: =IF($C16="",0,IFERROR(IF($D16="",$AP$2,$D16)*$AP$3/$AP$2,$AP$3)) -> 31 | AQ16: =IF(AND(1<=$AP$3,OR(E16=TRUE,E16=1)),0+1,0) -> 0 | AR16: =IF(AND(2<=$AP$3,OR(F16=TRUE,F16=1)),AQ16+1,0) -> 0 | AS16: =IF(AND(3<=$AP$3,OR(G16=TRUE,G16=1)),AR16+1,0) -> 0 | AT16: =IF(AND(4<=$AP$3,OR(H16=TRUE,H16=1)),AS16+1,0) -> 0 | AU16: =IF(AND(5<=$AP$3,OR(I16=TRUE,I16=1)),AT16+1,0) -> 0 | AV16: =IF(AND(6<=$AP$3,OR(J16=TRUE,J16=1)),AU16+1,0) -> 0 | AW16: =IF(AND(7<=$AP$3,OR(K16=TRUE,K16=1)),AV16+1,0) -> 0 | AX16: =IF(AND(8<=$AP$3,OR(L16=TRUE,L16=1)),AW16+1,0) -> 0 | AY16: =IF(AND(9<=$AP$3,OR(M16=TRUE,M16=1)),AX16+1,0) -> 0 | AZ16: =IF(AND(10<=$AP$3,OR(N16=TRUE,N16=1)),AY16+1,0) -> 0 | BA16: =IF(AND(11<=$AP$3,OR(O16=TRUE,O16=1)),AZ16+1,0) -> 0 | BB16: =IF(AND(12<=$AP$3,OR(P16=TRUE,P16=1)),BA16+1,0) -> 0 | BC16: =IF(AND(13<=$AP$3,OR(Q16=TRUE,Q16=1)),BB16+1,0) -> 0 | BD16: =IF(AND(14<=$AP$3,OR(R16=TRUE,R16=1)),BC16+1,0) -> 0 | BE16: =IF(AND(15<=$AP$3,OR(S16=TRUE,S16=1)),BD16+1,0) -> 0 | BF16: =IF(AND(16<=$AP$3,OR(T16=TRUE,T16=1)),BE16+1,0) -> 0 | BG16: =IF(AND(17<=$AP$3,OR(U16=TRUE,U16=1)),BF16+1,0) -> 0 | BH16: =IF(AND(18<=$AP$3,OR(V16=TRUE,V16=1)),BG16+1,0) -> 0 | BI16: =IF(AND(19<=$AP$3,OR(W16=TRUE,W16=1)),BH16+1,0) -> 0 | BJ16: =IF(AND(20<=$AP$3,OR(X16=TRUE,X16=1)),BI16+1,0) -> 0 | BK16: =IF(AND(21<=$AP$3,OR(Y16=TRUE,Y16=1)),BJ16+1,0) -> 0 | BL16: =IF(AND(22<=$AP$3,OR(Z16=TRUE,Z16=1)),BK16+1,0) -> 0 | BM16: =IF(AND(23<=$AP$3,OR(AA16=TRUE,AA16=1)),BL16+1,0) -> 0 | BN16: =IF(AND(24<=$AP$3,OR(AB16=TRUE,AB16=1)),BM16+1,0) -> 0 | BO16: =IF(AND(25<=$AP$3,OR(AC16=TRUE,AC16=1)),BN16+1,0) -> 0 | BP16: =IF(AND(26<=$AP$3,OR(AD16=TRUE,AD16=1)),BO16+1,0) -> 0 | BQ16: =IF(AND(27<=$AP$3,OR(AE16=TRUE,AE16=1)),BP16+1,0) -> 0 | BR16: =IF(AND(28<=$AP$3,OR(AF16=TRUE,AF16=1)),BQ16+1,0) -> 0 | BS16: =IF(AND(29<=$AP$3,OR(AG16=TRUE,AG16=1)),BR16+1,0) -> 0 | BT16: =IF(AND(30<=$AP$3,OR(AH16=TRUE,AH16=1)),BS16+1,0) -> 0 | BU16: =IF(AND(31<=$AP$3,OR(AI16=TRUE,AI16=1)),BT16+1,0) -> 0
B17: =IF('Старт'!$C$17="","",'Старт'!$C$17) -> Здоровье | C17: =IF('Старт'!$D$17="","",'Старт'!$D$17) -> Без сахара | D17: =IF('Старт'!$E$17="","",'Старт'!$E$17) | E17: FALSE | F17: FALSE | G17: FALSE | H17: FALSE | I17: FALSE | J17: FALSE | K17: FALSE | L17: FALSE | M17: FALSE | N17: FALSE | O17: FALSE | P17: FALSE | Q17: FALSE | R17: FALSE | S17: FALSE | T17: FALSE | U17: FALSE | V17: FALSE | W17: FALSE | X17: FALSE | Y17: FALSE | Z17: FALSE | AA17: FALSE | AB17: FALSE | AC17: FALSE | AD17: FALSE | AE17: FALSE | AF17: FALSE | AG17: FALSE | AH17: FALSE | AI17: FALSE | AK17: =IF($C17="","",SUMPRODUCT((((E17:AI17=TRUE)+(E17:AI17=1))>0)*($E$11:$AI$11<>""))) -> 0 | AL17: =IF($C17="","",IF($AP$3=0,0,IFERROR(MIN(1,AK17/$AP$17),0))) -> 0 | AM17: =IF($C17="","",IF($AP$3=0,0,MAX(INDEX($AQ$17:$BU$17,$AP$3),INDEX($AQ$17:$BU$17,MAX($AP$3-1,1))))) -> 0 | AN17: =IF($C17="","",MAX($AQ$17:$BU$17)) -> 0 | AP17: =IF($C17="",0,IFERROR(IF($D17="",$AP$2,$D17)*$AP$3/$AP$2,$AP$3)) -> 31 | AQ17: =IF(AND(1<=$AP$3,OR(E17=TRUE,E17=1)),0+1,0) -> 0 | AR17: =IF(AND(2<=$AP$3,OR(F17=TRUE,F17=1)),AQ17+1,0) -> 0 | AS17: =IF(AND(3<=$AP$3,OR(G17=TRUE,G17=1)),AR17+1,0) -> 0 | AT17: =IF(AND(4<=$AP$3,OR(H17=TRUE,H17=1)),AS17+1,0) -> 0 | AU17: =IF(AND(5<=$AP$3,OR(I17=TRUE,I17=1)),AT17+1,0) -> 0 | AV17: =IF(AND(6<=$AP$3,OR(J17=TRUE,J17=1)),AU17+1,0) -> 0 | AW17: =IF(AND(7<=$AP$3,OR(K17=TRUE,K17=1)),AV17+1,0) -> 0 | AX17: =IF(AND(8<=$AP$3,OR(L17=TRUE,L17=1)),AW17+1,0) -> 0 | AY17: =IF(AND(9<=$AP$3,OR(M17=TRUE,M17=1)),AX17+1,0) -> 0 | AZ17: =IF(AND(10<=$AP$3,OR(N17=TRUE,N17=1)),AY17+1,0) -> 0 | BA17: =IF(AND(11<=$AP$3,OR(O17=TRUE,O17=1)),AZ17+1,0) -> 0 | BB17: =IF(AND(12<=$AP$3,OR(P17=TRUE,P17=1)),BA17+1,0) -> 0 | BC17: =IF(AND(13<=$AP$3,OR(Q17=TRUE,Q17=1)),BB17+1,0) -> 0 | BD17: =IF(AND(14<=$AP$3,OR(R17=TRUE,R17=1)),BC17+1,0) -> 0 | BE17: =IF(AND(15<=$AP$3,OR(S17=TRUE,S17=1)),BD17+1,0) -> 0 | BF17: =IF(AND(16<=$AP$3,OR(T17=TRUE,T17=1)),BE17+1,0) -> 0 | BG17: =IF(AND(17<=$AP$3,OR(U17=TRUE,U17=1)),BF17+1,0) -> 0 | BH17: =IF(AND(18<=$AP$3,OR(V17=TRUE,V17=1)),BG17+1,0) -> 0 | BI17: =IF(AND(19<=$AP$3,OR(W17=TRUE,W17=1)),BH17+1,0) -> 0 | BJ17: =IF(AND(20<=$AP$3,OR(X17=TRUE,X17=1)),BI17+1,0) -> 0 | BK17: =IF(AND(21<=$AP$3,OR(Y17=TRUE,Y17=1)),BJ17+1,0) -> 0 | BL17: =IF(AND(22<=$AP$3,OR(Z17=TRUE,Z17=1)),BK17+1,0) -> 0 | BM17: =IF(AND(23<=$AP$3,OR(AA17=TRUE,AA17=1)),BL17+1,0) -> 0 | BN17: =IF(AND(24<=$AP$3,OR(AB17=TRUE,AB17=1)),BM17+1,0) -> 0 | BO17: =IF(AND(25<=$AP$3,OR(AC17=TRUE,AC17=1)),BN17+1,0) -> 0 | BP17: =IF(AND(26<=$AP$3,OR(AD17=TRUE,AD17=1)),BO17+1,0) -> 0 | BQ17: =IF(AND(27<=$AP$3,OR(AE17=TRUE,AE17=1)),BP17+1,0) -> 0 | BR17: =IF(AND(28<=$AP$3,OR(AF17=TRUE,AF17=1)),BQ17+1,0) -> 0 | BS17: =IF(AND(29<=$AP$3,OR(AG17=TRUE,AG17=1)),BR17+1,0) -> 0 | BT17: =IF(AND(30<=$AP$3,OR(AH17=TRUE,AH17=1)),BS17+1,0) -> 0 | BU17: =IF(AND(31<=$AP$3,OR(AI17=TRUE,AI17=1)),BT17+1,0) -> 0
B18: =IF('Старт'!$C$18="","",'Старт'!$C$18) -> Работа | C18: =IF('Старт'!$D$18="","",'Старт'!$D$18) -> План на завтра | D18: =IF('Старт'!$E$18="","",'Старт'!$E$18) | E18: FALSE | F18: FALSE | G18: FALSE | H18: FALSE | I18: FALSE | J18: FALSE | K18: FALSE | L18: FALSE | M18: FALSE | N18: FALSE | O18: FALSE | P18: FALSE | Q18: FALSE | R18: FALSE | S18: FALSE | T18: FALSE | U18: FALSE | V18: FALSE | W18: FALSE | X18: FALSE | Y18: FALSE | Z18: FALSE | AA18: FALSE | AB18: FALSE | AC18: FALSE | AD18: FALSE | AE18: FALSE | AF18: FALSE | AG18: FALSE | AH18: FALSE | AI18: FALSE | AK18: =IF($C18="","",SUMPRODUCT((((E18:AI18=TRUE)+(E18:AI18=1))>0)*($E$11:$AI$11<>""))) -> 0 | AL18: =IF($C18="","",IF($AP$3=0,0,IFERROR(MIN(1,AK18/$AP$18),0))) -> 0 | AM18: =IF($C18="","",IF($AP$3=0,0,MAX(INDEX($AQ$18:$BU$18,$AP$3),INDEX($AQ$18:$BU$18,MAX($AP$3-1,1))))) -> 0 | AN18: =IF($C18="","",MAX($AQ$18:$BU$18)) -> 0 | AP18: =IF($C18="",0,IFERROR(IF($D18="",$AP$2,$D18)*$AP$3/$AP$2,$AP$3)) -> 31 | AQ18: =IF(AND(1<=$AP$3,OR(E18=TRUE,E18=1)),0+1,0) -> 0 | AR18: =IF(AND(2<=$AP$3,OR(F18=TRUE,F18=1)),AQ18+1,0) -> 0 | AS18: =IF(AND(3<=$AP$3,OR(G18=TRUE,G18=1)),AR18+1,0) -> 0 | AT18: =IF(AND(4<=$AP$3,OR(H18=TRUE,H18=1)),AS18+1,0) -> 0 | AU18: =IF(AND(5<=$AP$3,OR(I18=TRUE,I18=1)),AT18+1,0) -> 0 | AV18: =IF(AND(6<=$AP$3,OR(J18=TRUE,J18=1)),AU18+1,0) -> 0 | AW18: =IF(AND(7<=$AP$3,OR(K18=TRUE,K18=1)),AV18+1,0) -> 0 | AX18: =IF(AND(8<=$AP$3,OR(L18=TRUE,L18=1)),AW18+1,0) -> 0 | AY18: =IF(AND(9<=$AP$3,OR(M18=TRUE,M18=1)),AX18+1,0) -> 0 | AZ18: =IF(AND(10<=$AP$3,OR(N18=TRUE,N18=1)),AY18+1,0) -> 0 | BA18: =IF(AND(11<=$AP$3,OR(O18=TRUE,O18=1)),AZ18+1,0) -> 0 | BB18: =IF(AND(12<=$AP$3,OR(P18=TRUE,P18=1)),BA18+1,0) -> 0 | BC18: =IF(AND(13<=$AP$3,OR(Q18=TRUE,Q18=1)),BB18+1,0) -> 0 | BD18: =IF(AND(14<=$AP$3,OR(R18=TRUE,R18=1)),BC18+1,0) -> 0 | BE18: =IF(AND(15<=$AP$3,OR(S18=TRUE,S18=1)),BD18+1,0) -> 0 | BF18: =IF(AND(16<=$AP$3,OR(T18=TRUE,T18=1)),BE18+1,0) -> 0 | BG18: =IF(AND(17<=$AP$3,OR(U18=TRUE,U18=1)),BF18+1,0) -> 0 | BH18: =IF(AND(18<=$AP$3,OR(V18=TRUE,V18=1)),BG18+1,0) -> 0 | BI18: =IF(AND(19<=$AP$3,OR(W18=TRUE,W18=1)),BH18+1,0) -> 0 | BJ18: =IF(AND(20<=$AP$3,OR(X18=TRUE,X18=1)),BI18+1,0) -> 0 | BK18: =IF(AND(21<=$AP$3,OR(Y18=TRUE,Y18=1)),BJ18+1,0) -> 0 | BL18: =IF(AND(22<=$AP$3,OR(Z18=TRUE,Z18=1)),BK18+1,0) -> 0 | BM18: =IF(AND(23<=$AP$3,OR(AA18=TRUE,AA18=1)),BL18+1,0) -> 0 | BN18: =IF(AND(24<=$AP$3,OR(AB18=TRUE,AB18=1)),BM18+1,0) -> 0 | BO18: =IF(AND(25<=$AP$3,OR(AC18=TRUE,AC18=1)),BN18+1,0) -> 0 | BP18: =IF(AND(26<=$AP$3,OR(AD18=TRUE,AD18=1)),BO18+1,0) -> 0 | BQ18: =IF(AND(27<=$AP$3,OR(AE18=TRUE,AE18=1)),BP18+1,0) -> 0 | BR18: =IF(AND(28<=$AP$3,OR(AF18=TRUE,AF18=1)),BQ18+1,0) -> 0 | BS18: =IF(AND(29<=$AP$3,OR(AG18=TRUE,AG18=1)),BR18+1,0) -> 0 | BT18: =IF(AND(30<=$AP$3,OR(AH18=TRUE,AH18=1)),BS18+1,0) -> 0 | BU18: =IF(AND(31<=$AP$3,OR(AI18=TRUE,AI18=1)),BT18+1,0) -> 0
B19: =IF('Старт'!$C$19="","",'Старт'!$C$19) -> Учёба | C19: =IF('Старт'!$D$19="","",'Старт'!$D$19) -> Английский 15 минут | D19: =IF('Старт'!$E$19="","",'Старт'!$E$19) -> 20 | E19: FALSE | F19: FALSE | G19: FALSE | H19: FALSE | I19: FALSE | J19: FALSE | K19: FALSE | L19: FALSE | M19: FALSE | N19: FALSE | O19: FALSE | P19: FALSE | Q19: FALSE | R19: FALSE | S19: FALSE | T19: FALSE | U19: FALSE | V19: FALSE | W19: FALSE | X19: FALSE | Y19: FALSE | Z19: FALSE | AA19: FALSE | AB19: FALSE | AC19: FALSE | AD19: FALSE | AE19: FALSE | AF19: FALSE | AG19: FALSE | AH19: FALSE | AI19: FALSE | AK19: =IF($C19="","",SUMPRODUCT((((E19:AI19=TRUE)+(E19:AI19=1))>0)*($E$11:$AI$11<>""))) -> 0 | AL19: =IF($C19="","",IF($AP$3=0,0,IFERROR(MIN(1,AK19/$AP$19),0))) -> 0 | AM19: =IF($C19="","",IF($AP$3=0,0,MAX(INDEX($AQ$19:$BU$19,$AP$3),INDEX($AQ$19:$BU$19,MAX($AP$3-1,1))))) -> 0 | AN19: =IF($C19="","",MAX($AQ$19:$BU$19)) -> 0 | AP19: =IF($C19="",0,IFERROR(IF($D19="",$AP$2,$D19)*$AP$3/$AP$2,$AP$3)) -> 20 | AQ19: =IF(AND(1<=$AP$3,OR(E19=TRUE,E19=1)),0+1,0) -> 0 | AR19: =IF(AND(2<=$AP$3,OR(F19=TRUE,F19=1)),AQ19+1,0) -> 0 | AS19: =IF(AND(3<=$AP$3,OR(G19=TRUE,G19=1)),AR19+1,0) -> 0 | AT19: =IF(AND(4<=$AP$3,OR(H19=TRUE,H19=1)),AS19+1,0) -> 0 | AU19: =IF(AND(5<=$AP$3,OR(I19=TRUE,I19=1)),AT19+1,0) -> 0 | AV19: =IF(AND(6<=$AP$3,OR(J19=TRUE,J19=1)),AU19+1,0) -> 0 | AW19: =IF(AND(7<=$AP$3,OR(K19=TRUE,K19=1)),AV19+1,0) -> 0 | AX19: =IF(AND(8<=$AP$3,OR(L19=TRUE,L19=1)),AW19+1,0) -> 0 | AY19: =IF(AND(9<=$AP$3,OR(M19=TRUE,M19=1)),AX19+1,0) -> 0 | AZ19: =IF(AND(10<=$AP$3,OR(N19=TRUE,N19=1)),AY19+1,0) -> 0 | BA19: =IF(AND(11<=$AP$3,OR(O19=TRUE,O19=1)),AZ19+1,0) -> 0 | BB19: =IF(AND(12<=$AP$3,OR(P19=TRUE,P19=1)),BA19+1,0) -> 0 | BC19: =IF(AND(13<=$AP$3,OR(Q19=TRUE,Q19=1)),BB19+1,0) -> 0 | BD19: =IF(AND(14<=$AP$3,OR(R19=TRUE,R19=1)),BC19+1,0) -> 0 | BE19: =IF(AND(15<=$AP$3,OR(S19=TRUE,S19=1)),BD19+1,0) -> 0 | BF19: =IF(AND(16<=$AP$3,OR(T19=TRUE,T19=1)),BE19+1,0) -> 0 | BG19: =IF(AND(17<=$AP$3,OR(U19=TRUE,U19=1)),BF19+1,0) -> 0 | BH19: =IF(AND(18<=$AP$3,OR(V19=TRUE,V19=1)),BG19+1,0) -> 0 | BI19: =IF(AND(19<=$AP$3,OR(W19=TRUE,W19=1)),BH19+1,0) -> 0 | BJ19: =IF(AND(20<=$AP$3,OR(X19=TRUE,X19=1)),BI19+1,0) -> 0 | BK19: =IF(AND(21<=$AP$3,OR(Y19=TRUE,Y19=1)),BJ19+1,0) -> 0 | BL19: =IF(AND(22<=$AP$3,OR(Z19=TRUE,Z19=1)),BK19+1,0) -> 0 | BM19: =IF(AND(23<=$AP$3,OR(AA19=TRUE,AA19=1)),BL19+1,0) -> 0 | BN19: =IF(AND(24<=$AP$3,OR(AB19=TRUE,AB19=1)),BM19+1,0) -> 0 | BO19: =IF(AND(25<=$AP$3,OR(AC19=TRUE,AC19=1)),BN19+1,0) -> 0 | BP19: =IF(AND(26<=$AP$3,OR(AD19=TRUE,AD19=1)),BO19+1,0) -> 0 | BQ19: =IF(AND(27<=$AP$3,OR(AE19=TRUE,AE19=1)),BP19+1,0) -> 0 | BR19: =IF(AND(28<=$AP$3,OR(AF19=TRUE,AF19=1)),BQ19+1,0) -> 0 | BS19: =IF(AND(29<=$AP$3,OR(AG19=TRUE,AG19=1)),BR19+1,0) -> 0 | BT19: =IF(AND(30<=$AP$3,OR(AH19=TRUE,AH19=1)),BS19+1,0) -> 0 | BU19: =IF(AND(31<=$AP$3,OR(AI19=TRUE,AI19=1)),BT19+1,0) -> 0
