Workbook

Sheet Старт
A2: РЕЖИМ
A3: Не идеально, а регулярно
A5: 1. Замени серые примеры своими привычками. Хватит пяти.
A6: 2. Открой месяц — плиткой ниже или вкладкой внизу.
A7: 3. Вечером ставь галочки. Остальное считается само.
A10: МОИ ПРИВЫЧКИ
A11: Значок | B11: Привычка | E11: Имя | F11: Раз в неделю
A12: 🏋 | B12: Зал · 10 минут разминки | E12: Зал | F12: 3
A13: 💧 | B13: Стакан воды после сна | E13: Вода | F13: 7
A14: 📖 | B14: 20 страниц книги | E14: Книга | F14: 7
A15: 🧘 | B15: Тишина 10 минут | E15: Дзен | F15: 7
A16: 📝 | B16: План на завтра | E16: План | F16: 5
A19: ЧТОБЫ…
A20: =IF($B$12="","",$A$12) | B20: …быть сильным
A21: =IF($B$13="","",$A$13)
A22: =IF($B$14="","",$A$14) | B22: …быть тем, кто читает
A23: =IF($B$15="","",$A$15) | B23: …спокойствие и фокус
A24: =IF($B$16="","",$A$16)
A25: =IF($B$17="","",$A$17)
A26: =IF($B$18="","",$A$18)
A28: Галочки уже включены. Если вместо них пустые квадраты: выдели их → Вставка → Флажок.
A29: · Значок и имя — для шапки месяца, их видно на телефоне.
A30: · «Раз в неделю» 7 — привычка на каждый день, у неё считается серия.
A31: · Привычка помещается в 10 минут в плохой день. Иначе это цель месяца.
A32: · Поле «Чтобы…» необязательное: планер вернёт эту фразу в трудный день.
A34: МЕСЯЦЫ
A35: Янв | B35: Фев | C35: Мар | D35: Апр | E35: Май | F35: Июн
A36: Июл | B36: Авг | C36: Сен | D36: Окт | E36: Ноя | F36: Дек
A38: =IF(Расчёт!$B$3=0,"Впиши хотя бы одну привычку","Всё работает ✓ · v2.0 · "&Расчёт!$B$3&" привычек")
A39: Если цвета странные: ⋮ → Тёмная тема → выкл
A40: Считать сегодняшним днём (обычно пусто) | D40: =IF($C$9="","—",$C$9)

Sheet Янв
A1: ="ЯНВ 2026" | F1: =IF(Расчёт!$C$379=0,"Не идеально, а регулярно",ROUND(Расчёт!$F$379*100,0)&" % · "&Расчёт!$B$6&" "&Расчёт!$B$5)
A2: =IF(OR(Расчёт!$B$2=0,Расчёт!$B$4=0),"Не идеально, а регулярно",IF(INDEX(Расчёт!$AA:$AA,Расчёт!$B$2)>0,"Награда «Возвращение» · +15 опыта",IF(MAX(IF(AND('Старт'!$B$12<>"",IF('Старт'!$F$12="",7,'Старт'!$F$12)=7,INDEX(Расчёт!$I:$I,Расчёт!$B$2)=0,INDEX(Расчёт!$P:$P,Расчёт!$B$2)>1,N($J$39)>=3),1,0),IF(AND('Старт'!$B$13<>"",IF('Старт'!$F$13="",7,'Старт'!$F$13)=7,INDEX(Расчёт!$J:$J,Расчёт!$B$2)=0,INDEX(Расчёт!$Q:$Q,Расчёт!$B$2)>1,N($J$40)>=3),2,0),IF(AND('Старт'!$B$14<>"",IF('Старт'!$F$14="",7,'Старт'!$F$14)=7,INDEX(Расчёт!$K:$K,Расчёт!$B$2)=0,INDEX(Расчёт!$R:$R,Расчёт!$B$2)>1,N($J$41)>=3),3,0),IF(AND('Старт'!$B$15<>"",IF('Старт'!$F$15="",7,'Старт'!$F$15)=7,INDEX(Расчёт!$L:$L,Расчёт!$B$2)=0,INDEX(Расчёт!$S:$S,Расчёт!$B$2)>1,N($J$42)>=3),4,0),IF(AND('Старт'!$B$16<>"",IF('Старт'!$F$16="",7,'Старт'!$F$16)=7,INDEX(Расчёт!$M:$M,Расчёт!$B$2)=0,INDEX(Расчёт!$T:$T,Расчёт!$B$2)>1,N($J$43)>=3),5,0),IF(AND('Старт'!$B$17<>"",IF('Старт'!$F$17="",7,'Старт'!$F$17)=7,INDEX(Расчёт!$N:$N,Расчёт!$B$2)=0,INDEX(Расчёт!$U:$U,Расчёт!$B$2)>1,N($J$44)>=3),6,0),IF(AND('Старт'!$B$18<>"",IF('Старт'!$F$18="",7,'Старт'!$F$18)=7,INDEX(Расчёт!$O:$O,Расчёт!$B$2)=0,INDEX(Расчёт!$V:$V,Расчёт!$B$2)>1,N($J$45)>=3),7,0))>0,"Верни «"&INDEX('Старт'!$E$12:$E$18,MAX(1,MAX(IF(AND('Старт'!$B$12<>"",IF('Старт'!$F$12="",7,'Старт'!$F$12)=7,INDEX(Расчёт!$I:$I,Расчёт!$B$2)=0,INDEX(Расчёт!$P:$P,Расчёт!$B$2)>1,N($J$39)>=3),1,0),IF(AND('Старт'!$B$13<>"",IF('Старт'!$F$13="",7,'Старт'!$F$13)=7,INDEX(Расчёт!$J:$J,Расчёт!$B$2)=0,INDEX(Расчёт!$Q:$Q,Расчёт!$B$2)>1,N($J$40)>=3),2,0),IF(AND('Старт'!$B$14<>"",IF('Старт'!$F$14="",7,'Старт'!$F$14)=7,INDEX(Расчёт!$K:$K,Расчёт!$B$2)=0,INDEX(Расчёт!$R:$R,Расчёт!$B$2)>1,N($J$41)>=3),3,0),IF(AND('Старт'!$B$15<>"",IF('Старт'!$F$15="",7,'Старт'!$F$15)=7,INDEX(Расчёт!$L:$L,Расчёт!$B$2)=0,INDEX(Расчёт!$S:$S,Расчёт!$B$2)>1,N($J$42)>=3),4,0),IF(AND('Старт'!$B$16<>"",IF('Старт'!$F$16="",7,'Старт'!$F$16)=7,INDEX(Расчёт!$M:$M,Расчёт!$B$2)=0,INDEX(Расчёт!$T:$T,Расчёт!$B$2)>1,N($J$43)>=3),5,0),IF(AND('Старт'!$B$17<>"",IF('Старт'!$F$17="",7,'Старт'!$F$17)=7,INDEX(Расчёт!$N:$N,Расчёт!$B$2)=0,INDEX(Расчёт!$U:$U,Расчёт!$B$2)>1,N($J$44)>=3),6,0),IF(AND('Старт'!$B$18<>"",IF('Старт'!$F$18="",7,'Старт'!$F$18)=7,INDEX(Расчёт!$O:$O,Расчёт!$B$2)=0,INDEX(Расчёт!$V:$V,Расчёт!$B$2)>1,N($J$45)>=3),7,0))))&"» сегодня"&IF(INDEX('Старт'!$B$20:$B$26,MAX(1,MAX(IF(AND('Старт'!$B$12<>"",IF('Старт'!$F$12="",7,'Старт'!$F$12)=7,INDEX(Расчёт!$I:$I,Расчёт!$B$2)=0,INDEX(Расчёт!$P:$P,Расчёт!$B$2)>1,N($J$39)>=3),1,0),IF(AND('Старт'!$B$13<>"",IF('Старт'!$F$13="",7,'Старт'!$F$13)=7,INDEX(Расчёт!$J:$J,Расчёт!$B$2)=0,INDEX(Расчёт!$Q:$Q,Расчёт!$B$2)>1,N($J$40)>=3),2,0),IF(AND('Старт'!$B$14<>"",IF('Старт'!$F$14="",7,'Старт'!$F$14)=7,INDEX(Расчёт!$K:$K,Расчёт!$B$2)=0,INDEX(Расчёт!$R:$R,Расчёт!$B$2)>1,N($J$41)>=3),3,0),IF(AND('Старт'!$B$15<>"",IF('Старт'!$F$15="",7,'Старт'!$F$15)=7,INDEX(Расчёт!$L:$L,Расчёт!$B$2)=0,INDEX(Расчёт!$S:$S,Расчёт!$B$2)>1,N($J$42)>=3),4,0),IF(AND('Старт'!$B$16<>"",IF('Старт'!$F$16="",7,'Старт'!$F$16)=7,INDEX(Расчёт!$M:$M,Расчёт!$B$2)=0,INDEX(Расчёт!$T:$T,Расчёт!$B$2)>1,N($J$43)>=3),5,0),IF(AND('Старт'!$B$17<>"",IF('Старт'!$F$17="",7,'Старт'!$F$17)=7,INDEX(Расчёт!$N:$N,Расчёт!$B$2)=0,INDEX(Расчёт!$U:$U,Расчёт!$B$2)>1,N($J$44)>=3),6,0),IF(AND('Старт'!$B$18<>"",IF('Старт'!$F$18="",7,'Старт'!$F$18)=7,INDEX(Расчёт!$O:$O,Расчёт!$B$2)=0,INDEX(Расчёт!$V:$V,Расчёт!$B$2)>1,N($J$45)>=3),7,0))))="",""," — "&INDEX('Старт'!$B$20:$B$26,MAX(1,MAX(IF(AND('Старт'!$B$12<>"",IF('Старт'!$F$12="",7,'Старт'!$F$12)=7,INDEX(Расчёт!$I:$I,Расчёт!$B$2)=0,INDEX(Расчёт!$P:$P,Расчёт!$B$2)>1,N($J$39)>=3),1,0),IF(AND('Старт'!$B$13<>"",IF('Старт'!$F$13="",7,'Старт'!$F$13)=7,INDEX(Расчёт!$J:$J,Расчёт!$B$2)=0,INDEX(Расчёт!$Q:$Q,Расчёт!$B$2)>1,N($J$40)>=3),2,0),IF(AND('Старт'!$B$14<>"",IF('Старт'!$F$14="",7,'Старт'!$F$14)=7,INDEX(Расчёт!$K:$K,Расчёт!$B$2)=0,INDEX(Расчёт!$R:$R,Расчёт!$B$2)>1,N($J$41)>=3),3,0),IF(AND('Старт'!$B$15<>"",IF('Старт'!$F$15="",7,'Старт'!$F$15)=7,INDEX(Расчёт!$L:$L,Расчёт!$B$2)=0,INDEX(Расчёт!$S:$S,Расчёт!$B$2)>1,N($J$42)>=3),4,0),IF(AND('Старт'!$B$16<>"",IF('Старт'!$F$16="",7,'Старт'!$F$16)=7,INDEX(Расчёт!$M:$M,Расчёт!$B$2)=0,INDEX(Расчёт!$T:$T,Расчёт!$B$2)>1,N($J$43)>=3),5,0),IF(AND('Старт'!$B$17<>"",IF('Старт'!$F$17="",7,'Старт'!$F$17)=7,INDEX(Расчёт!$N:$N,Расчёт!$B$2)=0,INDEX(Расчёт!$U:$U,Расчёт!$B$2)>1,N($J$44)>=3),6,0),IF(AND('Старт'!$B$18<>"",IF('Старт'!$F$18="",7,'Старт'!$F$18)=7,INDEX(Расчёт!$O:$O,Расчёт!$B$2)=0,INDEX(Расчёт!$V:$V,Расчёт!$B$2)>1,N($J$45)>=3),7,0))))),IF(Расчёт!$F$397=1,"Испытание закрыто · +100 опыта","Уровень "&Расчёт!$B$5&" · "&Расчёт!$B$6))))
B3: =IF('Старт'!$B$12="","",'Старт'!$A$12) | C3: =IF('Старт'!$B$13="","",'Старт'!$A$13) | D3: =IF('Старт'!$B$14="","",'Старт'!$A$14) | E3: =IF('Старт'!$B$15="","",'Старт'!$A$15) | F3: =IF('Старт'!$B$16="","",'Старт'!$A$16) | G3: =IF('Старт'!$B$17="","",'Старт'!$A$17) | H3: =IF('Старт'!$B$18="","",'Старт'!$A$18)
B4: =IF('Старт'!$B$12="","",'Старт'!$E$12) | C4: =IF('Старт'!$B$13="","",'Старт'!$E$13) | D4: =IF('Старт'!$B$14="","",'Старт'!$E$14) | E4: =IF('Старт'!$B$15="","",'Старт'!$E$15) | F4: =IF('Старт'!$B$16="","",'Старт'!$E$16) | G4: =IF('Старт'!$B$17="","",'Старт'!$E$17) | H4: =IF('Старт'!$B$18="","",'Старт'!$E$18)
B5: =IF('Старт'!$B$12="","",IF(Расчёт!$B$2=0,"",IF(IF('Старт'!$F$12="",7,'Старт'!$F$12)<7,"ок",IF(INDEX(Расчёт!$I:$I,Расчёт!$B$2)=0,IF(AND(INDEX(Расчёт!$P:$P,Расчёт!$B$2)>1,$J$39>=3),"верни",""),IF(INDEX(Расчёт!$I:$I,Расчёт!$B$2)>=3,"🔥","")&INDEX(Расчёт!$I:$I,Расчёт!$B$2)&IF(INDEX(Расчёт!$P:$P,Расчёт!$B$2)<=1,"🛡",""))))) | C5: =IF('Старт'!$B$13="","",IF(Расчёт!$B$2=0,"",IF(IF('Старт'!$F$13="",7,'Старт'!$F$13)<7,"ок",IF(INDEX(Расчёт!$J:$J,Расчёт!$B$2)=0,IF(AND(INDEX(Расчёт!$Q:$Q,Расчёт!$B$2)>1,$J$40>=3),"верни",""),IF(INDEX(Расчёт!$J:$J,Расчёт!$B$2)>=3,"🔥","")&INDEX(Расчёт!$J:$J,Расчёт!$B$2)&IF(INDEX(Расчёт!$Q:$Q,Расчёт!$B$2)<=1,"🛡",""))))) | D5: =IF('Старт'!$B$14="","",IF(Расчёт!$B$2=0,"",IF(IF('Старт'!$F$14="",7,'Старт'!$F$14)<7,"ок",IF(INDEX(Расчёт!$K:$K,Расчёт!$B$2)=0,IF(AND(INDEX(Расчёт!$R:$R,Расчёт!$B$2)>1,$J$41>=3),"верни",""),IF(INDEX(Расчёт!$K:$K,Расчёт!$B$2)>=3,"🔥","")&INDEX(Расчёт!$K:$K,Расчёт!$B$2)&IF(INDEX(Расчёт!$R:$R,Расчёт!$B$2)<=1,"🛡",""))))) | E5: =IF('Старт'!$B$15="","",IF(Расчёт!$B$2=0,"",IF(IF('Старт'!$F$15="",7,'Старт'!$F$15)<7,"ок",IF(INDEX(Расчёт!$L:$L,Расчёт!$B$2)=0,IF(AND(INDEX(Расчёт!$S:$S,Расчёт!$B$2)>1,$J$42>=3),"верни",""),IF(INDEX(Расчёт!$L:$L,Расчёт!$B$2)>=3,"🔥","")&INDEX(Расчёт!$L:$L,Расчёт!$B$2)&IF(INDEX(Расчёт!$S:$S,Расчёт!$B$2)<=1,"🛡",""))))) | F5: =IF('Старт'!$B$16="","",IF(Расчёт!$B$2=0,"",IF(IF('Старт'!$F$16="",7,'Старт'!$F$16)<7,"ок",IF(INDEX(Расчёт!$M:$M,Расчёт!$B$2)=0,IF(AND(INDEX(Расчёт!$T:$T,Расчёт!$B$2)>1,$J$43>=3),"верни",""),IF(INDEX(Расчёт!$M:$M,Расчёт!$B$2)>=3,"🔥","")&INDEX(Расчёт!$M:$M,Расчёт!$B$2)&IF(INDEX(Расчёт!$T:$T,Расчёт!$B$2)<=1,"🛡",""))))) | G5: =IF('Старт'!$B$17="","",IF(Расчёт!$B$2=0,"",IF(IF('Старт'!$F$17="",7,'Старт'!$F$17)<7,"ок",IF(INDEX(Расчёт!$N:$N,Расчёт!$B$2)=0,IF(AND(INDEX(Расчёт!$U:$U,Расчёт!$B$2)>1,$J$44>=3),"верни",""),IF(INDEX(Расчёт!$N:$N,Расчёт!$B$2)>=3,"🔥","")&INDEX(Расчёт!$N:$N,Расчёт!$B$2)&IF(INDEX(Расчёт!$U:$U,Расчёт!$B$2)<=1,"🛡",""))))) | H5: =IF('Старт'!$B$18="","",IF(Расчёт!$B$2=0,"",IF(IF('Старт'!$F$18="",7,'Старт'!$F$18)<7,"ок",IF(INDEX(Расчёт!$O:$O,Расчёт!$B$2)=0,IF(AND(INDEX(Расчёт!$V:$V,Расчёт!$B$2)>1,$J$45>=3),"верни",""),IF(INDEX(Расчёт!$O:$O,Расчёт!$B$2)>=3,"🔥","")&INDEX(Расчёт!$O:$O,Расчёт!$B$2)&IF(INDEX(Расчёт!$V:$V,Расчёт!$B$2)<=1,"🛡",""))))) | I5: =Расчёт!$B$3 | J5: =IF(AND(YEAR(Расчёт!$B$1)=2026,MONTH(Расчёт!$B$1)=1),5+DAY(Расчёт!$B$1),0) | K5: =IF(WEEKDAY(Расчёт!$B$1,2)>=6,1,0) | L5: =Расчёт!$B$2
A6: =IF(Расчёт!$A$11=0,"Чт 1","Чт 1"&CHAR(10)&Расчёт!$W$11&"/"&$I$5) | B6: FALSE | C6: FALSE | D6: FALSE | E6: FALSE | F6: FALSE | G6: FALSE | H6: FALSE
A7: =IF(Расчёт!$A$12=0,"Пт 2","Пт 2"&CHAR(10)&Расчёт!$W$12&"/"&$I$5) | B7: FALSE | C7: FALSE | D7: FALSE | E7: FALSE | F7: FALSE | G7: FALSE | H7: FALSE
A8: =IF(Расчёт!$A$13=0,"Сб 3","Сб 3"&CHAR(10)&Расчёт!$W$13&"/"&$I$5) | B8: FALSE | C8: FALSE | D8: FALSE | E8: FALSE | F8: FALSE | G8: FALSE | H8: FALSE
A9: =IF(Расчёт!$A$14=0,"Вс 4","Вс 4"&CHAR(10)&Расчёт!$W$14&"/"&$I$5) | B9: FALSE | C9: FALSE | D9: FALSE | E9: FALSE | F9: FALSE | G9: FALSE | H9: FALSE
A10: =IF(Расчёт!$A$15=0,"Пн 5","Пн 5"&CHAR(10)&Расчёт!$W$15&"/"&$I$5) | B10: FALSE | C10: FALSE | D10: FALSE | E10: FALSE | F10: FALSE | G10: FALSE | H10: FALSE
A11: =IF(Расчёт!$A$16=0,"Вт 6","Вт 6"&CHAR(10)&Расчёт!$W$16&"/"&$I$5) | B11: FALSE | C11: FALSE | D11: FALSE | E11: FALSE | F11: FALSE | G11: FALSE | H11: FALSE
A12: =IF(Расчёт!$A$17=0,"Ср 7","Ср 7"&CHAR(10)&Расчёт!$W$17&"/"&$I$5) | B12: FALSE | C12: FALSE | D12: FALSE | E12: FALSE | F12: FALSE | G12: FALSE | H12: FALSE
A13: =IF(Расчёт!$A$18=0,"Чт 8","Чт 8"&CHAR(10)&Расчёт!$W$18&"/"&$I$5) | B13: FALSE | C13: FALSE | D13: FALSE | E13: FALSE | F13: FALSE | G13: FALSE | H13: FALSE
A14: =IF(Расчёт!$A$19=0,"Пт 9","Пт 9"&CHAR(10)&Расчёт!$W$19&"/"&$I$5) | B14: FALSE | C14: FALSE | D14: FALSE | E14: FALSE | F14: FALSE | G14: FALSE | H14: FALSE
A15: =IF(Расчёт!$A$20=0,"Сб 10","Сб 10"&CHAR(10)&Расчёт!$W$20&"/"&$I$5) | B15: FALSE | C15: FALSE | D15: FALSE | E15: FALSE | F15: FALSE | G15: FALSE | H15: FALSE
A16: =IF(Расчёт!$A$21=0,"Вс 11","Вс 11"&CHAR(10)&Расчёт!$W$21&"/"&$I$5) | B16: FALSE | C16: FALSE | D16: FALSE | E16: FALSE | F16: FALSE | G16: FALSE | H16: FALSE
A17: =IF(Расчёт!$A$22=0,"Пн 12","Пн 12"&CHAR(10)&Расчёт!$W$22&"/"&$I$5) | B17: FALSE | C17: FALSE | D17: FALSE | E17: FALSE | F17: FALSE | G17: FALSE | H17: FALSE
A18: =IF(Расчёт!$A$23=0,"Вт 13","Вт 13"&CHAR(10)&Расчёт!$W$23&"/"&$I$5) | B18: FALSE | C18: FALSE | D18: FALSE | E18: FALSE | F18: FALSE | G18: FALSE | H18: FALSE
A19: =IF(Расчёт!$A$24=0,"Ср 14","Ср 14"&CHAR(10)&Расчёт!$W$24&"/"&$I$5) | B19: FALSE | C19: FALSE | D19: FALSE | E19: FALSE | F19: FALSE | G19: FALSE | H19: FALSE
A20: =IF(Расчёт!$A$25=0,"Чт 15","Чт 15"&CHAR(10)&Расчёт!$W$25&"/"&$I$5) | B20: FALSE | C20: FALSE | D20: FALSE | E20: FALSE | F20: FALSE | G20: FALSE | H20: FALSE
A21: =IF(Расчёт!$A$26=0,"Пт 16","Пт 16"&CHAR(10)&Расчёт!$W$26&"/"&$I$5) | B21: FALSE | C21: FALSE | D21: FALSE | E21: FALSE | F21: FALSE | G21: FALSE | H21: FALSE
A22: =IF(Расчёт!$A$27=0,"Сб 17","Сб 17"&CHAR(10)&Расчёт!$W$27&"/"&$I$5) | B22: FALSE | C22: FALSE | D22: FALSE | E22: FALSE | F22: FALSE | G22: FALSE | H22: FALSE
A23: =IF(Расчёт!$A$28=0,"Вс 18","Вс 18"&CHAR(10)&Расчёт!$W$28&"/"&$I$5) | B23: FALSE | C23: FALSE | D23: FALSE | E23: FALSE | F23: FALSE | G23: FALSE | H23: FALSE
A24: =IF(Расчёт!$A$29=0,"Пн 19","Пн 19"&CHAR(10)&Расчёт!$W$29&"/"&$I$5) | B24: FALSE | C24: FALSE | D24: FALSE | E24: FALSE | F24: FALSE | G24: FALSE | H24: FALSE
A25: =IF(Расчёт!$A$30=0,"Вт 20","Вт 20"&CHAR(10)&Расчёт!$W$30&"/"&$I$5) | B25: FALSE | C25: FALSE | D25: FALSE | E25: FALSE | F25: FALSE | G25: FALSE | H25: FALSE
A26: =IF(Расчёт!$A$31=0,"Ср 21","Ср 21"&CHAR(10)&Расчёт!$W$31&"/"&$I$5) | B26: FALSE | C26: FALSE | D26: FALSE | E26: FALSE | F26: FALSE | G26: FALSE | H26: FALSE
A27: =IF(Расчёт!$A$32=0,"Чт 22","Чт 22"&CHAR(10)&Расчёт!$W$32&"/"&$I$5) | B27: FALSE | C27: FALSE | D27: FALSE | E27: FALSE | F27: FALSE | G27: FALSE | H27: FALSE
A28: =IF(Расчёт!$A$33=0,"Пт 23","Пт 23"&CHAR(10)&Расчёт!$W$33&"/"&$I$5) | B28: FALSE | C28: FALSE | D28: FALSE | E28: FALSE | F28: FALSE | G28: FALSE | H28: FALSE
A29: =IF(Расчёт!$A$34=0,"Сб 24","Сб 24"&CHAR(10)&Расчёт!$W$34&"/"&$I$5) | B29: FALSE | C29: FALSE | D29: FALSE | E29: FALSE | F29: FALSE | G29: FALSE | H29: FALSE
A30: =IF(Расчёт!$A$35=0,"Вс 25","Вс 25"&CHAR(10)&Расчёт!$W$35&"/"&$I$5) | B30: FALSE | C30: FALSE | D30: FALSE | E30: FALSE | F30: FALSE | G30: FALSE | H30: FALSE
A31: =IF(Расчёт!$A$36=0,"Пн 26","Пн 26"&CHAR(10)&Расчёт!$W$36&"/"&$I$5) | B31: FALSE | C31: FALSE | D31: FALSE | E31: FALSE | F31: FALSE | G31: FALSE | H31: FALSE
A32: =IF(Расчёт!$A$37=0,"Вт 27","Вт 27"&CHAR(10)&Расчёт!$W$37&"/"&$I$5) | B32: FALSE | C32: FALSE | D32: FALSE | E32: FALSE | F32: FALSE | G32: FALSE | H32: FALSE
A33: =IF(Расчёт!$A$38=0,"Ср 28","Ср 28"&CHAR(10)&Расчёт!$W$38&"/"&$I$5) | B33: FALSE | C33: FALSE | D33: FALSE | E33: FALSE | F33: FALSE | G33: FALSE | H33: FALSE
A34: =IF(Расчёт!$A$39=0,"Чт 29","Чт 29"&CHAR(10)&Расчёт!$W$39&"/"&$I$5) | B34: FALSE | C34: FALSE | D34: FALSE | E34: FALSE | F34: FALSE | G34: FALSE | H34: FALSE
A35: =IF(Расчёт!$A$40=0,"Пт 30","Пт 30"&CHAR(10)&Расчёт!$W$40&"/"&$I$5) | B35: FALSE | C35: FALSE | D35: FALSE | E35: FALSE | F35: FALSE | G35: FALSE | H35: FALSE
A36: =IF(Расчёт!$A$41=0,"Сб 31","Сб 31"&CHAR(10)&Расчёт!$W$41&"/"&$I$5) | B36: FALSE | C36: FALSE | D36: FALSE | E36: FALSE | F36: FALSE | G36: FALSE | H36: FALSE
A38: МОИ ПРИВЫЧКИ
A39: =IF('Старт'!$B$12="","",'Старт'!$A$12&" "&'Старт'!$B$12) | G39: =IF('Старт'!$B$12="","",SUM(Расчёт!$B$11:$B$41)&" из "&ROUND(IF('Старт'!$F$12="",7,'Старт'!$F$12)*31/7,0)) | I39: =IF('Старт'!$B$12="","",IF(Расчёт!$B$2=0,"",IF(IF('Старт'!$F$12="",7,'Старт'!$F$12)<7,"ок",IF(INDEX(Расчёт!$I:$I,Расчёт!$B$2)=0,IF(AND(INDEX(Расчёт!$P:$P,Расчёт!$B$2)>1,$J$39>=3),"верни",""),IF(INDEX(Расчёт!$I:$I,Расчёт!$B$2)>=3,"🔥","")&INDEX(Расчёт!$I:$I,Расчёт!$B$2)&IF(INDEX(Расчёт!$P:$P,Расчёт!$B$2)<=1,"🛡",""))))) | J39: =IF('Старт'!$B$12="","",MAX(Расчёт!$I$11:$I$41)) | K39: =IF(OR('Старт'!$B$12="",Расчёт!$C$379=0),"",MIN(1,SUM(Расчёт!$B$11:$B$41)/MAX(1,ROUND(IF('Старт'!$F$12="",7,'Старт'!$F$12)*31/7,0)*Расчёт!$C$379/31))) | L39: =IF($K$39="","",SPARKLINE($K$39,{"charttype","bar";"max",1;"color1","#22A35E";"color2","#262B38"}))
A40: =IF('Старт'!$B$13="","",'Старт'!$A$13&" "&'Старт'!$B$13) | G40: =IF('Старт'!$B$13="","",SUM(Расчёт!$C$11:$C$41)&" из "&ROUND(IF('Старт'!$F$13="",7,'Старт'!$F$13)*31/7,0)) | I40: =IF('Старт'!$B$13="","",IF(Расчёт!$B$2=0,"",IF(IF('Старт'!$F$13="",7,'Старт'!$F$13)<7,"ок",IF(INDEX(Расчёт!$J:$J,Расчёт!$B$2)=0,IF(AND(INDEX(Расчёт!$Q:$Q,Расчёт!$B$2)>1,$J$40>=3),"верни",""),IF(INDEX(Расчёт!$J:$J,Расчёт!$B$2)>=3,"🔥","")&INDEX(Расчёт!$J:$J,Расчёт!$B$2)&IF(INDEX(Расчёт!$Q:$Q,Расчёт!$B$2)<=1,"🛡",""))))) | J40: =IF('Старт'!$B$13="","",MAX(Расчёт!$J$11:$J$41)) | K40: =IF(OR('Старт'!$B$13="",Расчёт!$C$379=0),"",MIN(1,SUM(Расчёт!$C$11:$C$41)/MAX(1,ROUND(IF('Старт'!$F$13="",7,'Старт'!$F$13)*31/7,0)*Расчёт!$C$379/31))) | L40: =IF($K$40="","",SPARKLINE($K$40,{"charttype","bar";"max",1;"color1","#22A35E";"color2","#262B38"}))
A41: =IF('Старт'!$B$14="","",'Старт'!$A$14&" "&'Старт'!$B$14) | G41: =IF('Старт'!$B$14="","",SUM(Расчёт!$D$11:$D$41)&" из "&ROUND(IF('Старт'!$F$14="",7,'Старт'!$F$14)*31/7,0)) | I41: =IF('Старт'!$B$14="","",IF(Расчёт!$B$2=0,"",IF(IF('Старт'!$F$14="",7,'Старт'!$F$14)<7,"ок",IF(INDEX(Расчёт!$K:$K,Расчёт!$B$2)=0,IF(AND(INDEX(Расчёт!$R:$R,Расчёт!$B$2)>1,$J$41>=3),"верни",""),IF(INDEX(Расчёт!$K:$K,Расчёт!$B$2)>=3,"🔥","")&INDEX(Расчёт!$K:$K,Расчёт!$B$2)&IF(INDEX(Расчёт!$R:$R,Расчёт!$B$2)<=1,"🛡",""))))) | J41: =IF('Старт'!$B$14="","",MAX(Расчёт!$K$11:$K$41)) | K41: =IF(OR('Старт'!$B$14="",Расчёт!$C$379=0),"",MIN(1,SUM(Расчёт!$D$11:$D$41)/MAX(1,ROUND(IF('Старт'!$F$14="",7,'Старт'!$F$14)*31/7,0)*Расчёт!$C$379/31))) | L41: =IF($K$41="","",SPARKLINE($K$41,{"charttype","bar";"max",1;"color1","#22A35E";"color2","#262B38"}))
...

Sheet Фев
A1: ="ФЕВ 2026" | F1: =IF(Расчёт!$C$380=0,"Не идеально, а регулярно",ROUND(Расчёт!$F$380*100,0)&" % · "&Расчёт!$B$6&" "&Расчёт!$B$5)
A2: =IF(OR(Расчёт!$B$2=0,Расчёт!$B$4=0),"Не идеально, а регулярно",IF(INDEX(Расчёт!$AA:$AA,Расчёт!$B$2)>0,"Награда «Возвращение» · +15 опыта",IF(MAX(IF(AND('Старт'!$B$12<>"",IF('Старт'!$F$12="",7,'Старт'!$F$12)=7,INDEX(Расчёт!$I:$I,Расчёт!$B$2)=0,INDEX(Расчёт!$P:$P,Расчёт!$B$2)>1,N($J$39)>=3),1,0),IF(AND('Старт'!$B$13<>"",IF('Старт'!$F$13="",7,'Старт'!$F$13)=7,INDEX(Расчёт!$J:$J,Расчёт!$B$2)=0,INDEX(Расчёт!$Q:$Q,Расчёт!$B$2)>1,N($J$40)>=3),2,0),IF(AND('Старт'!$B$14<>"",IF('Старт'!$F$14="",7,'Старт'!$F$14)=7,INDEX(Расчёт!$K:$K,Расчёт!$B$2)=0,INDEX(Расчёт!$R:$R,Расчёт!$B$2)>1,N($J$41)>=3),3,0),IF(AND('Старт'!$B$15<>"",IF('Старт'!$F$15="",7,'Старт'!$F$15)=7,INDEX(Расчёт!$L:$L,Расчёт!$B$2)=0,INDEX(Расчёт!$S:$S,Расчёт!$B$2)>1,N($J$42)>=3),4,0),IF(AND('Старт'!$B$16<>"",IF('Старт'!$F$16="",7,'Старт'!$F$16)=7,INDEX(Расчёт!$M:$M,Расчёт!$B$2)=0,INDEX(Расчёт!$T:$T,Расчёт!$B$2)>1,N($J$43)>=3),5,0),IF(AND('Старт'!$B$17<>"",IF('Старт'!$F$17="",7,'Старт'!$F$17)=7,INDEX(Расчёт!$N:$N,Расчёт!$B$2)=0,INDEX(Расчёт!$U:$U,Расчёт!$B$2)>1,N($J$44)>=3),6,0),IF(AND('Старт'!$B$18<>"",IF('Старт'!$F$18="",7,'Старт'!$F$18)=7,INDEX(Расчёт!$O:$O,Расчёт!$B$2)=0,INDEX(Расчёт!$V:$V,Расчёт!$B$2)>1,N($J$45)>=3),7,0))>0,"Верни «"&INDEX('Старт'!$E$12:$E$18,MAX(1,MAX(IF(AND('Старт'!$B$12<>"",IF('Старт'!$F$12="",7,'Старт'!$F$12)=7,INDEX(Расчёт!$I:$I,Расчёт!$B$2)=0,INDEX(Расчёт!$P:$P,Расчёт!$B$2)>1,N($J$39)>=3),1,0),IF(AND('Старт'!$B$13<>"",IF('Старт'!$F$13="",7,'Старт'!$F$13)=7,INDEX(Расчёт!$J:$J,Расчёт!$B$2)=0,INDEX(Расчёт!$Q:$Q,Расчёт!$B$2)>1,N($J$40)>=3),2,0),IF(AND('Старт'!$B$14<>"",IF('Старт'!$F$14="",7,'Старт'!$F$14)=7,INDEX(Расчёт!$K:$K,Расчёт!$B$2)=0,INDEX(Расчёт!$R:$R,Расчёт!$B$2)>1,N($J$41)>=3),3,0),IF(AND('Старт'!$B$15<>"",IF('Старт'!$F$15="",7,'Старт'!$F$15)=7,INDEX(Расчёт!$L:$L,Расчёт!$B$2)=0,INDEX(Расчёт!$S:$S,Расчёт!$B$2)>1,N($J$42)>=3),4,0),IF(AND('Старт'!$B$16<>"",IF('Старт'!$F$16="",7,'Старт'!$F$16)=7,INDEX(Расчёт!$M:$M,Расчёт!$B$2)=0,INDEX(Расчёт!$T:$T,Расчёт!$B$2)>1,N($J$43)>=3),5,0),IF(AND('Старт'!$B$17<>"",IF('Старт'!$F$17="",7,'Старт'!$F$17)=7,INDEX(Расчёт!$N:$N,Расчёт!$B$2)=0,INDEX(Расчёт!$U:$U,Расчёт!$B$2)>1,N($J$44)>=3),6,0),IF(AND('Старт'!$B$18<>"",IF('Старт'!$F$18="",7,'Старт'!$F$18)=7,INDEX(Расчёт!$O:$O,Расчёт!$B$2)=0,INDEX(Расчёт!$V:$V,Расчёт!$B$2)>1,N($J$45)>=3),7,0))))&"» сегодня"&IF(INDEX('Старт'!$B$20:$B$26,MAX(1,MAX(IF(AND('Старт'!$B$12<>"",IF('Старт'!$F$12="",7,'Старт'!$F$12)=7,INDEX(Расчёт!$I:$I,Расчёт!$B$2)=0,INDEX(Расчёт!$P:$P,Расчёт!$B$2)>1,N($J$39)>=3),1,0),IF(AND('Старт'!$B$13<>"",IF('Старт'!$F$13="",7,'Старт'!$F$13)=7,INDEX(Расчёт!$J:$J,Расчёт!$B$2)=0,INDEX(Расчёт!$Q:$Q,Расчёт!$B$2)>1,N($J$40)>=3),2,0),IF(AND('Старт'!$B$14<>"",IF('Старт'!$F$14="",7,'Старт'!$F$14)=7,INDEX(Расчёт!$K:$K,Расчёт!$B$2)=0,INDEX(Расчёт!$R:$R,Расчёт!$B$2)>1,N($J$41)>=3),3,0),IF(AND('Старт'!$B$15<>"",IF('Старт'!$F$15="",7,'Старт'!$F$15)=7,INDEX(Расчёт!$L:$L,Расчёт!$B$2)=0,INDEX(Расчёт!$S:$S,Расчёт!$B$2)>1,N($J$42)>=3),4,0),IF(AND('Старт'!$B$16<>"",IF('Старт'!$F$16="",7,'Старт'!$F$16)=7,INDEX(Расчёт!$M:$M,Расчёт!$B$2)=0,INDEX(Расчёт!$T:$T,Расчёт!$B$2)>1,N($J$43)>=3),5,0),IF(AND('Старт'!$B$17<>"",IF('Старт'!$F$17="",7,'Старт'!$F$17)=7,INDEX(Расчёт!$N:$N,Расчёт!$B$2)=0,INDEX(Расчёт!$U:$U,Расчёт!$B$2)>1,N($J$44)>=3),6,0),IF(AND('Старт'!$B$18<>"",IF('Старт'!$F$18="",7,'Старт'!$F$18)=7,INDEX(Расчёт!$O:$O,Расчёт!$B$2)=0,INDEX(Расчёт!$V:$V,Расчёт!$B$2)>1,N($J$45)>=3),7,0))))="",""," — "&INDEX('Старт'!$B$20:$B$26,MAX(1,MAX(IF(AND('Старт'!$B$12<>"",IF('Старт'!$F$12="",7,'Старт'!$F$12)=7,INDEX(Расчёт!$I:$I,Расчёт!$B$2)=0,INDEX(Расчёт!$P:$P,Расчёт!$B$2)>1,N($J$39)>=3),1,0),IF(AND('Старт'!$B$13<>"",IF('Старт'!$F$13="",7,'Старт'!$F$13)=7,INDEX(Расчёт!$J:$J,Расчёт!$B$2)=0,INDEX(Расчёт!$Q:$Q,Расчёт!$B$2)>1,N($J$40)>=3),2,0),IF(AND('Старт'!$B$14<>"",IF('Старт'!$F$14="",7,'Старт'!$F$14)=7,INDEX(Расчёт!$K:$K,Расчёт!$B$2)=0,INDEX(Расчёт!$R:$R,Расчёт!$B$2)>1,N($J$41)>=3),3,0),IF(AND('Старт'!$B$15<>"",IF('Старт'!$F$15="",7,'Старт'!$F$15)=7,INDEX(Расчёт!$L:$L,Расчёт!$B$2)=0,INDEX(Расчёт!$S:$S,Расчёт!$B$2)>1,N($J$42)>=3),4,0),IF(AND('Старт'!$B$16<>"",IF('Старт'!$F$16="",7,'Старт'!$F$16)=7,INDEX(Расчёт!$M:$M,Расчёт!$B$2)=0,INDEX(Расчёт!$T:$T,Расчёт!$B$2)>1,N($J$43)>=3),5,0),IF(AND('Старт'!$B$17<>"",IF('Старт'!$F$17="",7,'Старт'!$F$17)=7,INDEX(Расчёт!$N:$N,Расчёт!$B$2)=0,INDEX(Расчёт!$U:$U,Расчёт!$B$2)>1,N($J$44)>=3),6,0),IF(AND('Старт'!$B$18<>"",IF('Старт'!$F$18="",7,'Старт'!$F$18)=7,INDEX(Расчёт!$O:$O,Расчёт!$B$2)=0,INDEX(Расчёт!$V:$V,Расчёт!$B$2)>1,N($J$45)>=3),7,0))))),IF(Расчёт!$F$401=1,"Испытание закрыто · +100 опыта","Уровень "&Расчёт!$B$5&" · "&Расчёт!$B$6))))
B3: =IF('Старт'!$B$12="","",'Старт'!$A$12) | C3: =IF('Старт'!$B$13="","",'Старт'!$A$13) | D3: =IF('Старт'!$B$14="","",'Старт'!$A$14) | E3: =IF('Старт'!$B$15="","",'Старт'!$A$15) | F3: =IF('Старт'!$B$16="","",'Старт'!$A$16) | G3: =IF('Старт'!$B$17="","",'Старт'!$A$17) | H3: =IF('Старт'!$B$18="","",'Старт'!$A$18)
B4: =IF('Старт'!$B$12="","",'Старт'!$E$12) | C4: =IF('Старт'!$B$13="","",'Старт'!$E$13) | D4: =IF('Старт'!$B$14="","",'Старт'!$E$14) | E4: =IF('Старт'!$B$15="","",'Старт'!$E$15) | F4: =IF('Старт'!$B$16="","",'Старт'!$E$16) | G4: =IF('Старт'!$B$17="","",'Старт'!$E$17) | H4: =IF('Старт'!$B$18="","",'Старт'!$E$18)
B5: =IF('Старт'!$B$12="","",IF(Расчёт!$B$2=0,"",IF(IF('Старт'!$F$12="",7,'Старт'!$F$12)<7,"ок",IF(INDEX(Расчёт!$I:$I,Расчёт!$B$2)=0,IF(AND(INDEX(Расчёт!$P:$P,Расчёт!$B$2)>1,$J$39>=3),"верни",""),IF(INDEX(Расчёт!$I:$I,Расчёт!$B$2)>=3,"🔥","")&INDEX(Расчёт!$I:$I,Расчёт!$B$2)&IF(INDEX(Расчёт!$P:$P,Расчёт!$B$2)<=1,"🛡",""))))) | C5: =IF('Старт'!$B$13="","",IF(Расчёт!$B$2=0,"",IF(IF('Старт'!$F$13="",7,'Старт'!$F$13)<7,"ок",IF(INDEX(Расчёт!$J:$J,Расчёт!$B$2)=0,IF(AND(INDEX(Расчёт!$Q:$Q,Расчёт!$B$2)>1,$J$40>=3),"верни",""),IF(INDEX(Расчёт!$J:$J,Расчёт!$B$2)>=3,"🔥","")&INDEX(Расчёт!$J:$J,Расчёт!$B$2)&IF(INDEX(Расчёт!$Q:$Q,Расчёт!$B$2)<=1,"🛡",""))))) | D5: =IF('Старт'!$B$14="","",IF(Расчёт!$B$2=0,"",IF(IF('Старт'!$F$14="",7,'Старт'!$F$14)<7,"ок",IF(INDEX(Расчёт!$K:$K,Расчёт!$B$2)=0,IF(AND(INDEX(Расчёт!$R:$R,Расчёт!$B$2)>1,$J$41>=3),"верни",""),IF(INDEX(Расчёт!$K:$K,Расчёт!$B$2)>=3,"🔥","")&INDEX(Расчёт!$K:$K,Расчёт!$B$2)&IF(INDEX(Расчёт!$R:$R,Расчёт!$B$2)<=1,"🛡",""))))) | E5: =IF('Старт'!$B$15="","",IF(Расчёт!$B$2=0,"",IF(IF('Старт'!$F$15="",7,'Старт'!$F$15)<7,"ок",IF(INDEX(Расчёт!$L:$L,Расчёт!$B$2)=0,IF(AND(INDEX(Расчёт!$S:$S,Расчёт!$B$2)>1,$J$42>=3),"верни",""),IF(INDEX(Расчёт!$L:$L,Расчёт!$B$2)>=3,"🔥","")&INDEX(Расчёт!$L:$L,Расчёт!$B$2)&IF(INDEX(Расчёт!$S:$S,Расчёт!$B$2)<=1,"🛡",""))))) | F5: =IF('Старт'!$B$16="","",IF(Расчёт!$B$2=0,"",IF(IF('Старт'!$F$16="",7,'Старт'!$F$16)<7,"ок",IF(INDEX(Расчёт!$M:$M,Расчёт!$B$2)=0,IF(AND(INDEX(Расчёт!$T:$T,Расчёт!$B$2)>1,$J$43>=3),"верни",""),IF(INDEX(Расчёт!$M:$M,Расчёт!$B$2)>=3,"🔥","")&INDEX(Расчёт!$M:$M,Расчёт!$B$2)&IF(INDEX(Расчёт!$T:$T,Расчёт!$B$2)<=1,"🛡",""))))) | G5: =IF('Старт'!$B$17="","",IF(Расчёт!$B$2=0,"",IF(IF('Старт'!$F$17="",7,'Старт'!$F$17)<7,"ок",IF(INDEX(Расчёт!$N:$N,Расчёт!$B$2)=0,IF(AND(INDEX(Расчёт!$U:$U,Расчёт!$B$2)>1,$J$44>=3),"верни",""),IF(INDEX(Расчёт!$N:$N,Расчёт!$B$2)>=3,"🔥","")&INDEX(Расчёт!$N:$N,Расчёт!$B$2)&IF(INDEX(Расчёт!$U:$U,Расчёт!$B$2)<=1,"🛡",""))))) | H5: =IF('Старт'!$B$18="","",IF(Расчёт!$B$2=0,"",IF(IF('Старт'!$F$18="",7,'Старт'!$F$18)<7,"ок",IF(INDEX(Расчёт!$O:$O,Расчёт!$B$2)=0,IF(AND(INDEX(Расчёт!$V:$V,Расчёт!$B$2)>1,$J$45>=3),"верни",""),IF(INDEX(Расчёт!$O:$O,Расчёт!$B$2)>=3,"🔥","")&INDEX(Расчёт!$O:$O,Расчёт!$B$2)&IF(INDEX(Расчёт!$V:$V,Расчёт!$B$2)<=1,"🛡",""))))) | I5: =Расчёт!$B$3 | J5: =IF(AND(YEAR(Расчёт!$B$1)=2026,MONTH(Расчёт!$B$1)=2),5+DAY(Расчёт!$B$1),0) | K5: =IF(WEEKDAY(Расчёт!$B$1,2)>=6,1,0) | L5: =Расчёт!$B$2
A6: =IF(Расчёт!$A$42=0,"Вс 1","Вс 1"&CHAR(10)&Расчёт!$W$42&"/"&$I$5) | B6: FALSE | C6: FALSE | D6: FALSE | E6: FALSE | F6: FALSE | G6: FALSE | H6: FALSE
A7: =IF(Расчёт!$A$43=0,"Пн 2","Пн 2"&CHAR(10)&Расчёт!$W$43&"/"&$I$5) | B7: FALSE | C7: FALSE | D7: FALSE | E7: FALSE | F7: FALSE | G7: FALSE | H7: FALSE
A8: =IF(Расчёт!$A$44=0,"Вт 3","Вт 3"&CHAR(10)&Расчёт!$W$44&"/"&$I$5) | B8: FALSE | C8: FALSE | D8: FALSE | E8: FALSE | F8: FALSE | G8: FALSE | H8: FALSE
A9: =IF(Расчёт!$A$45=0,"Ср 4","Ср 4"&CHAR(10)&Расчёт!$W$45&"/"&$I$5) | B9: FALSE | C9: FALSE | D9: FALSE | E9: FALSE | F9: FALSE | G9: FALSE | H9: FALSE
A10: =IF(Расчёт!$A$46=0,"Чт 5","Чт 5"&CHAR(10)&Расчёт!$W$46&"/"&$I$5) | B10: FALSE | C10: FALSE | D10: FALSE | E10: FALSE | F10: FALSE | G10: FALSE | H10: FALSE
A11: =IF(Расчёт!$A$47=0,"Пт 6","Пт 6"&CHAR(10)&Расчёт!$W$47&"/"&$I$5) | B11: FALSE | C11: FALSE | D11: FALSE | E11: FALSE | F11: FALSE | G11: FALSE | H11: FALSE
A12: =IF(Расчёт!$A$48=0,"Сб 7","Сб 7"&CHAR(10)&Расчёт!$W$48&"/"&$I$5) | B12: FALSE | C12: FALSE | D12: FALSE | E12: FALSE | F12: FALSE | G12: FALSE | H12: FALSE
A13: =IF(Расчёт!$A$49=0,"Вс 8","Вс 8"&CHAR(10)&Расчёт!$W$49&"/"&$I$5) | B13: FALSE | C13: FALSE | D13: FALSE | E13: FALSE | F13: FALSE | G13: FALSE | H13: FALSE
A14: =IF(Расчёт!$A$50=0,"Пн 9","Пн 9"&CHAR(10)&Расчёт!$W$50&"/"&$I$5) | B14: FALSE | C14: FALSE | D14: FALSE | E14: FALSE | F14: FALSE | G14: FALSE | H14: FALSE
A15: =IF(Расчёт!$A$51=0,"Вт 10","Вт 10"&CHAR(10)&Расчёт!$W$51&"/"&$I$5) | B15: FALSE | C15: FALSE | D15: FALSE | E15: FALSE | F15: FALSE | G15: FALSE | H15: FALSE
A16: =IF(Расчёт!$A$52=0,"Ср 11","Ср 11"&CHAR(10)&Расчёт!$W$52&"/"&$I$5) | B16: FALSE | C16: FALSE | D16: FALSE | E16: FALSE | F16: FALSE | G16: FALSE | H16: FALSE
A17: =IF(Расчёт!$A$53=0,"Чт 12","Чт 12"&CHAR(10)&Расчёт!$W$53&"/"&$I$5) | B17: FALSE | C17: FALSE | D17: FALSE | E17: FALSE | F17: FALSE | G17: FALSE | H17: FALSE
A18: =IF(Расчёт!$A$54=0,"Пт 13","Пт 13"&CHAR(10)&Расчёт!$W$54&"/"&$I$5) | B18: FALSE | C18: FALSE | D18: FALSE | E18: FALSE | F18: FALSE | G18: FALSE | H18: FALSE
A19: =IF(Расчёт!$A$55=0,"Сб 14","Сб 14"&CHAR(10)&Расчёт!$W$55&"/"&$I$5) | B19: FALSE | C19: FALSE | D19: FALSE | E19: FALSE | F19: FALSE | G19: FALSE | H19: FALSE
A20: =IF(Расчёт!$A$56=0,"Вс 15","Вс 15"&CHAR(10)&Расчёт!$W$56&"/"&$I$5) | B20: FALSE | C20: FALSE | D20: FALSE | E20: FALSE | F20: FALSE | G20: FALSE | H20: FALSE
A21: =IF(Расчёт!$A$57=0,"Пн 16","Пн 16"&CHAR(10)&Расчёт!$W$57&"/"&$I$5) | B21: FALSE | C21: FALSE | D21: FALSE | E21: FALSE | F21: FALSE | G21: FALSE | H21: FALSE
A22: =IF(Расчёт!$A$58=0,"Вт 17","Вт 17"&CHAR(10)&Расчёт!$W$58&"/"&$I$5) | B22: FALSE | C22: FALSE | D22: FALSE | E22: FALSE | F22: FALSE | G22: FALSE | H22: FALSE
A23: =IF(Расчёт!$A$59=0,"Ср 18","Ср 18"&CHAR(10)&Расчёт!$W$59&"/"&$I$5) | B23: FALSE | C23: FALSE | D23: FALSE | E23: FALSE | F23: FALSE | G23: FALSE | H23: FALSE
A24: =IF(Расчёт!$A$60=0,"Чт 19","Чт 19"&CHAR(10)&Расчёт!$W$60&"/"&$I$5) | B24: FALSE | C24: FALSE | D24: FALSE | E24: FALSE | F24: FALSE | G24: FALSE | H24: FALSE
A25: =IF(Расчёт!$A$61=0,"Пт 20","Пт 20"&CHAR(10)&Расчёт!$W$61&"/"&$I$5) | B25: FALSE | C25: FALSE | D25: FALSE | E25: FALSE | F25: FALSE | G25: FALSE | H25: FALSE
A26: =IF(Расчёт!$A$62=0,"Сб 21","Сб 21"&CHAR(10)&Расчёт!$W$62&"/"&$I$5) | B26: FALSE | C26: FALSE | D26: FALSE | E26: FALSE | F26: FALSE | G26: FALSE | H26: FALSE
A27: =IF(Расчёт!$A$63=0,"Вс 22","Вс 22"&CHAR(10)&Расчёт!$W$63&"/"&$I$5) | B27: FALSE | C27: FALSE | D27: FALSE | E27: FALSE | F27: FALSE | G27: FALSE | H27: FALSE
A28: =IF(Расчёт!$A$64=0,"Пн 23","Пн 23"&CHAR(10)&Расчёт!$W$64&"/"&$I$5) | B28: FALSE | C28: FALSE | D28: FALSE | E28: FALSE | F28: FALSE | G28: FALSE | H28: FALSE
A29: =IF(Расчёт!$A$65=0,"Вт 24","Вт 24"&CHAR(10)&Расчёт!$W$65&"/"&$I$5) | B29: FALSE | C29: FALSE | D29: FALSE | E29: FALSE | F29: FALSE | G29: FALSE | H29: FALSE
A30: =IF(Расчёт!$A$66=0,"Ср 25","Ср 25"&CHAR(10)&Расчёт!$W$66&"/"&$I$5) | B30: FALSE | C30: FALSE | D30: FALSE | E30: FALSE | F30: FALSE | G30: FALSE | H30: FALSE
A31: =IF(Расчёт!$A$67=0,"Чт 26","Чт 26"&CHAR(10)&Расчёт!$W$67&"/"&$I$5) | B31: FALSE | C31: FALSE | D31: FALSE | E31: FALSE | F31: FALSE | G31: FALSE | H31: FALSE
A32: =IF(Расчёт!$A$68=0,"Пт 27","Пт 27"&CHAR(10)&Расчёт!$W$68&"/"&$I$5) | B32: FALSE | C32: FALSE | D32: FALSE | E32: FALSE | F32: FALSE | G32: FALSE | H32: FALSE
A33: =IF(Расчёт!$A$69=0,"Сб 28","Сб 28"&CHAR(10)&Расчёт!$W$69&"/"&$I$5) | B33: FALSE | C33: FALSE | D33: FALSE | E33: FALSE | F33: FALSE | G33: FALSE | H33: FALSE
A38: МОИ ПРИВЫЧКИ
A39: =IF('Старт'!$B$12="","",'Старт'!$A$12&" "&'Старт'!$B$12) | G39: =IF('Старт'!$B$12="","",SUM(Расчёт!$B$42:$B$69)&" из "&ROUND(IF('Старт'!$F$12="",7,'Старт'!$F$12)*28/7,0)) | I39: =IF('Старт'!$B$12="","",IF(Расчёт!$B$2=0,"",IF(IF('Старт'!$F$12="",7,'Старт'!$F$12)<7,"ок",IF(INDEX(Расчёт!$I:$I,Расчёт!$B$2)=0,IF(AND(INDEX(Расчёт!$P:$P,Расчёт!$B$2)>1,$J$39>=3),"верни",""),IF(INDEX(Расчёт!$I:$I,Расчёт!$B$2)>=3,"🔥","")&INDEX(Расчёт!$I:$I,Расчёт!$B$2)&IF(INDEX(Расчёт!$P:$P,Расчёт!$B$2)<=1,"🛡",""))))) | J39: =IF('Старт'!$B$12="","",MAX(Расчёт!$I$42:$I$69)) | K39: =IF(OR('Старт'!$B$12="",Расчёт!$C$380=0),"",MIN(1,SUM(Расчёт!$B$42:$B$69)/MAX(1,ROUND(IF('Старт'!$F$12="",7,'Старт'!$F$12)*28/7,0)*Расчёт!$C$380/28))) | L39: =IF($K$39="","",SPARKLINE($K$39,{"charttype","bar";"max",1;"color1","#22A35E";"color2","#262B38"}))
A40: =IF('Старт'!$B$13="","",'Старт'!$A$13&" "&'Старт'!$B$13) | G40: =IF('Старт'!$B$13="","",SUM(Расчёт!$C$42:$C$69)&" из "&ROUND(IF('Старт'!$F$13="",7,'Старт'!$F$13)*28/7,0)) | I40: =IF('Старт'!$B$13="","",IF(Расчёт!$B$2=0,"",IF(IF('Старт'!$F$13="",7,'Старт'!$F$13)<7,"ок",IF(INDEX(Расчёт!$J:$J,Расчёт!$B$2)=0,IF(AND(INDEX(Расчёт!$Q:$Q,Расчёт!$B$2)>1,$J$40>=3),"верни",""),IF(INDEX(Расчёт!$J:$J,Расчёт!$B$2)>=3,"🔥","")&INDEX(Расчёт!$J:$J,Расчёт!$B$2)&IF(INDEX(Расчёт!$Q:$Q,Расчёт!$B$2)<=1,"🛡",""))))) | J40: =IF('Старт'!$B$13="","",MAX(Расчёт!$J$42:$J$69)) | K40: =IF(OR('Старт'!$B$13="",Расчёт!$C$380=0),"",MIN(1,SUM(Расчёт!$C$42:$C$69)/MAX(1,ROUND(IF('Старт'!$F$13="",7,'Старт'!$F$13)*28/7,0)*Расчёт!$C$380/28))) | L40: =IF($K$40="","",SPARKLINE($K$40,{"charttype","bar";"max",1;"color1","#22A35E";"color2","#262B38"}))
A41: =IF('Старт'!$B$14="","",'Старт'!$A$14&" "&'Старт'!$B$14) | G41: =IF('Старт'!$B$14="","",SUM(Расчёт!$D$42:$D$69)&" из "&ROUND(IF('Старт'!$F$14="",7,'Старт'!$F$14)*28/7,0)) | I41: =IF('Старт'!$B$14="","",IF(Расчёт!$B$2=0,"",IF(IF('Старт'!$F$14="",7,'Старт'!$F$14)<7,"ок",IF(INDEX(Расчёт!$K:$K,Расчёт!$B$2)=0,IF(AND(INDEX(Расчёт!$R:$R,Расчёт!$B$2)>1,$J$41>=3),"верни",""),IF(INDEX(Расчёт!$K:$K,Расчёт!$B$2)>=3,"🔥","")&INDEX(Расчёт!$K:$K,Расчёт!$B$2)&IF(INDEX(Расчёт!$R:$R,Расчёт!$B$2)<=1,"🛡",""))))) | J41: =IF('Старт'!$B$14="","",MAX(Расчёт!$K$42:$K$69)) | K41: =IF(OR('Старт'!$B$14="",Расчёт!$C$380=0),"",MIN(1,SUM(Расчёт!$D$42:$D$69)/MAX(1,ROUND(IF('Старт'!$F$14="",7,'Старт'!$F$14)*28/7,0)*Расчёт!$C$380/28))) | L41: =IF($K$41="","",SPARKLINE($K$41,{"charttype","bar";"max",1;"color1","#22A35E";"color2","#262B38"}))
A42: =IF('Старт'!$B$15="","",'Старт'!$A$15&" "&'Старт'!$B$15) | G42: =IF('Старт'!$B$15="","",SUM(Расчёт!$E$42:$E$69)&" из "&ROUND(IF('Старт'!$F$15="",7,'Старт'!$F$15)*28/7,0)) | I42: =IF('Старт'!$B$15="","",IF(Расчёт!$B$2=0,"",IF(IF('Старт'!$F$15="",7,'Старт'!$F$15)<7,"ок",IF(INDEX(Расчёт!$L:$L,Расчёт!$B$2)=0,IF(AND(INDEX(Расчёт!$S:$S,Расчёт!$B$2)>1,$J$42>=3),"верни",""),IF(INDEX(Расчёт!$L:$L,Расчёт!$B$2)>=3,"🔥","")&INDEX(Расчёт!$L:$L,Расчёт!$B$2)&IF(INDEX(Расчёт!$S:$S,Расчёт!$B$2)<=1,"🛡",""))))) | J42: =IF('Старт'!$B$15="","",MAX(Расчёт!$L$42:$L$69)) | K42: =IF(OR('Старт'!$B$15="",Расчёт!$C$380=0),"",MIN(1,SUM(Расчёт!$E$42:$E$69)/MAX(1,ROUND(IF('Старт'!$F$15="",7,'Старт'!$F$15)*28/7,0)*Расчёт!$C$380/28))) | L42: =IF($K$42="","",SPARKLINE($K$42,{"charttype","bar";"max",1;"color1","#22A35E";"color2","#262B38"}))
A43: =IF('Старт'!$B$16="","",'Старт'!$A$16&" "&'Старт'!$B$16) | G43: =IF('Старт'!$B$16="","",SUM(Расчёт!$F$42:$F$69)&" из "&ROUND(IF('Старт'!$F$16="",7,'Старт'!$F$16)*28/7,0)) | I43: =IF('Старт'!$B$16="","",IF(Расчёт!$B$2=0,"",IF(IF('Старт'!$F$16="",7,'Старт'!$F$16)<7,"ок",IF(INDEX(Расчёт!$M:$M,Расчёт!$B$2)=0,IF(AND(INDEX(Расчёт!$T:$T,Расчёт!$B$2)>1,$J$43>=3),"верни",""),IF(INDEX(Расчёт!$M:$M,Расчёт!$B$2)>=3,"🔥","")&INDEX(Расчёт!$M:$M,Расчёт!$B$2)&IF(INDEX(Расчёт!$T:$T,Расчёт!$B$2)<=1,"🛡",""))))) | J43: =IF('Старт'!$B$16="","",MAX(Расчёт!$M$42:$M$69)) | K43: =IF(OR('Старт'!$B$16="",Расчёт!$C$380=0),"",MIN(1,SUM(Расчёт!$F$42:$F$69)/MAX(1,ROUND(IF('Старт'!$F$16="",7,'Старт'!$F$16)*28/7,0)*Расчёт!$C$380/28))) | L43: =IF($K$43="","",SPARKLINE($K$43,{"charttype","bar";"max",1;"color1","#22A35E";"color2","#262B38"}))
A44: =IF('Старт'!$B$17="","",'Старт'!$A$17&" "&'Старт'!$B$17) | G44: =IF('Старт'!$B$17="","",SUM(Расчёт!$G$42:$G$69)&" из "&ROUND(IF('Старт'!$F$17="",7,'Старт'!$F$17)*28/7,0)) | I44: =IF('Старт'!$B$17="","",IF(Расчёт!$B$2=0,"",IF(IF('Старт'!$F$17="",7,'Старт'!$F$17)<7,"ок",IF(INDEX(Расчёт!$N:$N,Расчёт!$B$2)=0,IF(AND(INDEX(Расчёт!$U:$U,Расчёт!$B$2)>1,$J$44>=3),"верни",""),IF(INDEX(Расчёт!$N:$N,Расчёт!$B$2)>=3,"🔥","")&INDEX(Расчёт!$N:$N,Расчёт!$B$2)&IF(INDEX(Расчёт!$U:$U,Расчёт!$B$2)<=1,"🛡",""))))) | J44: =IF('Старт'!$B$17="","",MAX(Расчёт!$N$42:$N$69)) | K44: =IF(OR('Старт'!$B$17="",Расчёт!$C$380=0),"",MIN(1,SUM(Расчёт!$G$42:$G$69)/MAX(1,ROUND(IF('Старт'!$F$17="",7,'Старт'!$F$17)*28/7,0)*Расчёт!$C$380/28))) | L44: =IF($K$44="","",SPARKLINE($K$44,{"charttype","bar";"max",1;"color1","#22A35E";"color2","#262B38"}))
...

Sheet Мар
A1: ="МАР 2026" | F1: =IF(Расчёт!$C$381=0,"Не идеально, а регулярно",ROUND(Расчёт!$F$381*100,0)&" % · "&Расчёт!$B$6&" "&Расчёт!$B$5)
A2: =IF(OR(Расчёт!$B$2=0,Расчёт!$B$4=0),"Не идеально, а регулярно",IF(INDEX(Расчёт!$AA:$AA,Расчёт!$B$2)>0,"Награда «Возвращение» · +15 опыта",IF(MAX(IF(AND('Старт'!$B$12<>"",IF('Старт'!$F$12="",7,'Старт'!$F$12)=7,INDEX(Расчёт!$I:$I,Расчёт!$B$2)=0,INDEX(Расчёт!$P:$P,Расчёт!$B$2)>1,N($J$39)>=3),1,0),IF(AND('Старт'!$B$13<>"",IF('Старт'!$F$13="",7,'Старт'!$F$13)=7,INDEX(Расчёт!$J:$J,Расчёт!$B$2)=0,INDEX(Расчёт!$Q:$Q,Расчёт!$B$2)>1,N($J$40)>=3),2,0),IF(AND('Старт'!$B$14<>"",IF('Старт'!$F$14="",7,'Старт'!$F$14)=7,INDEX(Расчёт!$K:$K,Расчёт!$B$2)=0,INDEX(Расчёт!$R:$R,Расчёт!$B$2)>1,N($J$41)>=3),3,0),IF(AND('Старт'!$B$15<>"",IF('Старт'!$F$15="",7,'Старт'!$F$15)=7,INDEX(Расчёт!$L:$L,Расчёт!$B$2)=0,INDEX(Расчёт!$S:$S,Расчёт!$B$2)>1,N($J$42)>=3),4,0),IF(AND('Старт'!$B$16<>"",IF('Старт'!$F$16="",7,'Старт'!$F$16)=7,INDEX(Расчёт!$M:$M,Расчёт!$B$2)=0,INDEX(Расчёт!$T:$T,Расчёт!$B$2)>1,N($J$43)>=3),5,0),IF(AND('Старт'!$B$17<>"",IF('Старт'!$F$17="",7,'Старт'!$F$17)=7,INDEX(Расчёт!$N:$N,Расчёт!$B$2)=0,INDEX(Расчёт!$U:$U,Расчёт!$B$2)>1,N($J$44)>=3),6,0),IF(AND('Старт'!$B$18<>"",IF('Старт'!$F$18="",7,'Старт'!$F$18)=7,INDEX(Расчёт!$O:$O,Расчёт!$B$2)=0,INDEX(Расчёт!$V:$V,Расчёт!$B$2)>1,N($J$45)>=3),7,0))>0,"Верни «"&INDEX('Старт'!$E$12:$E$18,MAX(1,MAX(IF(AND('Старт'!$B$12<>"",IF('Старт'!$F$12="",7,'Старт'!$F$12)=7,INDEX(Расчёт!$I:$I,Расчёт!$B$2)=0,INDEX(Расчёт!$P:$P,Расчёт!$B$2)>1,N($J$39)>=3),1,0),IF(AND('Старт'!$B$13<>"",IF('Старт'!$F$13="",7,'Старт'!$F$13)=7,INDEX(Расчёт!$J:$J,Расчёт!$B$2)=0,INDEX(Расчёт!$Q:$Q,Расчёт!$B$2)>1,N($J$40)>=3),2,0),IF(AND('Старт'!$B$14<>"",IF('Старт'!$F$14="",7,'Старт'!$F$14)=7,INDEX(Расчёт!$K:$K,Расчёт!$B$2)=0,INDEX(Расчёт!$R:$R,Расчёт!$B$2)>1,N($J$41)>=3),3,0),IF(AND('Старт'!$B$15<>"",IF('Старт'!$F$15="",7,'Старт'!$F$15)=7,INDEX(Расчёт!$L:$L,Расчёт!$B$2)=0,INDEX(Расчёт!$S:$S,Расчёт!$B$2)>1,N($J$42)>=3),4,0),IF(AND('Старт'!$B$16<>"",IF('Старт'!$F$16="",7,'Старт'!$F$16)=7,INDEX(Расчёт!$M:$M,Расчёт!$B$2)=0,INDEX(Расчёт!$T:$T,Расчёт!$B$2)>1,N($J$43)>=3),5,0),IF(AND('Старт'!$B$17<>"",IF('Старт'!$F$17="",7,'Старт'!$F$17)=7,INDEX(Расчёт!$N:$N,Расчёт!$B$2)=0,INDEX(Расчёт!$U:$U,Расчёт!$B$2)>1,N($J$44)>=3),6,0),IF(AND('Старт'!$B$18<>"",IF('Старт'!$F$18="",7,'Старт'!$F$18)=7,INDEX(Расчёт!$O:$O,Расчёт!$B$2)=0,INDEX(Расчёт!$V:$V,Расчёт!$B$2)>1,N($J$45)>=3),7,0))))&"» сегодня"&IF(INDEX('Старт'!$B$20:$B$26,MAX(1,MAX(IF(AND('Старт'!$B$12<>"",IF('Старт'!$F$12="",7,'Старт'!$F$12)=7,INDEX(Расчёт!$I:$I,Расчёт!$B$2)=0,INDEX(Расчёт!$P:$P,Расчёт!$B$2)>1,N($J$39)>=3),1,0),IF(AND('Старт'!$B$13<>"",IF('Старт'!$F$13="",7,'Старт'!$F$13)=7,INDEX(Расчёт!$J:$J,Расчёт!$B$2)=0,INDEX(Расчёт!$Q:$Q,Расчёт!$B$2)>1,N($J$40)>=3),2,0),IF(AND('Старт'!$B$14<>"",IF('Старт'!$F$14="",7,'Старт'!$F$14)=7,INDEX(Расчёт!$K:$K,Расчёт!$B$2)=0,INDEX(Расчёт!$R:$R,Расчёт!$B$2)>1,N($J$41)>=3),3,0),IF(AND('Старт'!$B$15<>"",IF('Старт'!$F$15="",7,'Старт'!$F$15)=7,INDEX(Расчёт!$L:$L,Расчёт!$B$2)=0,INDEX(Расчёт!$S:$S,Расчёт!$B$2)>1,N($J$42)>=3),4,0),IF(AND('Старт'!$B$16<>"",IF('Старт'!$F$16="",7,'Старт'!$F$16)=7,INDEX(Расчёт!$M:$M,Расчёт!$B$2)=0,INDEX(Расчёт!$T:$T,Расчёт!$B$2)>1,N($J$43)>=3),5,0),IF(AND('Старт'!$B$17<>"",IF('Старт'!$F$17="",7,'Старт'!$F$17)=7,INDEX(Расчёт!$N:$N,Расчёт!$B$2)=0,INDEX(Расчёт!$U:$U,Расчёт!$B$2)>1,N($J$44)>=3),6,0),IF(AND('Старт'!$B$18<>"",IF('Старт'!$F$18="",7,'Старт'!$F$18)=7,INDEX(Расчёт!$O:$O,Расчёт!$B$2)=0,INDEX(Расчёт!$V:$V,Расчёт!$B$2)>1,N($J$45)>=3),7,0))))="",""," — "&INDEX('Старт'!$B$20:$B$26,MAX(1,MAX(IF(AND('Старт'!$B$12<>"",IF('Старт'!$F$12="",7,'Старт'!$F$12)=7,INDEX(Расчёт!$I:$I,Расчёт!$B$2)=0,INDEX(Расчёт!$P:$P,Расчёт!$B$2)>1,N($J$39)>=3),1,0),IF(AND('Старт'!$B$13<>"",IF('Старт'!$F$13="",7,'Старт'!$F$13)=7,INDEX(Расчёт!$J:$J,Расчёт!$B$2)=0,INDEX(Расчёт!$Q:$Q,Расчёт!$B$2)>1,N($J$40)>=3),2,0),IF(AND('Старт'!$B$14<>"",IF('Старт'!$F$14="",7,'Старт'!$F$14)=7,INDEX(Расчёт!$K:$K,Расчёт!$B$2)=0,INDEX(Расчёт!$R:$R,Расчёт!$B$2)>1,N($J$41)>=3),3,0),IF(AND('Старт'!$B$15<>"",IF('Старт'!$F$15="",7,'Старт'!$F$15)=7,INDEX(Расчёт!$L:$L,Расчёт!$B$2)=0,INDEX(Расчёт!$S:$S,Расчёт!$B$2)>1,N($J$42)>=3),4,0),IF(AND('Старт'!$B$16<>"",IF('Старт'!$F$16="",7,'Старт'!$F$16)=7,INDEX(Расчёт!$M:$M,Расчёт!$B$2)=0,INDEX(Расчёт!$T:$T,Расчёт!$B$2)>1,N($J$43)>=3),5,0),IF(AND('Старт'!$B$17<>"",IF('Старт'!$F$17="",7,'Старт'!$F$17)=7,INDEX(Расчёт!$N:$N,Расчёт!$B$2)=0,INDEX(Расчёт!$U:$U,Расчёт!$B$2)>1,N($J$44)>=3),6,0),IF(AND('Старт'!$B$18<>"",IF('Старт'!$F$18="",7,'Старт'!$F$18)=7,INDEX(Расчёт!$O:$O,Расчёт!$B$2)=0,INDEX(Расчёт!$V:$V,Расчёт!$B$2)>1,N($J$45)>=3),7,0))))),IF(Расчёт!$F$406=1,"Испытание закрыто · +100 опыта","Уровень "&Расчёт!$B$5&" · "&Расчёт!$B$6))))
B3: =IF('Старт'!$B$12="","",'Старт'!$A$12) | C3: =IF('Старт'!$B$13="","",'Старт'!$A$13) | D3: =IF('Старт'!$B$14="","",'Старт'!$A$14) | E3: =IF('Старт'!$B$15="","",'Старт'!$A$15) | F3: =IF('Старт'!$B$16="","",'Старт'!$A$16) | G3: =IF('Старт'!$B$17="","",'Старт'!$A$17) | H3: =IF('Старт'!$B$18="","",'Старт'!$A$18)
B4: =IF('Старт'!$B$12="","",'Старт'!$E$12) | C4: =IF('Старт'!$B$13="","",'Старт'!$E$13) | D4: =IF('Старт'!$B$14="","",'Старт'!$E$14) | E4: =IF('Старт'!$B$15="","",'Старт'!$E$15) | F4: =IF('Старт'!$B$16="","",'Старт'!$E$16) | G4: =IF('Старт'!$B$17="","",'Старт'!$E$17) | H4: =IF('Старт'!$B$18="","",'Старт'!$E$18)
B5: =IF('Старт'!$B$12="","",IF(Расчёт!$B$2=0,"",IF(IF('Старт'!$F$12="",7,'Старт'!$F$12)<7,"ок",IF(INDEX(Расчёт!$I:$I,Расчёт!$B$2)=0,IF(AND(INDEX(Расчёт!$P:$P,Расчёт!$B$2)>1,$J$39>=3),"верни",""),IF(INDEX(Расчёт!$I:$I,Расчёт!$B$2)>=3,"🔥","")&INDEX(Расчёт!$I:$I,Расчёт!$B$2)&IF(INDEX(Расчёт!$P:$P,Расчёт!$B$2)<=1,"🛡",""))))) | C5: =IF('Старт'!$B$13="","",IF(Расчёт!$B$2=0,"",IF(IF('Старт'!$F$13="",7,'Старт'!$F$13)<7,"ок",IF(INDEX(Расчёт!$J:$J,Расчёт!$B$2)=0,IF(AND(INDEX(Расчёт!$Q:$Q,Расчёт!$B$2)>1,$J$40>=3),"верни",""),IF(INDEX(Расчёт!$J:$J,Расчёт!$B$2)>=3,"🔥","")&INDEX(Расчёт!$J:$J,Расчёт!$B$2)&IF(INDEX(Расчёт!$Q:$Q,Расчёт!$B$2)<=1,"🛡",""))))) | D5: =IF('Старт'!$B$14="","",IF(Расчёт!$B$2=0,"",IF(IF('Старт'!$F$14="",7,'Старт'!$F$14)<7,"ок",IF(INDEX(Расчёт!$K:$K,Расчёт!$B$2)=0,IF(AND(INDEX(Расчёт!$R:$R,Расчёт!$B$2)>1,$J$41>=3),"верни",""),IF(INDEX(Расчёт!$K:$K,Расчёт!$B$2)>=3,"🔥","")&INDEX(Расчёт!$K:$K,Расчёт!$B$2)&IF(INDEX(Расчёт!$R:$R,Расчёт!$B$2)<=1,"🛡",""))))) | E5: =IF('Старт'!$B$15="","",IF(Расчёт!$B$2=0,"",IF(IF('Старт'!$F$15="",7,'Старт'!$F$15)<7,"ок",IF(INDEX(Расчёт!$L:$L,Расчёт!$B$2)=0,IF(AND(INDEX(Расчёт!$S:$S,Расчёт!$B$2)>1,$J$42>=3),"верни",""),IF(INDEX(Расчёт!$L:$L,Расчёт!$B$2)>=3,"🔥","")&INDEX(Расчёт!$L:$L,Расчёт!$B$2)&IF(INDEX(Расчёт!$S:$S,Расчёт!$B$2)<=1,"🛡",""))))) | F5: =IF('Старт'!$B$16="","",IF(Расчёт!$B$2=0,"",IF(IF('Старт'!$F$16="",7,'Старт'!$F$16)<7,"ок",IF(INDEX(Расчёт!$M:$M,Расчёт!$B$2)=0,IF(AND(INDEX(Расчёт!$T:$T,Расчёт!$B$2)>1,$J$43>=3),"верни",""),IF(INDEX(Расчёт!$M:$M,Расчёт!$B$2)>=3,"🔥","")&INDEX(Расчёт!$M:$M,Расчёт!$B$2)&IF(INDEX(Расчёт!$T:$T,Расчёт!$B$2)<=1,"🛡",""))))) | G5: =IF('Старт'!$B$17="","",IF(Расчёт!$B$2=0,"",IF(IF('Старт'!$F$17="",7,'Старт'!$F$17)<7,"ок",IF(INDEX(Расчёт!$N:$N,Расчёт!$B$2)=0,IF(AND(INDEX(Расчёт!$U:$U,Расчёт!$B$2)>1,$J$44>=3),"верни",""),IF(INDEX(Расчёт!$N:$N,Расчёт!$B$2)>=3,"🔥","")&INDEX(Расчёт!$N:$N,Расчёт!$B$2)&IF(INDEX(Расчёт!$U:$U,Расчёт!$B$2)<=1,"🛡",""))))) | H5: =IF('Старт'!$B$18="","",IF(Расчёт!$B$2=0,"",IF(IF('Старт'!$F$18="",7,'Старт'!$F$18)<7,"ок",IF(INDEX(Расчёт!$O:$O,Расчёт!$B$2)=0,IF(AND(INDEX(Расчёт!$V:$V,Расчёт!$B$2)>1,$J$45>=3),"верни",""),IF(INDEX(Расчёт!$O:$O,Расчёт!$B$2)>=3,"🔥","")&INDEX(Расчёт!$O:$O,Расчёт!$B$2)&IF(INDEX(Расчёт!$V:$V,Расчёт!$B$2)<=1,"🛡",""))))) | I5: =Расчёт!$B$3 | J5: =IF(AND(YEAR(Расчёт!$B$1)=2026,MONTH(Расчёт!$B$1)=3),5+DAY(Расчёт!$B$1),0) | K5: =IF(WEEKDAY(Расчёт!$B$1,2)>=6,1,0) | L5: =Расчёт!$B$2
A6: =IF(Расчёт!$A$70=0,"Вс 1","Вс 1"&CHAR(10)&Расчёт!$W$70&"/"&$I$5) | B6: FALSE | C6: FALSE | D6: FALSE | E6: FALSE | F6: FALSE | G6: FALSE | H6: FALSE
A7: =IF(Расчёт!$A$71=0,"Пн 2","Пн 2"&CHAR(10)&Расчёт!$W$71&"/"&$I$5) | B7: FALSE | C7: FALSE | D7: FALSE | E7: FALSE | F7: FALSE | G7: FALSE | H7: FALSE
A8: =IF(Расчёт!$A$72=0,"Вт 3","Вт 3"&CHAR(10)&Расчёт!$W$72&"/"&$I$5) | B8: FALSE | C8: FALSE | D8: FALSE | E8: FALSE | F8: FALSE | G8: FALSE | H8: FALSE
A9: =IF(Расчёт!$A$73=0,"Ср 4","Ср 4"&CHAR(10)&Расчёт!$W$73&"/"&$I$5) | B9: FALSE | C9: FALSE | D9: FALSE | E9: FALSE | F9: FALSE | G9: FALSE | H9: FALSE
A10: =IF(Расчёт!$A$74=0,"Чт 5","Чт 5"&CHAR(10)&Расчёт!$W$74&"/"&$I$5) | B10: FALSE | C10: FALSE | D10: FALSE | E10: FALSE | F10: FALSE | G10: FALSE | H10: FALSE
A11: =IF(Расчёт!$A$75=0,"Пт 6","Пт 6"&CHAR(10)&Расчёт!$W$75&"/"&$I$5) | B11: FALSE | C11: FALSE | D11: FALSE | E11: FALSE | F11: FALSE | G11: FALSE | H11: FALSE
A12: =IF(Расчёт!$A$76=0,"Сб 7","Сб 7"&CHAR(10)&Расчёт!$W$76&"/"&$I$5) | B12: FALSE | C12: FALSE | D12: FALSE | E12: FALSE | F12: FALSE | G12: FALSE | H12: FALSE
A13: =IF(Расчёт!$A$77=0,"Вс 8","Вс 8"&CHAR(10)&Расчёт!$W$77&"/"&$I$5) | B13: FALSE | C13: FALSE | D13: FALSE | E13: FALSE | F13: FALSE | G13: FALSE | H13: FALSE
A14: =IF(Расчёт!$A$78=0,"Пн 9","Пн 9"&CHAR(10)&Расчёт!$W$78&"/"&$I$5) | B14: FALSE | C14: FALSE | D14: FALSE | E14: FALSE | F14: FALSE | G14: FALSE | H14: FALSE
A15: =IF(Расчёт!$A$79=0,"Вт 10","Вт 10"&CHAR(10)&Расчёт!$W$79&"/"&$I$5) | B15: FALSE | C15: FALSE | D15: FALSE | E15: FALSE | F15: FALSE | G15: FALSE | H15: FALSE
A16: =IF(Расчёт!$A$80=0,"Ср 11","Ср 11"&CHAR(10)&Расчёт!$W$80&"/"&$I$5) | B16: FALSE | C16: FALSE | D16: FALSE | E16: FALSE | F16: FALSE | G16: FALSE | H16: FALSE
A17: =IF(Расчёт!$A$81=0,"Чт 12","Чт 12"&CHAR(10)&Расчёт!$W$81&"/"&$I$5) | B17: FALSE | C17: FALSE | D17: FALSE | E17: FALSE | F17: FALSE | G17: FALSE | H17: FALSE
A18: =IF(Расчёт!$A$82=0,"Пт 13","Пт 13"&CHAR(10)&Расчёт!$W$82&"/"&$I$5) | B18: FALSE | C18: FALSE | D18: FALSE | E18: FALSE | F18: FALSE | G18: FALSE | H18: FALSE
A19: =IF(Расчёт!$A$83=0,"Сб 14","Сб 14"&CHAR(10)&Расчёт!$W$83&"/"&$I$5) | B19: FALSE | C19: FALSE | D19: FALSE | E19: FALSE | F19: FALSE | G19: FALSE | H19: FALSE
A20: =IF(Расчёт!$A$84=0,"Вс 15","Вс 15"&CHAR(10)&Расчёт!$W$84&"/"&$I$5) | B20: FALSE | C20: FALSE | D20: FALSE | E20: FALSE | F20: FALSE | G20: FALSE | H20: FALSE
A21: =IF(Расчёт!$A$85=0,"Пн 16","Пн 16"&CHAR(10)&Расчёт!$W$85&"/"&$I$5) | B21: FALSE | C21: FALSE | D21: FALSE | E21: FALSE | F21: FALSE | G21: FALSE | H21: FALSE
A22: =IF(Расчёт!$A$86=0,"Вт 17","Вт 17"&CHAR(10)&Расчёт!$W$86&"/"&$I$5) | B22: FALSE | C22: FALSE | D22: FALSE | E22: FALSE | F22: FALSE | G22: FALSE | H22: FALSE
A23: =IF(Расчёт!$A$87=0,"Ср 18","Ср 18"&CHAR(10)&Расчёт!$W$87&"/"&$I$5) | B23: FALSE | C23: FALSE | D23: FALSE | E23: FALSE | F23: FALSE | G23: FALSE | H23: FALSE
A24: =IF(Расчёт!$A$88=0,"Чт 19","Чт 19"&CHAR(10)&Расчёт!$W$88&"/"&$I$5) | B24: FALSE | C24: FALSE | D24: FALSE | E24: FALSE | F24: FALSE | G24: FALSE | H24: FALSE
A25: =IF(Расчёт!$A$89=0,"Пт 20","Пт 20"&CHAR(10)&Расчёт!$W$89&"/"&$I$5) | B25: FALSE | C25: FALSE | D25: FALSE | E25: FALSE | F25: FALSE | G25: FALSE | H25: FALSE
A26: =IF(Расчёт!$A$90=0,"Сб 21","Сб 21"&CHAR(10)&Расчёт!$W$90&"/"&$I$5) | B26: FALSE | C26: FALSE | D26: FALSE | E26: FALSE | F26: FALSE | G26: FALSE | H26: FALSE
A27: =IF(Расчёт!$A$91=0,"Вс 22","Вс 22"&CHAR(10)&Расчёт!$W$91&"/"&$I$5) | B27: FALSE | C27: FALSE | D27: FALSE | E27: FALSE | F27: FALSE | G27: FALSE | H27: FALSE
A28: =IF(Расчёт!$A$92=0,"Пн 23","Пн 23"&CHAR(10)&Расчёт!$W$92&"/"&$I$5) | B28: FALSE | C28: FALSE | D28: FALSE | E28: FALSE | F28: FALSE | G28: FALSE | H28: FALSE
A29: =IF(Расчёт!$A$93=0,"Вт 24","Вт 24"&CHAR(10)&Расчёт!$W$93&"/"&$I$5) | B29: FALSE | C29: FALSE | D29: FALSE | E29: FALSE | F29: FALSE | G29: FALSE | H29: FALSE
A30: =IF(Расчёт!$A$94=0,"Ср 25","Ср 25"&CHAR(10)&Расчёт!$W$94&"/"&$I$5) | B30: FALSE | C30: FALSE | D30: FALSE | E30: FALSE | F30: FALSE | G30: FALSE | H30: FALSE
A31: =IF(Расчёт!$A$95=0,"Чт 26","Чт 26"&CHAR(10)&Расчёт!$W$95&"/"&$I$5) | B31: FALSE | C31: FALSE | D31: FALSE | E31: FALSE | F31: FALSE | G31: FALSE | H31: FALSE
A32: =IF(Расчёт!$A$96=0,"Пт 27","Пт 27"&CHAR(10)&Расчёт!$W$96&"/"&$I$5) | B32: FALSE | C32: FALSE | D32: FALSE | E32: FALSE | F32: FALSE | G32: FALSE | H32: FALSE
A33: =IF(Расчёт!$A$97=0,"Сб 28","Сб 28"&CHAR(10)&Расчёт!$W$97&"/"&$I$5) | B33: FALSE | C33: FALSE | D33: FALSE | E33: FALSE | F33: FALSE | G33: FALSE | H33: FALSE
A34: =IF(Расчёт!$A$98=0,"Вс 29","Вс 29"&CHAR(10)&Расчёт!$W$98&"/"&$I$5) | B34: FALSE | C34: FALSE | D34: FALSE | E34: FALSE | F34: FALSE | G34: FALSE | H34: FALSE
A35: =IF(Расчёт!$A$99=0,"Пн 30","Пн 30"&CHAR(10)&Расчёт!$W$99&"/"&$I$5) | B35: FALSE | C35: FALSE | D35: FALSE | E35: FALSE | F35: FALSE | G35: FALSE | H35: FALSE
A36: =IF(Расчёт!$A$100=0,"Вт 31","Вт 31"&CHAR(10)&Расчёт!$W$100&"/"&$I$5) | B36: FALSE | C36: FALSE | D36: FALSE | E36: FALSE | F36: FALSE | G36: FALSE | H36: FALSE
A38: МОИ ПРИВЫЧКИ
A39: =IF('Старт'!$B$12="","",'Старт'!$A$12&" "&'Старт'!$B$12) | G39: =IF('Старт'!$B$12="","",SUM(Расчёт!$B$70:$B$100)&" из "&ROUND(IF('Старт'!$F$12="",7,'Старт'!$F$12)*31/7,0)) | I39: =IF('Старт'!$B$12="","",IF(Расчёт!$B$2=0,"",IF(IF('Старт'!$F$12="",7,'Старт'!$F$12)<7,"ок",IF(INDEX(Расчёт!$I:$I,Расчёт!$B$2)=0,IF(AND(INDEX(Расчёт!$P:$P,Расчёт!$B$2)>1,$J$39>=3),"верни",""),IF(INDEX(Расчёт!$I:$I,Расчёт!$B$2)>=3,"🔥","")&INDEX(Расчёт!$I:$I,Расчёт!$B$2)&IF(INDEX(Расчёт!$P:$P,Расчёт!$B$2)<=1,"🛡",""))))) | J39: =IF('Старт'!$B$12="","",MAX(Расчёт!$I$70:$I$100)) | K39: =IF(OR('Старт'!$B$12="",Расчёт!$C$381=0),"",MIN(1,SUM(Расчёт!$B$70:$B$100)/MAX(1,ROUND(IF('Старт'!$F$12="",7,'Старт'!$F$12)*31/7,0)*Расчёт!$C$381/31))) | L39: =IF($K$39="","",SPARKLINE($K$39,{"charttype","bar";"max",1;"color1","#22A35E";"color2","#262B38"}))
A40: =IF('Старт'!$B$13="","",'Старт'!$A$13&" "&'Старт'!$B$13) | G40: =IF('Старт'!$B$13="","",SUM(Расчёт!$C$70:$C$100)&" из "&ROUND(IF('Старт'!$F$13="",7,'Старт'!$F$13)*31/7,0)) | I40: =IF('Старт'!$B$13="","",IF(Расчёт!$B$2=0,"",IF(IF('Старт'!$F$13="",7,'Старт'!$F$13)<7,"ок",IF(INDEX(Расчёт!$J:$J,Расчёт!$B$2)=0,IF(AND(INDEX(Расчёт!$Q:$Q,Расчёт!$B$2)>1,$J$40>=3),"верни",""),IF(INDEX(Расчёт!$J:$J,Расчёт!$B$2)>=3,"🔥","")&INDEX(Расчёт!$J:$J,Расчёт!$B$2)&IF(INDEX(Расчёт!$Q:$Q,Расчёт!$B$2)<=1,"🛡",""))))) | J40: =IF('Старт'!$B$13="","",MAX(Расчёт!$J$70:$J$100)) | K40: =IF(OR('Старт'!$B$13="",Расчёт!$C$381=0),"",MIN(1,SUM(Расчёт!$C$70:$C$100)/MAX(1,ROUND(IF('Старт'!$F$13="",7,'Старт'!$F$13)*31/7,0)*Расчёт!$C$381/31))) | L40: =IF($K$40="","",SPARKLINE($K$40,{"charttype","bar";"max",1;"color1","#22A35E";"color2","#262B38"}))
A41: =IF('Старт'!$B$14="","",'Старт'!$A$14&" "&'Старт'!$B$14) | G41: =IF('Старт'!$B$14="","",SUM(Расчёт!$D$70:$D$100)&" из "&ROUND(IF('Старт'!$F$14="",7,'Старт'!$F$14)*31/7,0)) | I41: =IF('Старт'!$B$14="","",IF(Расчёт!$B$2=0,"",IF(IF('Старт'!$F$14="",7,'Старт'!$F$14)<7,"ок",IF(INDEX(Расчёт!$K:$K,Расчёт!$B$2)=0,IF(AND(INDEX(Расчёт!$R:$R,Расчёт!$B$2)>1,$J$41>=3),"верни",""),IF(INDEX(Расчёт!$K:$K,Расчёт!$B$2)>=3,"🔥","")&INDEX(Расчёт!$K:$K,Расчёт!$B$2)&IF(INDEX(Расчёт!$R:$R,Расчёт!$B$2)<=1,"🛡",""))))) | J41: =IF('Старт'!$B$14="","",MAX(Расчёт!$K$70:$K$100)) | K41: =IF(OR('Старт'!$B$14="",Расчёт!$C$381=0),"",MIN(1,SUM(Расчёт!$D$70:$D$100)/MAX(1,ROUND(IF('Старт'!$F$14="",7,'Старт'!$F$14)*31/7,0)*Расчёт!$C$381/31))) | L41: =IF($K$41="","",SPARKLINE($K$41,{"charttype","bar";"max",1;"color1","#22A35E";"color2","#262B38"}))
...

Sheet Апр
A1: ="АПР 2026" | F1: =IF(Расчёт!$C$382=0,"Не идеально, а регулярно",ROUND(Расчёт!$F$382*100,0)&" % · "&Расчёт!$B$6&" "&Расчёт!$B$5)
A2: =IF(OR(Расчёт!$B$2=0,Расчёт!$B$4=0),"Не идеально, а регулярно",IF(INDEX(Расчёт!$AA:$AA,Расчёт!$B$2)>0,"Награда «Возвращение» · +15 опыта",IF(MAX(IF(AND('Старт'!$B$12<>"",IF('Старт'!$F$12="",7,'Старт'!$F$12)=7,INDEX(Расчёт!$I:$I,Расчёт!$B$2)=0,INDEX(Расчёт!$P:$P,Расчёт!$B$2)>1,N($J$39)>=3),1,0),IF(AND('Старт'!$B$13<>"",IF('Старт'!$F$13="",7,'Старт'!$F$13)=7,INDEX(Расчёт!$J:$J,Расчёт!$B$2)=0,INDEX(Расчёт!$Q:$Q,Расчёт!$B$2)>1,N($J$40)>=3),2,0),IF(AND('Старт'!$B$14<>"",IF('Старт'!$F$14="",7,'Старт'!$F$14)=7,INDEX(Расчёт!$K:$K,Расчёт!$B$2)=0,INDEX(Расчёт!$R:$R,Расчёт!$B$2)>1,N($J$41)>=3),3,0),IF(AND('Старт'!$B$15<>"",IF('Старт'!$F$15="",7,'Старт'!$F$15)=7,INDEX(Расчёт!$L:$L,Расчёт!$B$2)=0,INDEX(Расчёт!$S:$S,Расчёт!$B$2)>1,N($J$42)>=3),4,0),IF(AND('Старт'!$B$16<>"",IF('Старт'!$F$16="",7,'Старт'!$F$16)=7,INDEX(Расчёт!$M:$M,Расчёт!$B$2)=0,INDEX(Расчёт!$T:$T,Расчёт!$B$2)>1,N($J$43)>=3),5,0),IF(AND('Старт'!$B$17<>"",IF('Старт'!$F$17="",7,'Старт'!$F$17)=7,INDEX(Расчёт!$N:$N,Расчёт!$B$2)=0,INDEX(Расчёт!$U:$U,Расчёт!$B$2)>1,N($J$44)>=3),6,0),IF(AND('Старт'!$B$18<>"",IF('Старт'!$F$18="",7,'Старт'!$F$18)=7,INDEX(Расчёт!$O:$O,Расчёт!$B$2)=0,INDEX(Расчёт!$V:$V,Расчёт!$B$2)>1,N($J$45)>=3),7,0))>0,"Верни «"&INDEX('Старт'!$E$12:$E$18,MAX(1,MAX(IF(AND('Старт'!$B$12<>"",IF('Старт'!$F$12="",7,'Старт'!$F$12)=7,INDEX(Расчёт!$I:$I,Расчёт!$B$2)=0,INDEX(Расчёт!$P:$P,Расчёт!$B$2)>1,N($J$39)>=3),1,0),IF(AND('Старт'!$B$13<>"",IF('Старт'!$F$13="",7,'Старт'!$F$13)=7,INDEX(Расчёт!$J:$J,Расчёт!$B$2)=0,INDEX(Расчёт!$Q:$Q,Расчёт!$B$2)>1,N($J$40)>=3),2,0),IF(AND('Старт'!$B$14<>"",IF('Старт'!$F$14="",7,'Старт'!$F$14)=7,INDEX(Расчёт!$K:$K,Расчёт!$B$2)=0,INDEX(Расчёт!$R:$R,Расчёт!$B$2)>1,N($J$41)>=3),3,0),IF(AND('Старт'!$B$15<>"",IF('Старт'!$F$15="",7,'Старт'!$F$15)=7,INDEX(Расчёт!$L:$L,Расчёт!$B$2)=0,INDEX(Расчёт!$S:$S,Расчёт!$B$2)>1,N($J$42)>=3),4,0),IF(AND('Старт'!$B$16<>"",IF('Старт'!$F$16="",7,'Старт'!$F$16)=7,INDEX(Расчёт!$M:$M,Расчёт!$B$2)=0,INDEX(Расчёт!$T:$T,Расчёт!$B$2)>1,N($J$43)>=3),5,0),IF(AND('Старт'!$B$17<>"",IF('Старт'!$F$17="",7,'Старт'!$F$17)=7,INDEX(Расчёт!$N:$N,Расчёт!$B$2)=0,INDEX(Расчёт!$U:$U,Расчёт!$B$2)>1,N($J$44)>=3),6,0),IF(AND('Старт'!$B$18<>"",IF('Старт'!$F$18="",7,'Старт'!$F$18)=7,INDEX(Расчёт!$O:$O,Расчёт!$B$2)=0,INDEX(Расчёт!$V:$V,Расчёт!$B$2)>1,N($J$45)>=3),7,0))))&"» сегодня"&IF(INDEX('Старт'!$B$20:$B$26,MAX(1,MAX(IF(AND('Старт'!$B$12<>"",IF('Старт'!$F$12="",7,'Старт'!$F$12)=7,INDEX(Расчёт!$I:$I,Расчёт!$B$2)=0,INDEX(Расчёт!$P:$P,Расчёт!$B$2)>1,N($J$39)>=3),1,0),IF(AND('Старт'!$B$13<>"",IF('Старт'!$F$13="",7,'Старт'!$F$13)=7,INDEX(Расчёт!$J:$J,Расчёт!$B$2)=0,INDEX(Расчёт!$Q:$Q,Расчёт!$B$2)>1,N($J$40)>=3),2,0),IF(AND('Старт'!$B$14<>"",IF('Старт'!$F$14="",7,'Старт'!$F$14)=7,INDEX(Расчёт!$K:$K,Расчёт!$B$2)=0,INDEX(Расчёт!$R:$R,Расчёт!$B$2)>1,N($J$41)>=3),3,0),IF(AND('Старт'!$B$15<>"",IF('Старт'!$F$15="",7,'Старт'!$F$15)=7,INDEX(Расчёт!$L:$L,Расчёт!$B$2)=0,INDEX(Расчёт!$S:$S,Расчёт!$B$2)>1,N($J$42)>=3),4,0),IF(AND('Старт'!$B$16<>"",IF('Старт'!$F$16="",7,'Старт'!$F$16)=7,INDEX(Расчёт!$M:$M,Расчёт!$B$2)=0,INDEX(Расчёт!$T:$T,Расчёт!$B$2)>1,N($J$43)>=3),5,0),IF(AND('Старт'!$B$17<>"",IF('Старт'!$F$17="",7,'Старт'!$F$17)=7,INDEX(Расчёт!$N:$N,Расчёт!$B$2)=0,INDEX(Расчёт!$U:$U,Расчёт!$B$2)>1,N($J$44)>=3),6,0),IF(AND('Старт'!$B$18<>"",IF('Старт'!$F$18="",7,'Старт'!$F$18)=7,INDEX(Расчёт!$O:$O,Расчёт!$B$2)=0,INDEX(Расчёт!$V:$V,Расчёт!$B$2)>1,N($J$45)>=3),7,0))))="",""," — "&INDEX('Старт'!$B$20:$B$26,MAX(1,MAX(IF(AND('Старт'!$B$12<>"",IF('Старт'!$F$12="",7,'Старт'!$F$12)=7,INDEX(Расчёт!$I:$I,Расчёт!$B$2)=0,INDEX(Расчёт!$P:$P,Расчёт!$B$2)>1,N($J$39)>=3),1,0),IF(AND('Старт'!$B$13<>"",IF('Старт'!$F$13="",7,'Старт'!$F$13)=7,INDEX(Расчёт!$J:$J,Расчёт!$B$2)=0,INDEX(Расчёт!$Q:$Q,Расчёт!$B$2)>1,N($J$40)>=3),2,0),IF(AND('Старт'!$B$14<>"",IF('Старт'!$F$14="",7,'Старт'!$F$14)=7,INDEX(Расчёт!$K:$K,Расчёт!$B$2)=0,INDEX(Расчёт!$R:$R,Расчёт!$B$2)>1,N($J$41)>=3),3,0),IF(AND('Старт'!$B$15<>"",IF('Старт'!$F$15="",7,'Старт'!$F$15)=7,INDEX(Расчёт!$L:$L,Расчёт!$B$2)=0,INDEX(Расчёт!$S:$S,Расчёт!$B$2)>1,N($J$42)>=3),4,0),IF(AND('Старт'!$B$16<>"",IF('Старт'!$F$16="",7,'Старт'!$F$16)=7,INDEX(Расчёт!$M:$M,Расчёт!$B$2)=0,INDEX(Расчёт!$T:$T,Расчёт!$B$2)>1,N($J$43)>=3),5,0),IF(AND('Старт'!$B$17<>"",IF('Старт'!$F$17="",7,'Старт'!$F$17)=7,INDEX(Расчёт!$N:$N,Расчёт!$B$2)=0,INDEX(Расчёт!$U:$U,Расчёт!$B$2)>1,N($J$44)>=3),6,0),IF(AND('Старт'!$B$18<>"",IF('Старт'!$F$18="",7,'Старт'!$F$18)=7,INDEX(Расчёт!$O:$O,Расчёт!$B$2)=0,INDEX(Расчёт!$V:$V,Расчёт!$B$2)>1,N($J$45)>=3),7,0))))),IF(Расчёт!$F$410=1,"Испытание закрыто · +100 опыта","Уровень "&Расчёт!$B$5&" · "&Расчёт!$B$6))))
B3: =IF('Старт'!$B$12="","",'Старт'!$A$12) | C3: =IF('Старт'!$B$13="","",'Старт'!$A$13) | D3: =IF('Старт'!$B$14="","",'Старт'!$A$14) | E3: =IF('Старт'!$B$15="","",'Старт'!$A$15) | F3: =IF('Старт'!$B$16="","",'Старт'!$A$16) | G3: =IF('Старт'!$B$17="","",'Старт'!$A$17) | H3: =IF('Старт'!$B$18="","",'Старт'!$A$18)
B4: =IF('Старт'!$B$12="","",'Старт'!$E$12) | C4: =IF('Старт'!$B$13="","",'Старт'!$E$13) | D4: =IF('Старт'!$B$14="","",'Старт'!$E$14) | E4: =IF('Старт'!$B$15="","",'Старт'!$E$15) | F4: =IF('Старт'!$B$16="","",'Старт'!$E$16) | G4: =IF('Старт'!$B$17="","",'Старт'!$E$17) | H4: =IF('Старт'!$B$18="","",'Старт'!$E$18)
B5: =IF('Старт'!$B$12="","",IF(Расчёт!$B$2=0,"",IF(IF('Старт'!$F$12="",7,'Старт'!$F$12)<7,"ок",IF(INDEX(Расчёт!$I:$I,Расчёт!$B$2)=0,IF(AND(INDEX(Расчёт!$P:$P,Расчёт!$B$2)>1,$J$39>=3),"верни",""),IF(INDEX(Расчёт!$I:$I,Расчёт!$B$2)>=3,"🔥","")&INDEX(Расчёт!$I:$I,Расчёт!$B$2)&IF(INDEX(Расчёт!$P:$P,Расчёт!$B$2)<=1,"🛡",""))))) | C5: =IF('Старт'!$B$13="","",IF(Расчёт!$B$2=0,"",IF(IF('Старт'!$F$13="",7,'Старт'!$F$13)<7,"ок",IF(INDEX(Расчёт!$J:$J,Расчёт!$B$2)=0,IF(AND(INDEX(Расчёт!$Q:$Q,Расчёт!$B$2)>1,$J$40>=3),"верни",""),IF(INDEX(Расчёт!$J:$J,Расчёт!$B$2)>=3,"🔥","")&INDEX(Расчёт!$J:$J,Расчёт!$B$2)&IF(INDEX(Расчёт!$Q:$Q,Расчёт!$B$2)<=1,"🛡",""))))) | D5: =IF('Старт'!$B$14="","",IF(Расчёт!$B$2=0,"",IF(IF('Старт'!$F$14="",7,'Старт'!$F$14)<7,"ок",IF(INDEX(Расчёт!$K:$K,Расчёт!$B$2)=0,IF(AND(INDEX(Расчёт!$R:$R,Расчёт!$B$2)>1,$J$41>=3),"верни",""),IF(INDEX(Расчёт!$K:$K,Расчёт!$B$2)>=3,"🔥","")&INDEX(Расчёт!$K:$K,Расчёт!$B$2)&IF(INDEX(Расчёт!$R:$R,Расчёт!$B$2)<=1,"🛡",""))))) | E5: =IF('Старт'!$B$15="","",IF(Расчёт!$B$2=0,"",IF(IF('Старт'!$F$15="",7,'Старт'!$F$15)<7,"ок",IF(INDEX(Расчёт!$L:$L,Расчёт!$B$2)=0,IF(AND(INDEX(Расчёт!$S:$S,Расчёт!$B$2)>1,$J$42>=3),"верни",""),IF(INDEX(Расчёт!$L:$L,Расчёт!$B$2)>=3,"🔥","")&INDEX(Расчёт!$L:$L,Расчёт!$B$2)&IF(INDEX(Расчёт!$S:$S,Расчёт!$B$2)<=1,"🛡",""))))) | F5: =IF('Старт'!$B$16="","",IF(Расчёт!$B$2=0,"",IF(IF('Старт'!$F$16="",7,'Старт'!$F$16)<7,"ок",IF(INDEX(Расчёт!$M:$M,Расчёт!$B$2)=0,IF(AND(INDEX(Расчёт!$T:$T,Расчёт!$B$2)>1,$J$43>=3),"верни",""),IF(INDEX(Расчёт!$M:$M,Расчёт!$B$2)>=3,"🔥","")&INDEX(Расчёт!$M:$M,Расчёт!$B$2)&IF(INDEX(Расчёт!$T:$T,Расчёт!$B$2)<=1,"🛡",""))))) | G5: =IF('Старт'!$B$17="","",IF(Расчёт!$B$2=0,"",IF(IF('Старт'!$F$17="",7,'Старт'!$F$17)<7,"ок",IF(INDEX(Расчёт!$N:$N,Расчёт!$B$2)=0,IF(AND(INDEX(Расчёт!$U:$U,Расчёт!$B$2)>1,$J$44>=3),"верни",""),IF(INDEX(Расчёт!$N:$N,Расчёт!$B$2)>=3,"🔥","")&INDEX(Расчёт!$N:$N,Расчёт!$B$2)&IF(INDEX(Расчёт!$U:$U,Расчёт!$B$2)<=1,"🛡",""))))) | H5: =IF('Старт'!$B$18="","",IF(Расчёт!$B$2=0,"",IF(IF('Старт'!$F$18="",7,'Старт'!$F$18)<7,"ок",IF(INDEX(Расчёт!$O:$O,Расчёт!$B$2)=0,IF(AND(INDEX(Расчёт!$V:$V,Расчёт!$B$2)>1,$J$45>=3),"верни",""),IF(INDEX(Расчёт!$O:$O,Расчёт!$B$2)>=3,"🔥","")&INDEX(Расчёт!$O:$O,Расчёт!$B$2)&IF(INDEX(Расчёт!$V:$V,Расчёт!$B$2)<=1,"🛡",""))))) | I5: =Расчёт!$B$3 | J5: =IF(AND(YEAR(Расчёт!$B$1)=2026,MONTH(Расчёт!$B$1)=4),5+DAY(Расчёт!$B$1),0) | K5: =IF(WEEKDAY(Расчёт!$B$1,2)>=6,1,0) | L5: =Расчёт!$B$2
A6: =IF(Расчёт!$A$101=0,"Ср 1","Ср 1"&CHAR(10)&Расчёт!$W$101&"/"&$I$5) | B6: FALSE | C6: FALSE | D6: FALSE | E6: FALSE | F6: FALSE | G6: FALSE | H6: FALSE
A7: =IF(Расчёт!$A$102=0,"Чт 2","Чт 2"&CHAR(10)&Расчёт!$W$102&"/"&$I$5) | B7: FALSE | C7: FALSE | D7: FALSE | E7: FALSE | F7: FALSE | G7: FALSE | H7: FALSE
A8: =IF(Расчёт!$A$103=0,"Пт 3","Пт 3"&CHAR(10)&Расчёт!$W$103&"/"&$I$5) | B8: FALSE | C8: FALSE | D8: FALSE | E8: FALSE | F8: FALSE | G8: FALSE | H8: FALSE
A9: =IF(Расчёт!$A$104=0,"Сб 4","Сб 4"&CHAR(10)&Расчёт!$W$104&"/"&$I$5) | B9: FALSE | C9: FALSE | D9: FALSE | E9: FALSE | F9: FALSE | G9: FALSE | H9: FALSE
A10: =IF(Расчёт!$A$105=0,"Вс 5","Вс 5"&CHAR(10)&Расчёт!$W$105&"/"&$I$5) | B10: FALSE | C10: FALSE | D10: FALSE | E10: FALSE | F10: FALSE | G10: FALSE | H10: FALSE
A11: =IF(Расчёт!$A$106=0,"Пн 6","Пн 6"&CHAR(10)&Расчёт!$W$106&"/"&$I$5) | B11: FALSE | C11: FALSE | D11: FALSE | E11: FALSE | F11: FALSE | G11: FALSE | H11: FALSE
A12: =IF(Расчёт!$A$107=0,"Вт 7","Вт 7"&CHAR(10)&Расчёт!$W$107&"/"&$I$5) | B12: FALSE | C12: FALSE | D12: FALSE | E12: FALSE | F12: FALSE | G12: FALSE | H12: FALSE
A13: =IF(Расчёт!$A$108=0,"Ср 8","Ср 8"&CHAR(10)&Расчёт!$W$108&"/"&$I$5) | B13: FALSE | C13: FALSE | D13: FALSE | E13: FALSE | F13: FALSE | G13: FALSE | H13: FALSE
A14: =IF(Расчёт!$A$109=0,"Чт 9","Чт 9"&CHAR(10)&Расчёт!$W$109&"/"&$I$5) | B14: FALSE | C14: FALSE | D14: FALSE | E14: FALSE | F14: FALSE | G14: FALSE | H14: FALSE
A15: =IF(Расчёт!$A$110=0,"Пт 10","Пт 10"&CHAR(10)&Расчёт!$W$110&"/"&$I$5) | B15: FALSE | C15: FALSE | D15: FALSE | E15: FALSE | F15: FALSE | G15: FALSE | H15: FALSE
A16: =IF(Расчёт!$A$111=0,"Сб 11","Сб 11"&CHAR(10)&Расчёт!$W$111&"/"&$I$5) | B16: FALSE | C16: FALSE | D16: FALSE | E16: FALSE | F16: FALSE | G16: FALSE | H16: FALSE
A17: =IF(Расчёт!$A$112=0,"Вс 12","Вс 12"&CHAR(10)&Расчёт!$W$112&"/"&$I$5) | B17: FALSE | C17: FALSE | D17: FALSE | E17: FALSE | F17: FALSE | G17: FALSE | H17: FALSE
A18: =IF(Расчёт!$A$113=0,"Пн 13","Пн 13"&CHAR(10)&Расчёт!$W$113&"/"&$I$5) | B18: FALSE | C18: FALSE | D18: FALSE | E18: FALSE | F18: FALSE | G18: FALSE | H18: FALSE
A19: =IF(Расчёт!$A$114=0,"Вт 14","Вт 14"&CHAR(10)&Расчёт!$W$114&"/"&$I$5) | B19: FALSE | C19: FALSE | D19: FALSE | E19: FALSE | F19: FALSE | G19: FALSE | H19: FALSE
A20: =IF(Расчёт!$A$115=0,"Ср 15","Ср 15"&CHAR(10)&Расчёт!$W$115&"/"&$I$5) | B20: FALSE | C20: FALSE | D20: FALSE | E20: FALSE | F20: FALSE | G20: FALSE | H20: FALSE
A21: =IF(Расчёт!$A$116=0,"Чт 16","Чт 16"&CHAR(10)&Расчёт!$W$116&"/"&$I$5) | B21: FALSE | C21: FALSE | D21: FALSE | E21: FALSE | F21: FALSE | G21: FALSE | H21: FALSE
